Workbook
Name MixA: CONCATENATE([1]非血建库!$C$7&[1]非血建库!$E$7,",",[1]非血建库!$I$6&[1]非血建库!$M$6,",",[1]非血建库!$C$8&[1]非血建库!$E$8,",")
Name MixC: CONCATENATE([2]非血建库!$I$7&[2]非血建库!$M$7,",",[2]非血建库!$I$6&[2]非血建库!$M$6,",",[2]非血建库!$C$9&[2]非血建库!$E$9,",",[2]非血建库!$I$8&[2]非血建库!$M$8,",")

Sheet 上机信息表
A1: 上机日期 | B1: 样品编号 | C1: 实验室编号 | D1: 患者姓名 | E1: 样品类型 | F1: 检测流程 | G1: 样品来源 | H1: 处理方式 | I1: 提取浓度（ng/ul） | J1: 建库起始核酸量（ng） | K1: 子文库编号 | L1: 接头编号 | M1: UMSI编号 | N1: 文库终浓度(ng/ul） | O1: 上机文库量(M) | P1: 芯片号 | Q1: 试剂批号 | R1: 操作人(组别+姓名） | S1: 备注 | T1: total reads | U1: Host_rate | V1: Q20 | W1: Q30 | X1: 报告结果 | Y1: 检出病原菌
A2: 2026.5.20 | B2: 61-S | C2: KY14538 | D2: VM031共提 | E2: 研磨液白蛉 | F2: DNA | G2: 科研样本 | H2: 破壁+prime2.0DNA建库 | I2: 0.562 | K2: =C2&"-"&S2&"-"&L2&"D" -> KY14538-1-T224D | L2: T224 | N2: 13.6 | O2: 20 | Q2: 提取20250603/建库RUO20260105/引物20250812 | R2: 科研组+冯冬凤 | S2: 1
A3: 2026.5.20 | B3: 62-S | C3: KY14539 | D3: VM031共提 | E3: 研磨液白蛉 | F3: DNA | G3: 科研样本 | H3: 破壁+prime2.0DNA建库 | I3: 0.292 | K3: =C3&"-"&S3&"-"&L3&"D" -> KY14539-1-T225D | L3: T225 | N3: 19.2 | O3: 20 | Q3: 提取20250603/建库RUO20260105/引物20250812 | R3: 科研组+冯冬凤 | S3: 1
A4: 2026.5.20 | B4: 63-S | C4: KY14540 | D4: VM031共提 | E4: 研磨液白蛉 | F4: DNA | G4: 科研样本 | H4: 破壁+prime2.0DNA建库 | I4: 0.722 | K4: =C4&"-"&S4&"-"&L4&"D" -> KY14540-1-T226D | L4: T226 | N4: 17.3 | O4: 20 | Q4: 提取20250603/建库RUO20260105/引物20250812 | R4: 科研组+冯冬凤 | S4: 1
A5: 2026.5.20 | B5: 64-S | C5: KY14541 | D5: VM031共提 | E5: 研磨液白蛉 | F5: DNA | G5: 科研样本 | H5: 破壁+prime2.0DNA建库 | I5: 0.512 | K5: =C5&"-"&S5&"-"&L5&"D" -> KY14541-1-T227D | L5: T227 | N5: 17.9 | O5: 20 | Q5: 提取20250603/建库RUO20260105/引物20250812 | R5: 科研组+冯冬凤 | S5: 1
A6: 2026.5.20 | B6: 65-S | C6: KY14542 | D6: VM031共提 | E6: 研磨液白蛉 | F6: DNA | G6: 科研样本 | H6: 破壁+prime2.0DNA建库 | I6: 0.452 | K6: =C6&"-"&S6&"-"&L6&"D" -> KY14542-1-T230D | L6: T230 | N6: 14.4 | O6: 20 | Q6: 提取20250603/建库RUO20260105/引物20250812 | R6: 科研组+冯冬凤 | S6: 1
A7: 2026.5.20 | B7: 66-S | C7: KY14543 | D7: VM031共提 | E7: 研磨液白蛉 | F7: DNA | G7: 科研样本 | H7: 破壁+prime2.0DNA建库 | I7: 0.868 | K7: =C7&"-"&S7&"-"&L7&"D" -> KY14543-1-T229D | L7: T229 | N7: 15.1 | O7: 20 | Q7: 提取20250603/建库RUO20260105/引物20250812 | R7: 科研组+冯冬凤 | S7: 1

Sheet pooling详情
A1: IDseq-GZ2026第1635期上机pooling表
A2: 建库日期 | B2: 实验室编号 | C2: 样本类型 | D2: index | F2: 片段大小(bp) | G2: QubitC(ng/µl) | H2: Molarity(nM) | I2: 数据量(M) | J2: 稀释后浓度 | K2: 稀释倍数 | L2: Library Volume (µl) | M2: H2O(µl) | N2: Pooling Volume (µl) | O2: =IF(_xlfn.IFNA(VLOOKUP("NC*",B3:B62,1,0),"注意！无NC")<>"注意！无NC","好棒！已加NC","注意！无NC") -> 注意！无NC | P2: =IF(COUNT($I$3:$I$62)<>COUNTIF($AB$3:$AB$62,"填写正确"),"实验室编号/接头与文库编号不一致",IF(COUNT($I$3:$I$62)<>COUNTIF($AC$3:$AC$62,"填写正确"),"子文库编号错误",IF(COUNT($I$3:$I$62)<>COUNTIF($AD$3:$AD$62,"填写正确"),"UMSI格式错误","好棒！pooling表填写正确"))) -> 实验室编号/接头与文库编号不一致 | Q2: =IF(COUNTIF($AE$3:$AE$62,"重复")>0,"请注意，接头有重复！","好棒！接头没有重复") -> 好棒！接头没有重复 | R2: =IF(I66>545,"总数据量为"&I66&"M,超载了!","总数据量为"&I66&"M,满足上机要求") -> 总数据量为120M,满足上机要求 | AA2: 稀释后浓度 | AB2: 实验室编号与文库编号检测 | AC2: 子文库编号检测 | AD2: UMSI检测 | AE2: INDEX是否重复
A3: =IF(上机信息表!A2<>0,上机信息表!A2,"") -> 2026.5.20 | B3: =IF(上机信息表!K2<>0,上机信息表!K2,"") -> KY14538-1-T224D | C3: =IF(上机信息表!E2<>0,上机信息表!E2,"") -> 研磨液白蛉 | D3: =IF(上机信息表!L2<>0,上机信息表!L2,"") -> T224 | F3: =IF(RIGHT(B3)="D",300,IF(RIGHT(B3)="R",450,"")) -> 300 | G3: =IF(上机信息表!N2<>0,VALUE(上机信息表!N2),"") -> 13.6 | H3: =IF(G3<>"",1000000*G3/(660*F3),"") -> 68.686869 | I3: =IF(B3="","",VALUE(上机信息表!O2)) -> 20 | J3: 40 | K3: =IFERROR(H3/J3,"") -> 1.7171717 | L3: =IF(B3="","",IF(H3<J3,0,IF(AND(H3>=J3,I3<=20),2,IF(AND(H3>=J3,I3>20),I3/10)))) -> 2 | M3: =IF(B3="","",IF(H3>J3,L3*K3-L3,0)) -> 1.4343434 | N3: =IF(H3="","",IF(AND(COUNTIF(B3,"*Y*")=0,J3*2*I3/H3/20>17),17,IF(H3>J3,I3*2/20,J3*2*I3/H3/20))) -> 2 | AA3: =IF(H3="","",IF(H3>J3,J3,H3)) -> 40 | AB3: =IF(上机信息表!C2="","",IF(AND(上机信息表!C2=LEFT(上机信息表!K2,FIND("-",上机信息表!K2)-1),ISNUMBER(FIND(上机信息表!L2,上机信息表!K2))),"填写正确","填写错误")) -> 填写正确 | AC3: =IF(上机信息表!K2="","",IF(AND(ISNUMBER(FIND("--",上机信息表!K2))=FALSE,LEN(上机信息表!K2)-LEN(SUBSTITUTE(上机信息表!K2,"-",""))=2,OR(RIGHT(上机信息表!K2)="D",RIGHT(上机信息表!K2)="R")),"填写正确","填写错误")) -> 填写正确 | AD3: =IF(ISTEXT(上机信息表!M2),"填写正确","") | AE3: =IF(COUNTIF(上机信息表!$L$2:$L$62,上机信息表!L2)>1,"重复","")
A4: =IF(上机信息表!A3<>0,上机信息表!A3,"") -> 2026.5.20 | B4: =IF(上机信息表!K3<>0,上机信息表!K3,"") -> KY14539-1-T225D | C4: =IF(上机信息表!E3<>0,上机信息表!E3,"") -> 研磨液白蛉 | D4: =IF(上机信息表!L3<>0,上机信息表!L3,"") -> T225 | F4: =IF(RIGHT(B4)="D",300,IF(RIGHT(B4)="R",450,"")) -> 300 | G4: =IF(上机信息表!N3<>0,VALUE(上机信息表!N3),"") -> 19.2 | H4: =IF(G4<>"",1000000*G4/(660*F4),"") -> 96.969697 | I4: =IF(B4="","",VALUE(上机信息表!O3)) -> 20 | J4: 40 | K4: =IFERROR(H4/J4,"") -> 2.4242424 | L4: =IF(B4="","",IF(H4<J4,0,IF(AND(H4>=J4,I4<=20),2,IF(AND(H4>=J4,I4>20),I4/10)))) -> 2 | M4: =IF(B4="","",IF(H4>J4,L4*K4-L4,0)) -> 2.8484848 | N4: =IF(H4="","",IF(AND(COUNTIF(B4,"*Y*")=0,J4*2*I4/H4/20>17),17,IF(H4>J4,I4*2/20,J4*2*I4/H4/20))) -> 2 | AA4: =IF(H4="","",IF(H4>J4,J4,H4)) -> 40
A5: =IF(上机信息表!A4<>0,上机信息表!A4,"") -> 2026.5.20 | B5: =IF(上机信息表!K4<>0,上机信息表!K4,"") -> KY14540-1-T226D | C5: =IF(上机信息表!E4<>0,上机信息表!E4,"") -> 研磨液白蛉 | D5: =IF(上机信息表!L4<>0,上机信息表!L4,"") -> T226 | F5: =IF(RIGHT(B5)="D",300,IF(RIGHT(B5)="R",450,"")) -> 300 | G5: =IF(上机信息表!N4<>0,VALUE(上机信息表!N4),"") -> 17.3 | H5: =IF(G5<>"",1000000*G5/(660*F5),"") -> 87.373737 | I5: =IF(B5="","",VALUE(上机信息表!O4)) -> 20 | J5: 40 | K5: =IFERROR(H5/J5,"") -> 2.1843434 | L5: =IF(B5="","",IF(H5<J5,0,IF(AND(H5>=J5,I5<=20),2,IF(AND(H5>=J5,I5>20),I5/10)))) -> 2 | M5: =IF(B5="","",IF(H5>J5,L5*K5-L5,0)) -> 2.3686869 | N5: =IF(H5="","",IF(AND(COUNTIF(B5,"*Y*")=0,J5*2*I5/H5/20>17),17,IF(H5>J5,I5*2/20,J5*2*I5/H5/20))) -> 2
A6: =IF(上机信息表!A5<>0,上机信息表!A5,"") -> 2026.5.20 | B6: =IF(上机信息表!K5<>0,上机信息表!K5,"") -> KY14541-1-T227D | C6: =IF(上机信息表!E5<>0,上机信息表!E5,"") -> 研磨液白蛉 | D6: =IF(上机信息表!L5<>0,上机信息表!L5,"") -> T227 | F6: =IF(RIGHT(B6)="D",300,IF(RIGHT(B6)="R",450,"")) -> 300 | G6: =IF(上机信息表!N5<>0,VALUE(上机信息表!N5),"") -> 17.9 | H6: =IF(G6<>"",1000000*G6/(660*F6),"") -> 90.40404 | I6: =IF(B6="","",VALUE(上机信息表!O5)) -> 20 | J6: 40 | K6: =IFERROR(H6/J6,"") -> 2.260101 | L6: =IF(B6="","",IF(H6<J6,0,IF(AND(H6>=J6,I6<=20),2,IF(AND(H6>=J6,I6>20),I6/10)))) -> 2 | M6: =IF(B6="","",IF(H6>J6,L6*K6-L6,0)) -> 2.520202 | N6: =IF(H6="","",IF(AND(COUNTIF(B6,"*Y*")=0,J6*2*I6/H6/20>17),17,IF(H6>J6,I6*2/20,J6*2*I6/H6/20))) -> 2
A7: =IF(上机信息表!A6<>0,上机信息表!A6,"") -> 2026.5.20 | B7: =IF(上机信息表!K6<>0,上机信息表!K6,"") -> KY14542-1-T230D | C7: =IF(上机信息表!E6<>0,上机信息表!E6,"") -> 研磨液白蛉 | D7: =IF(上机信息表!L6<>0,上机信息表!L6,"") -> T230 | F7: =IF(RIGHT(B7)="D",300,IF(RIGHT(B7)="R",450,"")) -> 300 | G7: =IF(上机信息表!N6<>0,VALUE(上机信息表!N6),"") -> 14.4 | H7: =IF(G7<>"",1000000*G7/(660*F7),"") -> 72.727273 | I7: =IF(B7="","",VALUE(上机信息表!O6)) -> 20 | J7: 40 | K7: =IFERROR(H7/J7,"") -> 1.8181818 | L7: =IF(B7="","",IF(H7<J7,0,IF(AND(H7>=J7,I7<=20),2,IF(AND(H7>=J7,I7>20),I7/10)))) -> 2 | M7: =IF(B7="","",IF(H7>J7,L7*K7-L7,0)) -> 1.6363636 | N7: =IF(H7="","",IF(AND(COUNTIF(B7,"*Y*")=0,J7*2*I7/H7/20>17),17,IF(H7>J7,I7*2/20,J7*2*I7/H7/20))) -> 2 | AA7: =IF(H7="","",IF(H7>J7,J7,H7)) -> 40 | AB7: =IF(上机信息表!C6="","",IF(AND(上机信息表!C6=LEFT(上机信息表!K6,FIND("-",上机信息表!K6)-1),ISNUMBER(FIND(上机信息表!L6,上机信息表!K6))),"填写正确","填写错误")) -> 填写正确 | AC7: =IF(上机信息表!K6="","",IF(AND(ISNUMBER(FIND("--",上机信息表!K6))=FALSE,LEN(上机信息表!K6)-LEN(SUBSTITUTE(上机信息表!K6,"-",""))=2,OR(RIGHT(上机信息表!K6)="D",RIGHT(上机信息表!K6)="R")),"填写正确","填写错误")) -> 填写正确 | AD7: =IF(ISTEXT(上机信息表!K6),"填写正确","") -> 填写正确 | AE7: =IF(COUNTIF(上机信息表!$L$2:$L$62,上机信息表!L6)>1,"重复","")
A8: =IF(上机信息表!A7<>0,上机信息表!A7,"") -> 2026.5.20 | B8: =IF(上机信息表!K7<>0,上机信息表!K7,"") -> KY14543-1-T229D | C8: =IF(上机信息表!E7<>0,上机信息表!E7,"") -> 研磨液白蛉 | D8: =IF(上机信息表!L7<>0,上机信息表!L7,"") -> T229 | F8: =IF(RIGHT(B8)="D",300,IF(RIGHT(B8)="R",450,"")) -> 300 | G8: =IF(上机信息表!N7<>0,VALUE(上机信息表!N7),"") -> 15.1 | H8: =IF(G8<>"",1000000*G8/(660*F8),"") -> 76.262626 | I8: =IF(B8="","",VALUE(上机信息表!O7)) -> 20 | J8: =IF(B8="","",IF(20/MIN($H$3:$H$62)>17,5,IF(MIN($H$3:$H$62)<20,10,IF(AND(MIN($H$3:$H$62)>=20,MIN($H$3:$H$62)<40),20,IF(MIN($H$3:$H$62)>=40,40))))) -> 40 | K8: =IFERROR(H8/J8,"") -> 1.9065657 | L8: =IF(B8="","",IF(H8<J8,0,IF(AND(H8>=J8,I8<=20),2,IF(AND(H8>=J8,I8>20),I8/10)))) -> 2 | M8: =IF(B8="","",IF(H8>J8,L8*K8-L8,0)) -> 1.8131313 | N8: =IF(H8="","",IF(AND(COUNTIF(B8,"*Y*")=0,J8*2*I8/H8/20>17),17,IF(H8>J8,I8*2/20,J8*2*I8/H8/20))) -> 2 | AA8: =IF(H8="","",IF(H8>J8,J8,H8)) -> 40 | AB8: =IF(上机信息表!C7="","",IF(AND(上机信息表!C7=LEFT(上机信息表!K7,FIND("-",上机信息表!K7)-1),ISNUMBER(FIND(上机信息表!L7,上机信息表!K7))),"填写正确","填写错误")) -> 填写正确 | AC8: =IF(上机信息表!K7="","",IF(AND(ISNUMBER(FIND("--",上机信息表!K7))=FALSE,LEN(上机信息表!K7)-LEN(SUBSTITUTE(上机信息表!K7,"-",""))=2,OR(RIGHT(上机信息表!K7)="D",RIGHT(上机信息表!K7)="R")),"填写正确","填写错误")) -> 填写正确 | AD8: =IF(ISTEXT(上机信息表!K7),"填写正确","") -> 填写正确 | AE8: =IF(COUNTIF(上机信息表!$L$2:$L$62,上机信息表!L7)>1,"重复","")
A9: =IF(上机信息表!A8<>0,上机信息表!A8,"") | B9: =IF(上机信息表!K8<>0,上机信息表!K8,"") | C9: =IF(上机信息表!E8<>0,上机信息表!E8,"") | D9: =IF(上机信息表!L8<>0,上机信息表!L8,"") | F9: =IF(RIGHT(B9)="D",300,IF(RIGHT(B9)="R",450,"")) | G9: =IF(上机信息表!N8<>0,VALUE(上机信息表!N8),"") | H9: =IF(G9<>"",1000000*G9/(660*F9),"") | I9: =IF(B9="","",VALUE(上机信息表!O8)) | J9: =IF(B9="","",IF(20/MIN($H$3:$H$62)>17,5,IF(MIN($H$3:$H$62)<20,10,IF(AND(MIN($H$3:$H$62)>=20,MIN($H$3:$H$62)<40),20,IF(MIN($H$3:$H$62)>=40,40))))) | K9: =IFERROR(H9/J9,"") | L9: =IF(B9="","",IF(H9<J9,0,IF(AND(H9>=J9,I9<=20),2,IF(AND(H9>=J9,I9>20),I9/10)))) | M9: =IF(B9="","",IF(H9>J9,L9*K9-L9,0)) | N9: =IF(H9="","",IF(AND(COUNTIF(B9,"*Y*")=0,J9*2*I9/H9/20>17),17,IF(H9>J9,I9*2/20,J9*2*I9/H9/20))) | AA9: =IF(H9="","",IF(H9>J9,J9,H9)) | AB9: =IF(上机信息表!C8="","",IF(AND(上机信息表!C8=LEFT(上机信息表!K8,FIND("-",上机信息表!K8)-1),ISNUMBER(FIND(上机信息表!L8,上机信息表!K8))),"填写正确","填写错误")) | AC9: =IF(上机信息表!K8="","",IF(AND(ISNUMBER(FIND("--",上机信息表!K8))=FALSE,LEN(上机信息表!K8)-LEN(SUBSTITUTE(上机信息表!K8,"-",""))=2,OR(RIGHT(上机信息表!K8)="D",RIGHT(上机信息表!K8)="R")),"填写正确","填写错误")) | AD9: =IF(ISTEXT(上机信息表!K8),"填写正确","") | AE9: =IF(COUNTIF(上机信息表!$L$2:$L$62,上机信息表!L8)>1,"重复","")
A10: =IF(上机信息表!A9<>0,上机信息表!A9,"") | B10: =IF(上机信息表!K9<>0,上机信息表!K9,"") | C10: =IF(上机信息表!E9<>0,上机信息表!E9,"") | D10: =IF(上机信息表!L9<>0,上机信息表!L9,"") | F10: =IF(RIGHT(B10)="D",300,IF(RIGHT(B10)="R",450,"")) | G10: =IF(上机信息表!N9<>0,VALUE(上机信息表!N9),"") | H10: =IF(G10<>"",1000000*G10/(660*F10),"") | I10: =IF(B10="","",VALUE(上机信息表!O9)) | J10: =IF(B10="","",IF(20/MIN($H$3:$H$62)>17,5,IF(MIN($H$3:$H$62)<20,10,IF(AND(MIN($H$3:$H$62)>=20,MIN($H$3:$H$62)<40),20,IF(MIN($H$3:$H$62)>=40,40))))) | K10: =IFERROR(H10/J10,"") | L10: =IF(B10="","",IF(H10<J10,0,IF(AND(H10>=J10,I10<=20),2,IF(AND(H10>=J10,I10>20),I10/10)))) | M10: =IF(B10="","",IF(H10>J10,L10*K10-L10,0)) | N10: =IF(H10="","",IF(AND(COUNTIF(B10,"*Y*")=0,J10*2*I10/H10/20>17),17,IF(H10>J10,I10*2/20,J10*2*I10/H10/20))) | AA10: =IF(H10="","",IF(H10>J10,J10,H10)) | AB10: =IF(上机信息表!C9="","",IF(AND(上机信息表!C9=LEFT(上机信息表!K9,FIND("-",上机信息表!K9)-1),ISNUMBER(FIND(上机信息表!L9,上机信息表!K9))),"填写正确","填写错误")) | AC10: =IF(上机信息表!K9="","",IF(AND(ISNUMBER(FIND("--",上机信息表!K9))=FALSE,LEN(上机信息表!K9)-LEN(SUBSTITUTE(上机信息表!K9,"-",""))=2,OR(RIGHT(上机信息表!K9)="D",RIGHT(上机信息表!K9)="R")),"填写正确","填写错误")) | AD10: =IF(ISTEXT(上机信息表!K9),"填写正确","") | AE10: =IF(COUNTIF(上机信息表!$L$2:$L$62,上机信息表!L9)>1,"重复","")
A11: =IF(上机信息表!A10<>0,上机信息表!A10,"") | B11: =IF(上机信息表!K10<>0,上机信息表!K10,"") | C11: =IF(上机信息表!E10<>0,上机信息表!E10,"") | D11: =IF(上机信息表!L10<>0,上机信息表!L10,"") | F11: =IF(RIGHT(B11)="D",300,IF(RIGHT(B11)="R",450,"")) | G11: =IF(上机信息表!N10<>0,VALUE(上机信息表!N10),"") | H11: =IF(G11<>"",1000000*G11/(660*F11),"") | I11: =IF(B11="","",VALUE(上机信息表!O10)) | J11: =IF(B11="","",IF(20/MIN($H$3:$H$62)>17,5,IF(MIN($H$3:$H$62)<20,10,IF(AND(MIN($H$3:$H$62)>=20,MIN($H$3:$H$62)<40),20,IF(MIN($H$3:$H$62)>=40,40))))) | K11: =IFERROR(H11/J11,"") | L11: =IF(B11="","",IF(H11<J11,0,IF(AND(H11>=J11,I11<=20),2,IF(AND(H11>=J11,I11>20),I11/10)))) | M11: =IF(B11="","",IF(H11>J11,L11*K11-L11,0)) | N11: =IF(H11="","",IF(AND(COUNTIF(B11,"*Y*")=0,J11*2*I11/H11/20>17),17,IF(H11>J11,I11*2/20,J11*2*I11/H11/20))) | AA11: =IF(H11="","",IF(H11>J11,J11,H11)) | AB11: =IF(上机信息表!C10="","",IF(AND(上机信息表!C10=LEFT(上机信息表!K10,FIND("-",上机信息表!K10)-1),ISNUMBER(FIND(上机信息表!L10,上机信息表!K10))),"填写正确","填写错误")) | AC11: =IF(上机信息表!K10="","",IF(AND(ISNUMBER(FIND("--",上机信息表!K10))=FALSE,LEN(上机信息表!K10)-LEN(SUBSTITUTE(上机信息表!K10,"-",""))=2,OR(RIGHT(上机信息表!K10)="D",RIGHT(上机信息表!K10)="R")),"填写正确","填写错误")) | AD11: =IF(ISTEXT(上机信息表!K10),"填写正确","") | AE11: =IF(COUNTIF(上机信息表!$L$2:$L$62,上机信息表!L10)>1,"重复","")
A12: =IF(上机信息表!A11<>0,上机信息表!A11,"") | B12: =IF(上机信息表!K11<>0,上机信息表!K11,"") | C12: =IF(上机信息表!E11<>0,上机信息表!E11,"") | D12: =IF(上机信息表!L11<>0,上机信息表!L11,"") | F12: =IF(RIGHT(B12)="D",300,IF(RIGHT(B12)="R",450,"")) | G12: =IF(上机信息表!N11<>0,VALUE(上机信息表!N11),"") | H12: =IF(G12<>"",1000000*G12/(660*F12),"") | I12: =IF(B12="","",VALUE(上机信息表!O11)) | J12: =IF(B12="","",IF(20/MIN($H$3:$H$62)>17,5,IF(MIN($H$3:$H$62)<20,10,IF(AND(MIN($H$3:$H$62)>=20,MIN($H$3:$H$62)<40),20,IF(MIN($H$3:$H$62)>=40,40))))) | K12: =IFERROR(H12/J12,"") | L12: =IF(B12="","",IF(H12<J12,0,IF(AND(H12>=J12,I12<=20),2,IF(AND(H12>=J12,I12>20),I12/10)))) | M12: =IF(B12="","",IF(H12>J12,L12*K12-L12,0)) | N12: =IF(H12="","",IF(AND(COUNTIF(B12,"*Y*")=0,J12*2*I12/H12/20>17),17,IF(H12>J12,I12*2/20,J12*2*I12/H12/20))) | AA12: =IF(H12="","",IF(H12>J12,J12,H12)) | AB12: =IF(上机信息表!C11="","",IF(AND(上机信息表!C11=LEFT(上机信息表!K11,FIND("-",上机信息表!K11)-1),ISNUMBER(FIND(上机信息表!L11,上机信息表!K11))),"填写正确","填写错误")) | AC12: =IF(上机信息表!K11="","",IF(AND(ISNUMBER(FIND("--",上机信息表!K11))=FALSE,LEN(上机信息表!K11)-LEN(SUBSTITUTE(上机信息表!K11,"-",""))=2,OR(RIGHT(上机信息表!K11)="D",RIGHT(上机信息表!K11)="R")),"填写正确","填写错误")) | AD12: =IF(ISTEXT(上机信息表!K11),"填写正确","") | AE12: =IF(COUNTIF(上机信息表!$L$2:$L$62,上机信息表!L11)>1,"重复","")
A13: =IF(上机信息表!A12<>0,上机信息表!A12,"") | B13: =IF(上机信息表!K12<>0,上机信息表!K12,"") | C13: =IF(上机信息表!E12<>0,上机信息表!E12,"") | D13: =IF(上机信息表!L12<>0,上机信息表!L12,"") | F13: =IF(RIGHT(B13)="D",300,IF(RIGHT(B13)="R",450,"")) | G13: =IF(上机信息表!N12<>0,VALUE(上机信息表!N12),"") | H13: =IF(G13<>"",1000000*G13/(660*F13),"") | I13: =IF(B13="","",VALUE(上机信息表!O12)) | J13: =IF(B13="","",IF(20/MIN($H$3:$H$62)>17,5,IF(MIN($H$3:$H$62)<20,10,IF(AND(MIN($H$3:$H$62)>=20,MIN($H$3:$H$62)<40),20,IF(MIN($H$3:$H$62)>=40,40))))) | K13: =IFERROR(H13/J13,"") | L13: =IF(B13="","",IF(H13<J13,0,IF(AND(H13>=J13,I13<=20),2,IF(AND(H13>=J13,I13>20),I13/10)))) | M13: =IF(B13="","",IF(H13>J13,L13*K13-L13,0)) | N13: =IF(H13="","",IF(AND(COUNTIF(B13,"*Y*")=0,J13*2*I13/H13/20>17),17,IF(H13>J13,I13*2/20,J13*2*I13/H13/20))) | AA13: =IF(H13="","",IF(H13>J13,J13,H13)) | AB13: =IF(上机信息表!C12="","",IF(AND(上机信息表!C12=LEFT(上机信息表!K12,FIND("-",上机信息表!K12)-1),ISNUMBER(FIND(上机信息表!L12,上机信息表!K12))),"填写正确","填写错误")) | AC13: =IF(上机信息表!K12="","",IF(AND(ISNUMBER(FIND("--",上机信息表!K12))=FALSE,LEN(上机信息表!K12)-LEN(SUBSTITUTE(上机信息表!K12,"-",""))=2,OR(RIGHT(上机信息表!K12)="D",RIGHT(上机信息表!K12)="R")),"填写正确","填写错误")) | AD13: =IF(ISTEXT(上机信息表!M12),"填写正确","") | AE13: =IF(COUNTIF(上机信息表!$L$2:$L$62,上机信息表!L12)>1,"重复","")
A14: =IF(上机信息表!A13<>0,上机信息表!A13,"") | B14: =IF(上机信息表!K13<>0,上机信息表!K13,"") | C14: =IF(上机信息表!E13<>0,上机信息表!E13,"") | D14: =IF(上机信息表!L13<>0,上机信息表!L13,"") | F14: =IF(RIGHT(B14)="D",300,IF(RIGHT(B14)="R",450,"")) | G14: =IF(上机信息表!N13<>0,VALUE(上机信息表!N13),"") | H14: =IF(G14<>"",1000000*G14/(660*F14),"") | I14: =IF(B14="","",VALUE(上机信息表!O13)) | J14: =IF(B14="","",IF(20/MIN($H$3:$H$62)>17,5,IF(MIN($H$3:$H$62)<20,10,IF(AND(MIN($H$3:$H$62)>=20,MIN($H$3:$H$62)<40),20,IF(MIN($H$3:$H$62)>=40,40))))) | K14: =IFERROR(H14/J14,"") | L14: =IF(B14="","",IF(H14<J14,0,IF(AND(H14>=J14,I14<=20),2,IF(AND(H14>=J14,I14>20),I14/10)))) | M14: =IF(B14="","",IF(H14>J14,L14*K14-L14,0)) | N14: =IF(H14="","",IF(AND(COUNTIF(B14,"*Y*")=0,J14*2*I14/H14/20>17),17,IF(H14>J14,I14*2/20,J14*2*I14/H14/20))) | AA14: =IF(H14="","",IF(H14>J14,J14,H14)) | AB14: =IF(上机信息表!C13="","",IF(AND(上机信息表!C13=LEFT(上机信息表!K13,FIND("-",上机信息表!K13)-1),ISNUMBER(FIND(上机信息表!L13,上机信息表!K13))),"填写正确","填写错误")) | AC14: =IF(上机信息表!K13="","",IF(AND(ISNUMBER(FIND("--",上机信息表!K13))=FALSE,LEN(上机信息表!K13)-LEN(SUBSTITUTE(上机信息表!K13,"-",""))=2,OR(RIGHT(上机信息表!K13)="D",RIGHT(上机信息表!K13)="R")),"填写正确","填写错误")) | AD14: =IF(ISTEXT(上机信息表!M13),"填写正确","") | AE14: =IF(COUNTIF(上机信息表!$L$2:$L$62,上机信息表!L13)>1,"重复","")
A15: =IF(上机信息表!A14<>0,上机信息表!A14,"") | B15: =IF(上机信息表!K14<>0,上机信息表!K14,"") | C15: =IF(上机信息表!E14<>0,上机信息表!E14,"") | D15: =IF(上机信息表!L14<>0,上机信息表!L14,"") | F15: =IF(RIGHT(B15)="D",300,IF(RIGHT(B15)="R",450,"")) | G15: =IF(上机信息表!N14<>0,VALUE(上机信息表!N14),"") | H15: =IF(G15<>"",1000000*G15/(660*F15),"") | I15: =IF(B15="","",VALUE(上机信息表!O14)) | J15: =IF(B15="","",IF(20/MIN($H$3:$H$62)>17,5,IF(MIN($H$3:$H$62)<20,10,IF(AND(MIN($H$3:$H$62)>=20,MIN($H$3:$H$62)<40),20,IF(MIN($H$3:$H$62)>=40,40))))) | K15: =IFERROR(H15/J15,"") | L15: =IF(B15="","",IF(H15<J15,0,IF(AND(H15>=J15,I15<=20),2,IF(AND(H15>=J15,I15>20),I15/10)))) | M15: =IF(B15="","",IF(H15>J15,L15*K15-L15,0)) | N15: =IF(H15="","",IF(AND(COUNTIF(B15,"*Y*")=0,J15*2*I15/H15/20>17),17,IF(H15>J15,I15*2/20,J15*2*I15/H15/20))) | AA15: =IF(H15="","",IF(H15>J15,J15,H15)) | AB15: =IF(上机信息表!C14="","",IF(AND(上机信息表!C14=LEFT(上机信息表!K14,FIND("-",上机信息表!K14)-1),ISNUMBER(FIND(上机信息表!L14,上机信息表!K14))),"填写正确","填写错误")) | AC15: =IF(上机信息表!K14="","",IF(AND(ISNUMBER(FIND("--",上机信息表!K14))=FALSE,LEN(上机信息表!K14)-LEN(SUBSTITUTE(上机信息表!K14,"-",""))=2,OR(RIGHT(上机信息表!K14)="D",RIGHT(上机信息表!K14)="R")),"填写正确","填写错误")) | AD15: =IF(ISTEXT(上机信息表!M14),"填写正确","") | AE15: =IF(COUNTIF(上机信息表!$L$2:$L$62,上机信息表!L14)>1,"重复","")
A16: =IF(上机信息表!A15<>0,上机信息表!A15,"") | B16: =IF(上机信息表!K15<>0,上机信息表!K15,"") | C16: =IF(上机信息表!E15<>0,上机信息表!E15,"") | D16: =IF(上机信息表!L15<>0,上机信息表!L15,"") | F16: =IF(RIGHT(B16)="D",300,IF(RIGHT(B16)="R",450,"")) | G16: =IF(上机信息表!N15<>0,VALUE(上机信息表!N15),"") | H16: =IF(G16<>"",1000000*G16/(660*F16),"") | I16: =IF(B16="","",VALUE(上机信息表!O15)) | J16: =IF(B16="","",IF(20/MIN($H$3:$H$62)>17,5,IF(MIN($H$3:$H$62)<20,10,IF(AND(MIN($H$3:$H$62)>=20,MIN($H$3:$H$62)<40),20,IF(MIN($H$3:$H$62)>=40,40))))) | K16: =IFERROR(H16/J16,"") | L16: =IF(B16="","",IF(H16<J16,0,IF(AND(H16>=J16,I16<=20),2,IF(AND(H16>=J16,I16>20),I16/10)))) | M16: =IF(B16="","",IF(H16>J16,L16*K16-L16,0)) | N16: =IF(H16="","",IF(AND(COUNTIF(B16,"*Y*")=0,J16*2*I16/H16/20>17),17,IF(H16>J16,I16*2/20,J16*2*I16/H16/20))) | AA16: =IF(H16="","",IF(H16>J16,J16,H16)) | AB16: =IF(上机信息表!C15="","",IF(AND(上机信息表!C15=LEFT(上机信息表!K15,FIND("-",上机信息表!K15)-1),ISNUMBER(FIND(上机信息表!L15,上机信息表!K15))),"填写正确","填写错误")) | AC16: =IF(上机信息表!K15="","",IF(AND(ISNUMBER(FIND("--",上机信息表!K15))=FALSE,LEN(上机信息表!K15)-LEN(SUBSTITUTE(上机信息表!K15,"-",""))=2,OR(RIGHT(上机信息表!K15)="D",RIGHT(上机信息表!K15)="R")),"填写正确","填写错误")) | AD16: =IF(ISTEXT(上机信息表!M15),"填写正确","") | AE16: =IF(COUNTIF(上机信息表!$L$2:$L$62,上机信息表!L15)>1,"重复","")
A17: =IF(上机信息表!A16<>0,上机信息表!A16,"") | B17: =IF(上机信息表!K16<>0,上机信息表!K16,"") | C17: =IF(上机信息表!E16<>0,上机信息表!E16,"") | D17: =IF(上机信息表!L16<>0,上机信息表!L16,"") | F17: =IF(RIGHT(B17)="D",300,IF(RIGHT(B17)="R",450,"")) | G17: =IF(上机信息表!N16<>0,VALUE(上机信息表!N16),"") | H17: =IF(G17<>"",1000000*G17/(660*F17),"") | I17: =IF(B17="","",VALUE(上机信息表!O16)) | J17: =IF(B17="","",IF(20/MIN($H$3:$H$62)>17,5,IF(MIN($H$3:$H$62)<20,10,IF(AND(MIN($H$3:$H$62)>=20,MIN($H$3:$H$62)<40),20,IF(MIN($H$3:$H$62)>=40,40))))) | K17: =IFERROR(H17/J17,"") | L17: =IF(B17="","",IF(H17<J17,0,IF(AND(H17>=J17,I17<=20),2,IF(AND(H17>=J17,I17>20),I17/10)))) | M17: =IF(B17="","",IF(H17>J17,L17*K17-L17,0)) | N17: =IF(H17="","",IF(AND(COUNTIF(B17,"*Y*")=0,J17*2*I17/H17/20>17),17,IF(H17>J17,I17*2/20,J17*2*I17/H17/20))) | AA17: =IF(H17="","",IF(H17>J17,J17,H17)) | AB17: =IF(上机信息表!C16="","",IF(AND(上机信息表!C16=LEFT(上机信息表!K16,FIND("-",上机信息表!K16)-1),ISNUMBER(FIND(上机信息表!L16,上机信息表!K16))),"填写正确","填写错误")) | AC17: =IF(上机信息表!K16="","",IF(AND(ISNUMBER(FIND("--",上机信息表!K16))=FALSE,LEN(上机信息表!K16)-LEN(SUBSTITUTE(上机信息表!K16,"-",""))=2,OR(RIGHT(上机信息表!K16)="D",RIGHT(上机信息表!K16)="R")),"填写正确","填写错误")) | AD17: =IF(ISTEXT(上机信息表!M16),"填写正确","") | AE17: =IF(COUNTIF(上机信息表!$L$2:$L$62,上机信息表!L16)>1,"重复","")
A18: =IF(上机信息表!A17<>0,上机信息表!A17,"") | B18: =IF(上机信息表!K17<>0,上机信息表!K17,"") | C18: =IF(上机信息表!E17<>0,上机信息表!E17,"") | D18: =IF(上机信息表!L17<>0,上机信息表!L17,"") | F18: =IF(RIGHT(B18)="D",300,IF(RIGHT(B18)="R",450,"")) | G18: =IF(上机信息表!N17<>0,VALUE(上机信息表!N17),"") | H18: =IF(G18<>"",1000000*G18/(660*F18),"") | I18: =IF(B18="","",VALUE(上机信息表!O17)) | J18: =IF(B18="","",IF(20/MIN($H$3:$H$62)>17,5,IF(MIN($H$3:$H$62)<20,10,IF(AND(MIN($H$3:$H$62)>=20,MIN($H$3:$H$62)<40),20,IF(MIN($H$3:$H$62)>=40,40))))) | K18: =IFERROR(H18/J18,"") | L18: =IF(B18="","",IF(H18<J18,0,IF(AND(H18>=J18,I18<=20),2,IF(AND(H18>=J18,I18>20),I18/10)))) | M18: =IF(B18="","",IF(H18>J18,L18*K18-L18,0)) | N18: =IF(H18="","",IF(AND(COUNTIF(B18,"*Y*")=0,J18*2*I18/H18/20>17),17,IF(H18>J18,I18*2/20,J18*2*I18/H18/20))) | AA18: =IF(H18="","",IF(H18>J18,J18,H18)) | AB18: =IF(上机信息表!C17="","",IF(AND(上机信息表!C17=LEFT(上机信息表!K17,FIND("-",上机信息表!K17)-1),ISNUMBER(FIND(上机信息表!L17,上机信息表!K17))),"填写正确","填写错误")) | AC18: =IF(上机信息表!K17="","",IF(AND(ISNUMBER(FIND("--",上机信息表!K17))=FALSE,LEN(上机信息表!K17)-LEN(SUBSTITUTE(上机信息表!K17,"-",""))=2,OR(RIGHT(上机信息表!K17)="D",RIGHT(上机信息表!K17)="R")),"填写正确","填写错误")) | AD18: =IF(ISTEXT(上机信息表!M17),"填写正确","") | AE18: =IF(COUNTIF(上机信息表!$L$2:$L$62,上机信息表!L17)>1,"重复","")
A19: =IF(上机信息表!A18<>0,上机信息表!A18,"") | B19: =IF(上机信息表!K18<>0,上机信息表!K18,"") | C19: =IF(上机信息表!E18<>0,上机信息表!E18,"") | D19: =IF(上机信息表!L18<>0,上机信息表!L18,"") | F19: =IF(RIGHT(B19)="D",300,IF(RIGHT(B19)="R",450,"")) | G19: =IF(上机信息表!N18<>0,VALUE(上机信息表!N18),"") | H19: =IF(G19<>"",1000000*G19/(660*F19),"") | I19: =IF(B19="","",VALUE(上机信息表!O18)) | J19: =IF(B19="","",IF(20/MIN($H$3:$H$62)>17,5,IF(MIN($H$3:$H$62)<20,10,IF(AND(MIN($H$3:$H$62)>=20,MIN($H$3:$H$62)<40),20,IF(MIN($H$3:$H$62)>=40,40))))) | K19: =IFERROR(H19/J19,"") | L19: =IF(B19="","",IF(H19<J19,0,IF(AND(H19>=J19,I19<=20),2,IF(AND(H19>=J19,I19>20),I19/10)))) | M19: =IF(B19="","",IF(H19>J19,L19*K19-L19,0)) | N19: =IF(H19="","",IF(AND(COUNTIF(B19,"*Y*")=0,J19*2*I19/H19/20>17),17,IF(H19>J19,I19*2/20,J19*2*I19/H19/20))) | AA19: =IF(H19="","",IF(H19>J19,J19,H19)) | AB19: =IF(上机信息表!C18="","",IF(AND(上机信息表!C18=LEFT(上机信息表!K18,FIND("-",上机信息表!K18)-1),ISNUMBER(FIND(上机信息表!L18,上机信息表!K18))),"填写正确","填写错误")) | AC19: =IF(上机信息表!K18="","",IF(AND(ISNUMBER(FIND("--",上机信息表!K18))=FALSE,LEN(上机信息表!K18)-LEN(SUBSTITUTE(上机信息表!K18,"-",""))=2,OR(RIGHT(上机信息表!K18)="D",RIGHT(上机信息表!K18)="R")),"填写正确","填写错误")) | AD19: =IF(ISTEXT(上机信息表!M18),"填写正确","") | AE19: =IF(COUNTIF(上机信息表!$L$2:$L$62,上机信息表!L18)>1,"重复","")
A20: =IF(上机信息表!A19<>0,上机信息表!A19,"") | B20: =IF(上机信息表!K19<>0,上机信息表!K19,"") | C20: =IF(上机信息表!E19<>0,上机信息表!E19,"") | D20: =IF(上机信息表!L19<>0,上机信息表!L19,"") | F20: =IF(RIGHT(B20)="D",300,IF(RIGHT(B20)="R",450,"")) | G20: =IF(上机信息表!N19<>0,VALUE(上机信息表!N19),"") | H20: =IF(G20<>"",1000000*G20/(660*F20),"") | I20: =IF(B20="","",VALUE(上机信息表!O19)) | J20: =IF(B20="","",IF(20/MIN($H$3:$H$62)>17,5,IF(MIN($H$3:$H$62)<20,10,IF(AND(MIN($H$3:$H$62)>=20,MIN($H$3:$H$62)<40),20,IF(MIN($H$3:$H$62)>=40,40))))) | K20: =IFERROR(H20/J20,"") | L20: =IF(B20="","",IF(H20<J20,0,IF(AND(H20>=J20,I20<=20),2,IF(AND(H20>=J20,I20>20),I20/10)))) | M20: =IF(B20="","",IF(H20>J20,L20*K20-L20,0)) | N20: =IF(H20="","",IF(AND(COUNTIF(B20,"*Y*")=0,J20*2*I20/H20/20>17),17,IF(H20>J20,I20*2/20,J20*2*I20/H20/20))) | AA20: =IF(H20="","",IF(H20>J20,J20,H20)) | AB20: =IF(上机信息表!C19="","",IF(AND(上机信息表!C19=LEFT(上机信息表!K19,FIND("-",上机信息表!K19)-1),ISNUMBER(FIND(上机信息表!L19,上机信息表!K19))),"填写正确","填写错误")) | AC20: =IF(上机信息表!K19="","",IF(AND(ISNUMBER(FIND("--",上机信息表!K19))=FALSE,LEN(上机信息表!K19)-LEN(SUBSTITUTE(上机信息表!K19,"-",""))=2,OR(RIGHT(上机信息表!K19)="D",RIGHT(上机信息表!K19)="R")),"填写正确","填写错误")) | AD20: =IF(ISTEXT(上机信息表!M19),"填写正确","") | AE20: =IF(COUNTIF(上机信息表!$L$2:$L$62,上机信息表!L19)>1,"重复","")
A21: =IF(上机信息表!A20<>0,上机信息表!A20,"") | B21: =IF(上机信息表!K20<>0,上机信息表!K20,"") | C21: =IF(上机信息表!E20<>0,上机信息表!E20,"") | D21: =IF(上机信息表!L20<>0,上机信息表!L20,"") | F21: =IF(RIGHT(B21)="D",300,IF(RIGHT(B21)="R",450,"")) | G21: =IF(上机信息表!N20<>0,VALUE(上机信息表!N20),"") | H21: =IF(G21<>"",1000000*G21/(660*F21),"") | I21: =IF(B21="","",VALUE(上机信息表!O20)) | J21: =IF(B21="","",IF(20/MIN($H$3:$H$62)>17,5,IF(MIN($H$3:$H$62)<20,10,IF(AND(MIN($H$3:$H$62)>=20,MIN($H$3:$H$62)<40),20,IF(MIN($H$3:$H$62)>=40,40))))) | K21: =IFERROR(H21/J21,"") | L21: =IF(B21="","",IF(H21<J21,0,IF(AND(H21>=J21,I21<=20),2,IF(AND(H21>=J21,I21>20),I21/10)))) | M21: =IF(B21="","",IF(H21>J21,L21*K21-L21,0)) | N21: =IF(H21="","",IF(AND(COUNTIF(B21,"*Y*")=0,J21*2*I21/H21/20>17),17,IF(H21>J21,I21*2/20,J21*2*I21/H21/20))) | AA21: =IF(H21="","",IF(H21>J21,J21,H21)) | AB21: =IF(上机信息表!C20="","",IF(AND(上机信息表!C20=LEFT(上机信息表!K20,FIND("-",上机信息表!K20)-1),ISNUMBER(FIND(上机信息表!L20,上机信息表!K20))),"填写正确","填写错误")) | AC21: =IF(上机信息表!K20="","",IF(AND(ISNUMBER(FIND("--",上机信息表!K20))=FALSE,LEN(上机信息表!K20)-LEN(SUBSTITUTE(上机信息表!K20,"-",""))=2,OR(RIGHT(上机信息表!K20)="D",RIGHT(上机信息表!K20)="R")),"填写正确","填写错误")) | AD21: =IF(ISTEXT(上机信息表!M20),"填写正确","") | AE21: =IF(COUNTIF(上机信息表!$L$2:$L$62,上机信息表!L20)>1,"重复","")
A22: =IF(上机信息表!A21<>0,上机信息表!A21,"") | B22: =IF(上机信息表!K21<>0,上机信息表!K21,"") | C22: =IF(上机信息表!E21<>0,上机信息表!E21,"") | D22: =IF(上机信息表!L21<>0,上机信息表!L21,"") | F22: =IF(RIGHT(B22)="D",300,IF(RIGHT(B22)="R",450,"")) | G22: =IF(上机信息表!N21<>0,VALUE(上机信息表!N21),"") | H22: =IF(G22<>"",1000000*G22/(660*F22),"") | I22: =IF(B22="","",VALUE(上机信息表!O21)) | J22: =IF(B22="","",IF(20/MIN($H$3:$H$62)>17,5,IF(MIN($H$3:$H$62)<20,10,IF(AND(MIN($H$3:$H$62)>=20,MIN($H$3:$H$62)<40),20,IF(MIN($H$3:$H$62)>=40,40))))) | K22: =IFERROR(H22/J22,"") | L22: =IF(B22="","",IF(H22<J22,0,IF(AND(H22>=J22,I22<=20),2,IF(AND(H22>=J22,I22>20),I22/10)))) | M22: =IF(B22="","",IF(H22>J22,L22*K22-L22,0)) | N22: =IF(H22="","",IF(AND(COUNTIF(B22,"*Y*")=0,J22*2*I22/H22/20>17),17,IF(H22>J22,I22*2/20,J22*2*I22/H22/20))) | AA22: =IF(H22="","",IF(H22>J22,J22,H22)) | AB22: =IF(上机信息表!C21="","",IF(AND(上机信息表!C21=LEFT(上机信息表!K21,FIND("-",上机信息表!K21)-1),ISNUMBER(FIND(上机信息表!L21,上机信息表!K21))),"填写正确","填写错误")) | AC22: =IF(上机信息表!K21="","",IF(AND(ISNUMBER(FIND("--",上机信息表!K21))=FALSE,LEN(上机信息表!K21)-LEN(SUBSTITUTE(上机信息表!K21,"-",""))=2,OR(RIGHT(上机信息表!K21)="D",RIGHT(上机信息表!K21)="R")),"填写正确","填写错误")) | AD22: =IF(ISTEXT(上机信息表!M21),"填写正确","") | AE22: =IF(COUNTIF(上机信息表!$L$2:$L$62,上机信息表!L21)>1,"重复","")
A23: =IF(上机信息表!A22<>0,上机信息表!A22,"") | C23: =IF(上机信息表!E22<>0,上机信息表!E22,"") | F23: =IF(RIGHT(B23)="D",300,IF(RIGHT(B23)="R",450,"")) | I23: =IF(B23="","",VALUE(上机信息表!O22)) | J23: =IF(B23="","",IF(20/MIN($H$3:$H$62)>17,5,IF(MIN($H$3:$H$62)<20,10,IF(AND(MIN($H$3:$H$62)>=20,MIN($H$3:$H$62)<40),20,IF(MIN($H$3:$H$62)>=40,40))))) | AA23: =IF(H23="","",IF(H23>J23,J23,H23)) | AB23: =IF(上机信息表!C22="","",IF(AND(上机信息表!C22=LEFT(上机信息表!K22,FIND("-",上机信息表!K22)-1),ISNUMBER(FIND(上机信息表!L22,上机信息表!K22))),"填写正确","填写错误")) | AC23: =IF(上机信息表!K22="","",IF(AND(ISNUMBER(FIND("--",上机信息表!K22))=FALSE,LEN(上机信息表!K22)-LEN(SUBSTITUTE(上机信息表!K22,"-",""))=2,OR(RIGHT(上机信息表!K22)="D",RIGHT(上机信息表!K22)="R")),"填写正确","填写错误")) | AD23: =IF(ISTEXT(上机信息表!M22),"填写正确","") | AE23: =IF(COUNTIF(上机信息表!$L$2:$L$62,上机信息表!L22)>1,"重复","")
A24: =IF(上机信息表!A23<>0,上机信息表!A23,"") | B24: =IF(上机信息表!K23<>0,上机信息表!K23,"") | C24: =IF(上机信息表!E23<>0,上机信息表!E23,"") | D24: =IF(上机信息表!L23<>0,上机信息表!L23,"") | F24: =IF(RIGHT(B24)="D",300,IF(RIGHT(B24)="R",450,"")) | G24: =IF(上机信息表!N23<>0,VALUE(上机信息表!N23),"") | H24: =IF(G24<>"",1000000*G24/(660*F24),"") | I24: =IF(B24="","",VALUE(上机信息表!O23)) | J24: =IF(B24="","",IF(20/MIN($H$3:$H$62)>17,5,IF(MIN($H$3:$H$62)<20,10,IF(AND(MIN($H$3:$H$62)>=20,MIN($H$3:$H$62)<40),20,IF(MIN($H$3:$H$62)>=40,40))))) | K24: =IFERROR(H24/J24,"") | L24: =IF(B24="","",IF(H24<J24,0,IF(AND(H24>=J24,I24<=20),2,IF(AND(H24>=J24,I24>20),I24/10)))) | M24: =IF(B24="","",IF(H24>J24,L24*K24-L24,0)) | N24: =IF(H24="","",IF(AND(COUNTIF(B24,"*Y*")=0,J24*2*I24/H24/20>17),17,IF(H24>J24,I24*2/20,J24*2*I24/H24/20))) | AA24: =IF(H24="","",IF(H24>J24,J24,H24)) | AB24: =IF(上机信息表!C23="","",IF(AND(上机信息表!C23=LEFT(上机信息表!K23,FIND("-",上机信息表!K23)-1),ISNUMBER(FIND(上机信息表!L23,上机信息表!K23))),"填写正确","填写错误")) | AC24: =IF(上机信息表!K23="","",IF(AND(ISNUMBER(FIND("--",上机信息表!K23))=FALSE,LEN(上机信息表!K23)-LEN(SUBSTITUTE(上机信息表!K23,"-",""))=2,OR(RIGHT(上机信息表!K23)="D",RIGHT(上机信息表!K23)="R")),"填写正确","填写错误")) | AD24: =IF(ISTEXT(上机信息表!M23),"填写正确","") | AE24: =IF(COUNTIF(上机信息表!$L$2:$L$62,上机信息表!L23)>1,"重复","")
A25: =IF(上机信息表!A24<>0,上机信息表!A24,"") | B25: =IF(上机信息表!K24<>0,上机信息表!K24,"") | C25: =IF(上机信息表!E24<>0,上机信息表!E24,"") | D25: =IF(上机信息表!L24<>0,上机信息表!L24,"") | F25: =IF(RIGHT(B25)="D",300,IF(RIGHT(B25)="R",450,"")) | G25: =IF(上机信息表!N24<>0,VALUE(上机信息表!N24),"") | H25: =IF(G25<>"",1000000*G25/(660*F25),"") | I25: =IF(B25="","",VALUE(上机信息表!O24)) | J25: =IF(B25="","",IF(20/MIN($H$3:$H$62)>17,5,IF(MIN($H$3:$H$62)<20,10,IF(AND(MIN($H$3:$H$62)>=20,MIN($H$3:$H$62)<40),20,IF(MIN($H$3:$H$62)>=40,40))))) | K25: =IFERROR(H25/J25,"") | L25: =IF(B25="","",IF(H25<J25,0,IF(AND(H25>=J25,I25<=20),2,IF(AND(H25>=J25,I25>20),I25/10)))) | M25: =IF(B25="","",IF(H25>J25,L25*K25-L25,0)) | N25: =IF(H25="","",IF(AND(COUNTIF(B25,"*Y*")=0,J25*2*I25/H25/20>17),17,IF(H25>J25,I25*2/20,J25*2*I25/H25/20))) | AA25: =IF(H25="","",IF(H25>J25,J25,H25)) | AB25: =IF(上机信息表!C24="","",IF(AND(上机信息表!C24=LEFT(上机信息表!K24,FIND("-",上机信息表!K24)-1),ISNUMBER(FIND(上机信息表!L24,上机信息表!K24))),"填写正确","填写错误")) | AC25: =IF(上机信息表!K24="","",IF(AND(ISNUMBER(FIND("--",上机信息表!K24))=FALSE,LEN(上机信息表!K24)-LEN(SUBSTITUTE(上机信息表!K24,"-",""))=2,OR(RIGHT(上机信息表!K24)="D",RIGHT(上机信息表!K24)="R")),"填写正确","填写错误")) | AD25: =IF(ISTEXT(上机信息表!M24),"填写正确","") | AE25: =IF(COUNTIF(上机信息表!$L$2:$L$62,上机信息表!L24)>1,"重复","")
A26: =IF(上机信息表!A25<>0,上机信息表!A25,"") | B26: =IF(上机信息表!K25<>0,上机信息表!K25,"") | C26: =IF(上机信息表!E25<>0,上机信息表!E25,"") | D26: =IF(上机信息表!L25<>0,上机信息表!L25,"") | F26: =IF(RIGHT(B26)="D",300,IF(RIGHT(B26)="R",450,"")) | G26: =IF(上机信息表!N25<>0,VALUE(上机信息表!N25),"") | H26: =IF(G26<>"",1000000*G26/(660*F26),"") | I26: =IF(B26="","",VALUE(上机信息表!O25)) | J26: =IF(B26="","",IF(20/MIN($H$3:$H$62)>17,5,IF(MIN($H$3:$H$62)<20,10,IF(AND(MIN($H$3:$H$62)>=20,MIN($H$3:$H$62)<40),20,IF(MIN($H$3:$H$62)>=40,40))))) | K26: =IFERROR(H26/J26,"") | L26: =IF(B26="","",IF(H26<J26,0,IF(AND(H26>=J26,I26<=20),2,IF(AND(H26>=J26,I26>20),I26/10)))) | M26: =IF(B26="","",IF(H26>J26,L26*K26-L26,0)) | N26: =IF(H26="","",IF(AND(COUNTIF(B26,"*Y*")=0,J26*2*I26/H26/20>17),17,IF(H26>J26,I26*2/20,J26*2*I26/H26/20))) | AA26: =IF(H26="","",IF(H26>J26,J26,H26)) | AB26: =IF(上机信息表!C25="","",IF(AND(上机信息表!C25=LEFT(上机信息表!K25,FIND("-",上机信息表!K25)-1),ISNUMBER(FIND(上机信息表!L25,上机信息表!K25))),"填写正确","填写错误")) | AC26: =IF(上机信息表!K25="","",IF(AND(ISNUMBER(FIND("--",上机信息表!K25))=FALSE,LEN(上机信息表!K25)-LEN(SUBSTITUTE(上机信息表!K25,"-",""))=2,OR(RIGHT(上机信息表!K25)="D",RIGHT(上机信息表!K25)="R")),"填写正确","填写错误")) | AD26: =IF(ISTEXT(上机信息表!M25),"填写正确","") | AE26: =IF(COUNTIF(上机信息表!$L$2:$L$62,上机信息表!L25)>1,"重复","")
A27: =IF(上机信息表!A26<>0,上机信息表!A26,"") | B27: =IF(上机信息表!K26<>0,上机信息表!K26,"") | C27: =IF(上机信息表!E26<>0,上机信息表!E26,"") | D27: =IF(上机信息表!L26<>0,上机信息表!L26,"") | F27: =IF(RIGHT(B27)="D",300,IF(RIGHT(B27)="R",450,"")) | G27: =IF(上机信息表!N26<>0,VALUE(上机信息表!N26),"") | H27: =IF(G27<>"",1000000*G27/(660*F27),"") | I27: =IF(B27="","",VALUE(上机信息表!O26)) | J27: =IF(B27="","",IF(20/MIN($H$3:$H$62)>17,5,IF(MIN($H$3:$H$62)<20,10,IF(AND(MIN($H$3:$H$62)>=20,MIN($H$3:$H$62)<40),20,IF(MIN($H$3:$H$62)>=40,40))))) | K27: =IFERROR(H27/J27,"") | L27: =IF(B27="","",IF(H27<J27,0,IF(AND(H27>=J27,I27<=20),2,IF(AND(H27>=J27,I27>20),I27/10)))) | M27: =IF(B27="","",IF(H27>J27,L27*K27-L27,0)) | N27: =IF(H27="","",IF(AND(COUNTIF(B27,"*Y*")=0,J27*2*I27/H27/20>17),17,IF(H27>J27,I27*2/20,J27*2*I27/H27/20))) | AA27: =IF(H27="","",IF(H27>J27,J27,H27)) | AB27: =IF(上机信息表!C26="","",IF(AND(上机信息表!C26=LEFT(上机信息表!K26,FIND("-",上机信息表!K26)-1),ISNUMBER(FIND(上机信息表!L26,上机信息表!K26))),"填写正确","填写错误")) | AC27: =IF(上机信息表!K26="","",IF(AND(ISNUMBER(FIND("--",上机信息表!K26))=FALSE,LEN(上机信息表!K26)-LEN(SUBSTITUTE(上机信息表!K26,"-",""))=2,OR(RIGHT(上机信息表!K26)="D",RIGHT(上机信息表!K26)="R")),"填写正确","填写错误")) | AD27: =IF(ISTEXT(上机信息表!M26),"填写正确","") | AE27: =IF(COUNTIF(上机信息表!$L$2:$L$62,上机信息表!L26)>1,"重复","")
A28: =IF(上机信息表!A27<>0,上机信息表!A27,"") | B28: =IF(上机信息表!K27<>0,上机信息表!K27,"") | C28: =IF(上机信息表!E27<>0,上机信息表!E27,"") | D28: =IF(上机信息表!L27<>0,上机信息表!L27,"") | F28: =IF(RIGHT(B28)="D",300,IF(RIGHT(B28)="R",450,"")) | G28: =IF(上机信息表!N27<>0,VALUE(上机信息表!N27),"") | H28: =IF(G28<>"",1000000*G28/(660*F28),"") | I28: =IF(B28="","",VALUE(上机信息表!O27)) | J28: =IF(B28="","",IF(20/MIN($H$3:$H$62)>17,5,IF(MIN($H$3:$H$62)<20,10,IF(AND(MIN($H$3:$H$62)>=20,MIN($H$3:$H$62)<40),20,IF(MIN($H$3:$H$62)>=40,40))))) | K28: =IFERROR(H28/J28,"") | L28: =IF(B28="","",IF(H28<J28,0,IF(AND(H28>=J28,I28<=20),2,IF(AND(H28>=J28,I28>20),I28/10)))) | M28: =IF(B28="","",IF(H28>J28,L28*K28-L28,0)) | N28: =IF(H28="","",IF(AND(COUNTIF(B28,"*Y*")=0,J28*2*I28/H28/20>17),17,IF(H28>J28,I28*2/20,J28*2*I28/H28/20))) | AA28: =IF(H28="","",IF(H28>J28,J28,H28)) | AB28: =IF(上机信息表!C27="","",IF(AND(上机信息表!C27=LEFT(上机信息表!K27,FIND("-",上机信息表!K27)-1),ISNUMBER(FIND(上机信息表!L27,上机信息表!K27))),"填写正确","填写错误")) | AC28: =IF(上机信息表!K27="","",IF(AND(ISNUMBER(FIND("--",上机信息表!K27))=FALSE,LEN(上机信息表!K27)-LEN(SUBSTITUTE(上机信息表!K27,"-",""))=2,OR(RIGHT(上机信息表!K27)="D",RIGHT(上机信息表!K27)="R")),"填写正确","填写错误")) | AD28: =IF(ISTEXT(上机信息表!M27),"填写正确","") | AE28: =IF(COUNTIF(上机信息表!$L$2:$L$62,上机信息表!L27)>1,"重复","")
A29: =IF(上机信息表!A28<>0,上机信息表!A28,"") | B29: =IF(上机信息表!K28<>0,上机信息表!K28,"") | C29: =IF(上机信息表!E28<>0,上机信息表!E28,"") | D29: =IF(上机信息表!L28<>0,上机信息表!L28,"") | F29: =IF(RIGHT(B29)="D",300,IF(RIGHT(B29)="R",450,"")) | G29: =IF(上机信息表!N28<>0,VALUE(上机信息表!N28),"") | H29: =IF(G29<>"",1000000*G29/(660*F29),"") | I29: =IF(B29="","",VALUE(上机信息表!O28)) | J29: =IF(B29="","",IF(20/MIN($H$3:$H$62)>17,5,IF(MIN($H$3:$H$62)<20,10,IF(AND(MIN($H$3:$H$62)>=20,MIN($H$3:$H$62)<40),20,IF(MIN($H$3:$H$62)>=40,40))))) | K29: =IFERROR(H29/J29,"") | L29: =IF(B29="","",IF(H29<J29,0,IF(AND(H29>=J29,I29<=20),2,IF(AND(H29>=J29,I29>20),I29/10)))) | M29: =IF(B29="","",IF(H29>J29,L29*K29-L29,0)) | N29: =IF(H29="","",IF(AND(COUNTIF(B29,"*Y*")=0,J29*2*I29/H29/20>17),17,IF(H29>J29,I29*2/20,J29*2*I29/H29/20))) | AA29: =IF(H29="","",IF(H29>J29,J29,H29)) | AB29: =IF(上机信息表!C28="","",IF(AND(上机信息表!C28=LEFT(上机信息表!K28,FIND("-",上机信息表!K28)-1),ISNUMBER(FIND(上机信息表!L28,上机信息表!K28))),"填写正确","填写错误")) | AC29: =IF(上机信息表!K28="","",IF(AND(ISNUMBER(FIND("--",上机信息表!K28))=FALSE,LEN(上机信息表!K28)-LEN(SUBSTITUTE(上机信息表!K28,"-",""))=2,OR(RIGHT(上机信息表!K28)="D",RIGHT(上机信息表!K28)="R")),"填写正确","填写错误")) | AD29: =IF(ISTEXT(上机信息表!M28),"填写正确","") | AE29: =IF(COUNTIF(上机信息表!$L$2:$L$62,上机信息表!L28)>1,"重复","")
A30: =IF(上机信息表!A29<>0,上机信息表!A29,"") | B30: =IF(上机信息表!K29<>0,上机信息表!K29,"") | C30: =IF(上机信息表!E29<>0,上机信息表!E29,"") | D30: =IF(上机信息表!L29<>0,上机信息表!L29,"") | F30: =IF(RIGHT(B30)="D",300,IF(RIGHT(B30)="R",450,"")) | G30: =IF(上机信息表!N29<>0,VALUE(上机信息表!N29),"") | H30: =IF(G30<>"",1000000*G30/(660*F30),"") | I30: =IF(B30="","",VALUE(上机信息表!O29)) | J30: =IF(B30="","",IF(20/MIN($H$3:$H$62)>17,5,IF(MIN($H$3:$H$62)<20,10,IF(AND(MIN($H$3:$H$62)>=20,MIN($H$3:$H$62)<40),20,IF(MIN($H$3:$H$62)>=40,40))))) | K30: =IFERROR(H30/J30,"") | L30: =IF(B30="","",IF(H30<J30,0,IF(AND(H30>=J30,I30<=20),2,IF(AND(H30>=J30,I30>20),I30/10)))) | M30: =IF(B30="","",IF(H30>J30,L30*K30-L30,0)) | N30: =IF(H30="","",IF(AND(COUNTIF(B30,"*Y*")=0,J30*2*I30/H30/20>17),17,IF(H30>J30,I30*2/20,J30*2*I30/H30/20))) | AA30: =IF(H30="","",IF(H30>J30,J30,H30)) | AB30: =IF(上机信息表!C29="","",IF(AND(上机信息表!C29=LEFT(上机信息表!K29,FIND("-",上机信息表!K29)-1),ISNUMBER(FIND(上机信息表!L29,上机信息表!K29))),"填写正确","填写错误")) | AC30: =IF(上机信息表!K29="","",IF(AND(ISNUMBER(FIND("--",上机信息表!K29))=FALSE,LEN(上机信息表!K29)-LEN(SUBSTITUTE(上机信息表!K29,"-",""))=2,OR(RIGHT(上机信息表!K29)="D",RIGHT(上机信息表!K29)="R")),"填写正确","填写错误")) | AD30: =IF(ISTEXT(上机信息表!M29),"填写正确","") | AE30: =IF(COUNTIF(上机信息表!$L$2:$L$62,上机信息表!L29)>1,"重复","")
A31: =IF(上机信息表!A30<>0,上机信息表!A30,"") | B31: =IF(上机信息表!K30<>0,上机信息表!K30,"") | C31: =IF(上机信息表!E30<>0,上机信息表!E30,"") | D31: =IF(上机信息表!L30<>0,上机信息表!L30,"") | F31: =IF(RIGHT(B31)="D",300,IF(RIGHT(B31)="R",450,"")) | G31: =IF(上机信息表!N30<>0,VALUE(上机信息表!N30),"") | H31: =IF(G31<>"",1000000*G31/(660*F31),"") | I31: =IF(B31="","",VALUE(上机信息表!O30)) | J31: =IF(B31="","",IF(20/MIN($H$3:$H$62)>17,5,IF(MIN($H$3:$H$62)<20,10,IF(AND(MIN($H$3:$H$62)>=20,MIN($H$3:$H$62)<40),20,IF(MIN($H$3:$H$62)>=40,40))))) | K31: =IFERROR(H31/J31,"") | L31: =IF(B31="","",IF(H31<J31,0,IF(AND(H31>=J31,I31<=20),2,IF(AND(H31>=J31,I31>20),I31/10)))) | M31: =IF(B31="","",IF(H31>J31,L31*K31-L31,0)) | N31: =IF(H31="","",IF(AND(COUNTIF(B31,"*Y*")=0,J31*2*I31/H31/20>17),17,IF(H31>J31,I31*2/20,J31*2*I31/H31/20))) | AA31: =IF(H31="","",IF(H31>J31,J31,H31)) | AB31: =IF(上机信息表!C30="","",IF(AND(上机信息表!C30=LEFT(上机信息表!K30,FIND("-",上机信息表!K30)-1),ISNUMBER(FIND(上机信息表!L30,上机信息表!K30))),"填写正确","填写错误")) | AC31: =IF(上机信息表!K30="","",IF(AND(ISNUMBER(FIND("--",上机信息表!K30))=FALSE,LEN(上机信息表!K30)-LEN(SUBSTITUTE(上机信息表!K30,"-",""))=2,OR(RIGHT(上机信息表!K30)="D",RIGHT(上机信息表!K30)="R")),"填写正确","填写错误")) | AD31: =IF(ISTEXT(上机信息表!M30),"填写正确","") | AE31: =IF(COUNTIF(上机信息表!$L$2:$L$62,上机信息表!L30)>1,"重复","")
A32: =IF(上机信息表!A31<>0,上机信息表!A31,"") | B32: =IF(上机信息表!K31<>0,上机信息表!K31,"") | C32: =IF(上机信息表!E31<>0,上机信息表!E31,"") | D32: =IF(上机信息表!L31<>0,上机信息表!L31,"") | F32: =IF(RIGHT(B32)="D",300,IF(RIGHT(B32)="R",450,"")) | G32: =IF(上机信息表!N31<>0,VALUE(上机信息表!N31),"") | H32: =IF(G32<>"",1000000*G32/(660*F32),"") | I32: =IF(B32="","",VALUE(上机信息表!O31)) | J32: =IF(B32="","",IF(20/MIN($H$3:$H$62)>17,5,IF(MIN($H$3:$H$62)<20,10,IF(AND(MIN($H$3:$H$62)>=20,MIN($H$3:$H$62)<40),20,IF(MIN($H$3:$H$62)>=40,40))))) | K32: =IFERROR(H32/J32,"") | L32: =IF(B32="","",IF(H32<J32,0,IF(AND(H32>=J32,I32<=20),2,IF(AND(H32>=J32,I32>20),I32/10)))) | M32: =IF(B32="","",IF(H32>J32,L32*K32-L32,0)) | N32: =IF(H32="","",IF(AND(COUNTIF(B32,"*Y*")=0,J32*2*I32/H32/20>17),17,IF(H32>J32,I32*2/20,J32*2*I32/H32/20))) | AA32: =IF(H32="","",IF(H32>J32,J32,H32)) | AB32: =IF(上机信息表!C31="","",IF(AND(上机信息表!C31=LEFT(上机信息表!K31,FIND("-",上机信息表!K31)-1),ISNUMBER(FIND(上机信息表!L31,上机信息表!K31))),"填写正确","填写错误")) | AC32: =IF(上机信息表!K31="","",IF(AND(ISNUMBER(FIND("--",上机信息表!K31))=FALSE,LEN(上机信息表!K31)-LEN(SUBSTITUTE(上机信息表!K31,"-",""))=2,OR(RIGHT(上机信息表!K31)="D",RIGHT(上机信息表!K31)="R")),"填写正确","填写错误")) | AD32: =IF(ISTEXT(上机信息表!M31),"填写正确","") | AE32: =IF(COUNTIF(上机信息表!$L$2:$L$62,上机信息表!L31)>1,"重复","")
A33: =IF(上机信息表!A32<>0,上机信息表!A32,"") | B33: =IF(上机信息表!K32<>0,上机信息表!K32,"") | C33: =IF(上机信息表!E32<>0,上机信息表!E32,"") | D33: =IF(上机信息表!L32<>0,上机信息表!L32,"") | F33: =IF(RIGHT(B33)="D",300,IF(RIGHT(B33)="R",450,"")) | G33: =IF(上机信息表!N32<>0,VALUE(上机信息表!N32),"") | H33: =IF(G33<>"",1000000*G33/(660*F33),"") | I33: =IF(B33="","",VALUE(上机信息表!O32)) | J33: =IF(B33="","",IF(20/MIN($H$3:$H$62)>17,5,IF(MIN($H$3:$H$62)<20,10,IF(AND(MIN($H$3:$H$62)>=20,MIN($H$3:$H$62)<40),20,IF(MIN($H$3:$H$62)>=40,40))))) | K33: =IFERROR(H33/J33,"") | L33: =IF(B33="","",IF(H33<J33,0,IF(AND(H33>=J33,I33<=20),2,IF(AND(H33>=J33,I33>20),I33/10)))) | M33: =IF(B33="","",IF(H33>J33,L33*K33-L33,0)) | N33: =IF(H33="","",IF(AND(COUNTIF(B33,"*Y*")=0,J33*2*I33/H33/20>17),17,IF(H33>J33,I33*2/20,J33*2*I33/H33/20))) | AA33: =IF(H33="","",IF(H33>J33,J33,H33)) | AB33: =IF(上机信息表!C32="","",IF(AND(上机信息表!C32=LEFT(上机信息表!K32,FIND("-",上机信息表!K32)-1),ISNUMBER(FIND(上机信息表!L32,上机信息表!K32))),"填写正确","填写错误")) | AC33: =IF(上机信息表!K32="","",IF(AND(ISNUMBER(FIND("--",上机信息表!K32))=FALSE,LEN(上机信息表!K32)-LEN(SUBSTITUTE(上机信息表!K32,"-",""))=2,OR(RIGHT(上机信息表!K32)="D",RIGHT(上机信息表!K32)="R")),"填写正确","填写错误")) | AD33: =IF(ISTEXT(上机信息表!M32),"填写正确","") | AE33: =IF(COUNTIF(上机信息表!$L$2:$L$62,上机信息表!L32)>1,"重复","")
A34: =IF(上机信息表!A33<>0,上机信息表!A33,"") | B34: =IF(上机信息表!K33<>0,上机信息表!K33,"") | C34: =IF(上机信息表!E33<>0,上机信息表!E33,"") | D34: =IF(上机信息表!L33<>0,上机信息表!L33,"") | F34: =IF(RIGHT(B34)="D",300,IF(RIGHT(B34)="R",450,"")) | G34: =IF(上机信息表!N33<>0,VALUE(上机信息表!N33),"") | H34: =IF(G34<>"",1000000*G34/(660*F34),"") | I34: =IF(B34="","",VALUE(上机信息表!O33)) | J34: =IF(B34="","",IF(20/MIN($H$3:$H$62)>17,5,IF(MIN($H$3:$H$62)<20,10,IF(AND(MIN($H$3:$H$62)>=20,MIN($H$3:$H$62)<40),20,IF(MIN($H$3:$H$62)>=40,40))))) | K34: =IFERROR(H34/J34,"") | L34: =IF(B34="","",IF(H34<J34,0,IF(AND(H34>=J34,I34<=20),2,IF(AND(H34>=J34,I34>20),I34/10)))) | M34: =IF(B34="","",IF(H34>J34,L34*K34-L34,0)) | N34: =IF(H34="","",IF(AND(COUNTIF(B34,"*Y*")=0,J34*2*I34/H34/20>17),17,IF(H34>J34,I34*2/20,J34*2*I34/H34/20))) | AA34: =IF(H34="","",IF(H34>J34,J34,H34)) | AB34: =IF(上机信息表!C33="","",IF(AND(上机信息表!C33=LEFT(上机信息表!K33,FIND("-",上机信息表!K33)-1),ISNUMBER(FIND(上机信息表!L33,上机信息表!K33))),"填写正确","填写错误")) | AC34: =IF(上机信息表!K33="","",IF(AND(ISNUMBER(FIND("--",上机信息表!K33))=FALSE,LEN(上机信息表!K33)-LEN(SUBSTITUTE(上机信息表!K33,"-",""))=2,OR(RIGHT(上机信息表!K33)="D",RIGHT(上机信息表!K33)="R")),"填写正确","填写错误")) | AD34: =IF(ISTEXT(上机信息表!M33),"填写正确","") | AE34: =IF(COUNTIF(上机信息表!$L$2:$L$62,上机信息表!L33)>1,"重复","")
A35: =IF(上机信息表!A34<>0,上机信息表!A34,"") | B35: =IF(上机信息表!K34<>0,上机信息表!K34,"") | C35: =IF(上机信息表!E34<>0,上机信息表!E34,"") | D35: =IF(上机信息表!L34<>0,上机信息表!L34,"") | F35: =IF(RIGHT(B35)="D",300,IF(RIGHT(B35)="R",450,"")) | G35: =IF(上机信息表!N34<>0,VALUE(上机信息表!N34),"") | H35: =IF(G35<>"",1000000*G35/(660*F35),"") | I35: =IF(B35="","",VALUE(上机信息表!O34)) | J35: =IF(B35="","",IF(20/MIN($H$3:$H$62)>17,5,IF(MIN($H$3:$H$62)<20,10,IF(AND(MIN($H$3:$H$62)>=20,MIN($H$3:$H$62)<40),20,IF(MIN($H$3:$H$62)>=40,40))))) | K35: =IFERROR(H35/J35,"") | L35: =IF(B35="","",IF(H35<J35,0,IF(AND(H35>=J35,I35<=20),2,IF(AND(H35>=J35,I35>20),I35/10)))) | M35: =IF(B35="","",IF(H35>J35,L35*K35-L35,0)) | N35: =IF(H35="","",IF(AND(COUNTIF(B35,"*Y*")=0,J35*2*I35/H35/20>17),17,IF(H35>J35,I35*2/20,J35*2*I35/H35/20))) | AA35: =IF(H35="","",IF(H35>J35,J35,H35)) | AB35: =IF(上机信息表!C34="","",IF(AND(上机信息表!C34=LEFT(上机信息表!K34,FIND("-",上机信息表!K34)-1),ISNUMBER(FIND(上机信息表!L34,上机信息表!K34))),"填写正确","填写错误")) | AC35: =IF(上机信息表!K34="","",IF(AND(ISNUMBER(FIND("--",上机信息表!K34))=FALSE,LEN(上机信息表!K34)-LEN(SUBSTITUTE(上机信息表!K34,"-",""))=2,OR(RIGHT(上机信息表!K34)="D",RIGHT(上机信息表!K34)="R")),"填写正确","填写错误")) | AD35: =IF(ISTEXT(上机信息表!M34),"填写正确","") | AE35: =IF(COUNTIF(上机信息表!$L$2:$L$62,上机信息表!L34)>1,"重复","")
... A62: =IF(上机信息表!A61<>0,上机信息表!A61,"") | B62: =IF(上机信息表!K61<>0,上机信息表!K61,"") | C62: =IF(上机信息表!E61<>0,上机信息表!E61,"") | D62: =IF(上机信息表!L61<>0,上机信息表!L61,"") | F62: =IF(RIGHT(B62)="D",300,IF(RIGHT(B62)="R",450,"")) | G62: =IF(上机信息表!N61<>0,VALUE(上机信息表!N61),"") | H62: =IF(G62<>"",1000000*G62/(660*F62),"") | I62: =IF(B62="","",VALUE(上机信息表!O61)) | J62: =IF(B62="","",IF(20/MIN($H$3:$H$62)>17,5,IF(MIN($H$3:$H$62)<20,10,IF(AND(MIN($H$3:$H$62)>=20,MIN($H$3:$H$62)<40),20,IF(MIN($H$3:$H$62)>=40,40))))) | K62: =IFERROR(H62/J62,"") | L62: =IF(B62="","",IF(H62<J62,0,IF(AND(H62>=J62,I62<=20),2,IF(AND(H62>=J62,I62>20),I62/10)))) | M62: =IF(B62="","",IF(H62>J62,L62*K62-L62,0)) | N62: =IF(H62="","",IF(AND(COUNTIF(B62,"*Y*")=0,J62*2*I62/H62/20>17),17,IF(H62>J62,I62*2/20,J62*2*I62/H62/20))) | AA62: =IF(H62="","",IF(H62>J62,J62,H62)) | AB62: =IF(上机信息表!C61="","",IF(AND(上机信息表!C61=LEFT(上机信息表!K61,FIND("-",上机信息表!K61)-1),ISNUMBER(FIND(上机信息表!L61,上机信息表!K61))),"填写正确","填写错误")) | AC62: =IF(上机信息表!K61="","",IF(AND(ISNUMBER(FIND("--",上机信息表!K61))=FALSE,LEN(上机信息表!K61)-LEN(SUBSTITUTE(上机信息表!K61,"-",""))=2,OR(RIGHT(上机信息表!K61)="D",RIGHT(上机信息表!K61)="R")),"填写正确","填写错误")) | AD62: =IF(ISTEXT(上机信息表!M61),"填写正确","") | AE62: =IF(COUNTIF(上机信息表!$L$2:$L$62,上机信息表!L61)>1,"重复","")
F65: 平均大小 | G65: pooling文库浓度 | H65: Molarity实际值(nM) | I65: 总数据量 | J65: Molarity理论值 | K65: 偏差大小
B66: =TEXT(A3,"YYYYMMDD")&"pooling" -> 2026.5.20pooling | F66: {=SUMPRODUCT($F$3:$F$62,$I$3:$I$62)/SUM($I$3:$I$62)} -> 300 | G66: 8.68 | H66: =1000000*G66/(660*F66) -> 43.838384 | I66: =SUM($I$3:$I$62) -> 120 | J66: {=SUMPRODUCT(AA3:AA62,N3:N62)/SUM(N3:N62)} -> 26.666667 | K66: =ABS(J66-H66)/J66 -> 0.64393939
L68: =IF(K66<=0.2,"pooling合格,请继续","pooling失败，请检测文库浓度后重新pooling") -> pooling失败，请检测文库浓度后重新pooling
A70: 上机稀释
...

Sheet IDseq-上机流程监控表
A1: 出自文件：广州微远医学检验实验室有限公司 IDSeq-宏基因组标准操作作业指导书-广州
A2: 文件编号：GZVM-SOP01.21 | E2: 版本：1.0版 | G2: 生效日期：2019年8月8日
A3: 页码/总页数：第1页 共1页 | E3: 审核者：梁波 | G3: 批准者：武卫玮
A4: ="IDseq-GZ2022第"&MID(pooling详情!A1,14,(FIND("期",pooling详情!A1)-FIND("第",pooling详情!A1)-1))&"期上机流程监控表" -> IDseq-GZ2022第1635期上机流程监控表 | G4: 表号：GZVM-SOP01.21.02
A5: 实验前 准备 | B5: 辅助试剂 | C5: □ 质控合格 □ 有效期内 | E5: 试剂 | F5: 芯片 lot | G5: 20546839 | I5: 备注
B6: 耗材 | C6: □ 质控合格 □ 有效期内 | F6: 上机试剂 lot | G6: 20557000
B7: 仪器 | C7: □正常 □ 不正常 | F7: Buffer lot | G7: 20544484
B8: 测序仪状态 | D8: □ 正常 □ 不正常
B9: 数据传输路径 | D9: □ 服务器 □ 仪器 □ 专用电脑
B10: 仪器清洗 | D10: □ 正常 □ 不正常
B11: 4℃上机试剂准备 | D11: □ 有效期内 □ 质检合格 □ 室温平衡
B12: -20℃上机试剂解冻 | D12: □ 有效期内 □ 质检合格 □ 室温平衡
A13: 文库变性 | B13: —— | D13: 组分 | E13: 反应体积 (μL) | F13: —— | H13: 确认 (打 √)
B14: NaOH（0.2N ） | D14: 20 μL NaOH (1N) +80 μL ddH2O，混匀
B15: =CONCATENATE("文库稀释",pooling详情!B72,"nM") -> 文库稀释4nM | D15: =pooling详情!$H$66 -> 43.838384 | E15: =pooling详情!$D$72 -> 3
D16: HT1 | E16: =pooling详情!$E$72 -> 29.878788
B17: =CONCATENATE("文库变性(",pooling详情!B72/2,"nM)") -> 文库变性(2nM) | D17: =CONCATENATE(pooling详情!B72,"nM文库 Pool") -> 4nM文库 Pool | E17: =pooling详情!$B$76 -> 5 | F17: 室温变性5min,期间涡旋混匀2次;5 min后立即放冰上
D18: NaOH (0.2N) | E18: =pooling详情!$C$76 -> 5
A19: 上机浓度 稀释 | B19: 文库稀释（20 pM） | D19: =CONCATENATE(,pooling详情!B72/2,"nM文库)") -> 2nM文库) | E19: =pooling详情!$B$78 -> 10 | F19: 混匀
D20: HT1 | E20: =pooling详情!$C$78 -> 990
B21: =CONCATENATE("□ Nextseq 550 ( ",ROUND(pooling详情!A80,2),"pM)") -> □ Nextseq 550 ( 1.3pM) | D21: 20 pM文库 | E21: =ROUND(pooling详情!$B$80,1) -> 84.5 | F21: 文库装入#10
D22: HT1 | E22: =ROUND(pooling详情!$C$80,1) -> 1215.5
D23: 总体积 | E23: 1300
A24: 实验后 清洁 | B24: 实验桌面 | C24: □ 清洁整理 □ 丢弃实验废物
B25: 仪器 | C25: □ 清洁维护 □ 关闭电源

Sheet 跟进表信息提取
A1: 期数 | B1: 是否加测 | C1: 实验室编号 | D1: 患者姓名 | E1: 样品类型 | F1: 检测流程 | G1: 处理方式 | H1: 提取浓度（ng/ml） | I1: 提取总量（ng） | J1: 核酸剩余量 | K1: 提取时间 | L1: 建库起始核酸量（ng） | M1: 子文库编号 | N1: barcode | O1: UMSI编号 | P1: 文库终浓度(ng/ml） | Q1: 上机文库量(M) | R1: 上机文库号 | S1: 芯片号 | T1: pooling后浓度(ng/μL) | U1: 上机浓度(pM) | V1: 测序类型 | W1: 上机时间 | X1: 操作人 | Y1: 提取试剂盒 | Z1: 提取试剂盒批号（lot） | AA1: 建库试剂盒 | AB1: 建库试剂盒批号（lot） | AC1: 上机试剂信息 | AD1: 下机时间 | AE1: total reads | AF1: Host_rate | AG1: Q20 | AH1: Q30 | AI1: 报告结果 | AJ1: 检出病原菌
A2: =IF(C2=0,"","YF23"&TEXT(MID(pooling详情!$A$1,14,(FIND("期",pooling详情!$A$1)-FIND("第",pooling详情!$A$1)-1)),"0000")) -> YF231635 | B2: =上机信息表!G2 -> 科研样本 | C2: =上机信息表!C2 -> KY14538 | D2: =上机信息表!D2 -> VM031共提 | E2: =上机信息表!E2 -> 研磨液白蛉 | F2: =上机信息表!F2 -> DNA | G2: =上机信息表!H2 -> 破壁+prime2.0DNA建库 | H2: =上机信息表!I2 -> 0.562 | I2: =IF(F2="DNA",上机信息表!I2*70,上机信息表!I2*100) -> 39.34 | K2: =上机信息表!A2 -> 2026.5.20 | L2: =上机信息表!J2 -> 0 | M2: =上机信息表!K2 -> KY14538-1-T224D | N2: =上机信息表!L2 -> T224 | O2: =上机信息表!M2 -> 0 | P2: =上机信息表!N2 -> 13.6 | Q2: =上机信息表!O2 -> 20 | R2: =IF(C2=0,"","VMGZ22"&TEXT(MID(pooling详情!$A$1,14,(FIND("期",pooling详情!$A$1)-FIND("第",pooling详情!$A$1)-1)),"0000")) -> VMGZ221635 | S2: =上机信息表!P2 -> 0 | T2: =IF(C2=0,"",pooling详情!$G$66) -> 8.68 | U2: =IF(C2=0,"",pooling详情!$A$80) -> 1.3 | V2: =IF(C2=0,"","illumina") -> illumina | X2: =上机信息表!R2 -> 科研组+冯冬凤 | Y2: =IF(F2="RNA","RNA提取试剂盒",IF(LEFT(F2,3)="DNA","DNA提取试剂盒","")) -> DNA提取试剂盒 | Z2: =IFERROR(IF(Y2="RNA提取试剂盒",CONCATENATE(MID(上机信息表!Q2,SEARCH("提取",上机信息表!Q2),SEARCH("建",上机信息表!Q2)-2)),IF(Y2="DNA提取试剂盒",IF(ISNUMBER(FIND("呼吸道",上机信息表!Q2)),CONCATENATE(MID(上机信息表!Q2,SEARCH("提取",上机信息表!Q2),SEARCH(",",上机信息表!Q2,SEARCH("呼吸道",上机信息表!Q2))-1)),IF(ISNUMBER(FIND("组织",上机信息表!Q2)),CONCATENATE(MID(上机信息表!Q2,SEARCH("提取",上机信息表!Q2),SEARCH(",",上机信息表!Q2,SEARCH("组织",上机信息表!Q2))-1)),CONCATENATE(MID(上机信息表!Q2,SEARCH("提取",上机信息表!Q2),SEARCH(",",上机信息表!Q2)-1)))),"")),"") | AA2: =IF(F2="RNA","RNA建库试剂盒",IF(LEFT(F2,3)="DNA","DNA建库试剂盒","")) -> DNA建库试剂盒 | AB2: =IFERROR(IF(AA2="RNA建库试剂盒",MID(上机信息表!Q2,SEARCH("建库",上机信息表!Q2),20),IF(AA2="DNA建库试剂盒",MID(上机信息表!Q2,SEARCH("建库",上机信息表!Q2),20),"")),"") -> 建库RUO20260105/引物2025 | AC2: =IF(C2=0,"",CONCATENATE("芯片批号：",'IDseq-上机流程监控表'!$G$5,",","上机试剂批号：",'IDseq-上机流程监控表'!$G$6,",","Buffer批号：",'IDseq-上机流程监控表'!$G$7)) -> 芯片批号：20546839,上机试剂批号：20557000,Buffer批号：20544484
A3: =IF(C3=0,"","YF23"&TEXT(MID(pooling详情!$A$1,14,(FIND("期",pooling详情!$A$1)-FIND("第",pooling详情!$A$1)-1)),"0000")) -> YF231635 | B3: =上机信息表!G3 -> 科研样本 | C3: =上机信息表!C3 -> KY14539 | D3: =上机信息表!D3 -> VM031共提 | E3: =上机信息表!E3 -> 研磨液白蛉 | F3: =上机信息表!F3 -> DNA | G3: =上机信息表!H3 -> 破壁+prime2.0DNA建库 | H3: =上机信息表!I3 -> 0.292 | I3: =IF(F3="DNA",上机信息表!I3*70,上机信息表!I3*100) -> 20.44 | K3: =上机信息表!A3 -> 2026.5.20 | L3: =上机信息表!J3 -> 0 | M3: =上机信息表!K3 -> KY14539-1-T225D | N3: =上机信息表!L3 -> T225 | O3: =上机信息表!M3 -> 0 | P3: =上机信息表!N3 -> 19.2 | Q3: =上机信息表!O3 -> 20 | R3: =IF(C3=0,"","VMGZ22"&TEXT(MID(pooling详情!$A$1,14,(FIND("期",pooling详情!$A$1)-FIND("第",pooling详情!$A$1)-1)),"0000")) -> VMGZ221635 | S3: =上机信息表!P3 -> 0 | T3: =IF(C3=0,"",pooling详情!$G$66) -> 8.68 | U3: =IF(C3=0,"",pooling详情!$A$80) -> 1.3 | V3: =IF(C3=0,"","illumina") -> illumina | W3: =上机信息表!X3 -> 0 | X3: =上机信息表!R3 -> 科研组+冯冬凤 | Y3: =IF(F3="RNA","RNA提取试剂盒",IF(LEFT(F3,3)="DNA","DNA提取试剂盒","")) -> DNA提取试剂盒 | Z3: =IFERROR(IF(Y3="RNA提取试剂盒",CONCATENATE(MID(上机信息表!Q3,SEARCH("提取",上机信息表!Q3),SEARCH("建",上机信息表!Q3)-2)),IF(Y3="DNA提取试剂盒",IF(ISNUMBER(FIND("呼吸道",上机信息表!Q3)),CONCATENATE(MID(上机信息表!Q3,SEARCH("提取",上机信息表!Q3),SEARCH(",",上机信息表!Q3,SEARCH("呼吸道",上机信息表!Q3))-1)),IF(ISNUMBER(FIND("组织",上机信息表!Q3)),CONCATENATE(MID(上机信息表!Q3,SEARCH("提取",上机信息表!Q3),SEARCH(",",上机信息表!Q3,SEARCH("组织",上机信息表!Q3))-1)),CONCATENATE(MID(上机信息表!Q3,SEARCH("提取",上机信息表!Q3),SEARCH(",",上机信息表!Q3)-1)))),"")),"") | AA3: =IF(F3="RNA","RNA建库试剂盒",IF(LEFT(F3,3)="DNA","DNA建库试剂盒","")) -> DNA建库试剂盒 | AB3: =IFERROR(IF(AA3="RNA建库试剂盒",MID(上机信息表!Q3,SEARCH("建库",上机信息表!Q3),20),IF(AA3="DNA建库试剂盒",MID(上机信息表!Q3,SEARCH("建库",上机信息表!Q3),20),"")),"") -> 建库RUO20260105/引物2025 | AC3: =IF(C3=0,"",CONCATENATE("芯片批号：",'IDseq-上机流程监控表'!$G$5,",","上机试剂批号：",'IDseq-上机流程监控表'!$G$6,",","Buffer批号：",'IDseq-上机流程监控表'!$G$7)) -> 芯片批号：20546839,上机试剂批号：20557000,Buffer批号：20544484
A4: =IF(C4=0,"","YF23"&TEXT(MID(pooling详情!$A$1,14,(FIND("期",pooling详情!$A$1)-FIND("第",pooling详情!$A$1)-1)),"0000")) -> YF231635 | B4: =上机信息表!G4 -> 科研样本 | C4: =上机信息表!C4 -> KY14540 | D4: =上机信息表!D4 -> VM031共提 | E4: =上机信息表!E4 -> 研磨液白蛉 | F4: =上机信息表!F4 -> DNA | G4: =上机信息表!H4 -> 破壁+prime2.0DNA建库 | H4: =上机信息表!I4 -> 0.722 | I4: =IF(F4="DNA",上机信息表!I4*70,上机信息表!I4*100) -> 50.54 | K4: =上机信息表!A4 -> 2026.5.20 | L4: =上机信息表!J4 -> 0 | M4: =上机信息表!K4 -> KY14540-1-T226D | N4: =上机信息表!L4 -> T226 | O4: =上机信息表!M4 -> 0 | P4: =上机信息表!N4 -> 17.3 | Q4: =上机信息表!O4 -> 20 | R4: =IF(C4=0,"","VMGZ22"&TEXT(MID(pooling详情!$A$1,14,(FIND("期",pooling详情!$A$1)-FIND("第",pooling详情!$A$1)-1)),"0000")) -> VMGZ221635 | S4: =上机信息表!P4 -> 0 | T4: =IF(C4=0,"",pooling详情!$G$66) -> 8.68 | U4: =IF(C4=0,"",pooling详情!$A$80) -> 1.3 | V4: =IF(C4=0,"","illumina") -> illumina | W4: =上机信息表!X4 -> 0 | X4: =上机信息表!R4 -> 科研组+冯冬凤 | Y4: =IF(F4="RNA","RNA提取试剂盒",IF(LEFT(F4,3)="DNA","DNA提取试剂盒","")) -> DNA提取试剂盒 | Z4: =IFERROR(IF(Y4="RNA提取试剂盒",CONCATENATE(MID(上机信息表!Q4,SEARCH("提取",上机信息表!Q4),SEARCH("建",上机信息表!Q4)-2)),IF(Y4="DNA提取试剂盒",IF(ISNUMBER(FIND("呼吸道",上机信息表!Q4)),CONCATENATE(MID(上机信息表!Q4,SEARCH("提取",上机信息表!Q4),SEARCH(",",上机信息表!Q4,SEARCH("呼吸道",上机信息表!Q4))-1)),IF(ISNUMBER(FIND("组织",上机信息表!Q4)),CONCATENATE(MID(上机信息表!Q4,SEARCH("提取",上机信息表!Q4),SEARCH(",",上机信息表!Q4,SEARCH("组织",上机信息表!Q4))-1)),CONCATENATE(MID(上机信息表!Q4,SEARCH("提取",上机信息表!Q4),SEARCH(",",上机信息表!Q4)-1)))),"")),"") | AA4: =IF(F4="RNA","RNA建库试剂盒",IF(LEFT(F4,3)="DNA","DNA建库试剂盒","")) -> DNA建库试剂盒 | AB4: =IFERROR(IF(AA4="RNA建库试剂盒",MID(上机信息表!Q4,SEARCH("建库",上机信息表!Q4),20),IF(AA4="DNA建库试剂盒",MID(上机信息表!Q4,SEARCH("建库",上机信息表!Q4),20),"")),"") -> 建库RUO20260105/引物2025 | AC4: =IF(C4=0,"",CONCATENATE("芯片批号：",'IDseq-上机流程监控表'!$G$5,",","上机试剂批号：",'IDseq-上机流程监控表'!$G$6,",","Buffer批号：",'IDseq-上机流程监控表'!$G$7)) -> 芯片批号：20546839,上机试剂批号：20557000,Buffer批号：20544484
A5: =IF(C5=0,"","YF23"&TEXT(MID(pooling详情!$A$1,14,(FIND("期",pooling详情!$A$1)-FIND("第",pooling详情!$A$1)-1)),"0000")) -> YF231635 | B5: =上机信息表!G5 -> 科研样本 | C5: =上机信息表!C5 -> KY14541 | D5: =上机信息表!D5 -> VM031共提 | E5: =上机信息表!E5 -> 研磨液白蛉 | F5: =上机信息表!F5 -> DNA | G5: =上机信息表!H5 -> 破壁+prime2.0DNA建库 | H5: =上机信息表!I5 -> 0.512 | I5: =IF(F5="DNA",上机信息表!I5*70,上机信息表!I5*100) -> 35.84 | K5: =上机信息表!A5 -> 2026.5.20 | L5: =上机信息表!J5 -> 0 | M5: =上机信息表!K5 -> KY14541-1-T227D | N5: =上机信息表!L5 -> T227 | O5: =上机信息表!M5 -> 0 | P5: =上机信息表!N5 -> 17.9 | Q5: =上机信息表!O5 -> 20 | R5: =IF(C5=0,"","VMGZ22"&TEXT(MID(pooling详情!$A$1,14,(FIND("期",pooling详情!$A$1)-FIND("第",pooling详情!$A$1)-1)),"0000")) -> VMGZ221635 | S5: =上机信息表!P5 -> 0 | T5: =IF(C5=0,"",pooling详情!$G$66) -> 8.68 | U5: =IF(C5=0,"",pooling详情!$A$80) -> 1.3 | V5: =IF(C5=0,"","illumina") -> illumina | W5: =上机信息表!X5 -> 0 | X5: =上机信息表!R5 -> 科研组+冯冬凤 | Y5: =IF(F5="RNA","RNA提取试剂盒",IF(LEFT(F5,3)="DNA","DNA提取试剂盒","")) -> DNA提取试剂盒 | Z5: =IFERROR(IF(Y5="RNA提取试剂盒",CONCATENATE(MID(上机信息表!Q5,SEARCH("提取",上机信息表!Q5),SEARCH("建",上机信息表!Q5)-2)),IF(Y5="DNA提取试剂盒",IF(ISNUMBER(FIND("呼吸道",上机信息表!Q5)),CONCATENATE(MID(上机信息表!Q5,SEARCH("提取",上机信息表!Q5),SEARCH(",",上机信息表!Q5,SEARCH("呼吸道",上机信息表!Q5))-1)),IF(ISNUMBER(FIND("组织",上机信息表!Q5)),CONCATENATE(MID(上机信息表!Q5,SEARCH("提取",上机信息表!Q5),SEARCH(",",上机信息表!Q5,SEARCH("组织",上机信息表!Q5))-1)),CONCATENATE(MID(上机信息表!Q5,SEARCH("提取",上机信息表!Q5),SEARCH(",",上机信息表!Q5)-1)))),"")),"") | AA5: =IF(F5="RNA","RNA建库试剂盒",IF(LEFT(F5,3)="DNA","DNA建库试剂盒","")) -> DNA建库试剂盒 | AB5: =IFERROR(IF(AA5="RNA建库试剂盒",MID(上机信息表!Q5,SEARCH("建库",上机信息表!Q5),20),IF(AA5="DNA建库试剂盒",MID(上机信息表!Q5,SEARCH("建库",上机信息表!Q5),20),"")),"") -> 建库RUO20260105/引物2025 | AC5: =IF(C5=0,"",CONCATENATE("芯片批号：",'IDseq-上机流程监控表'!$G$5,",","上机试剂批号：",'IDseq-上机流程监控表'!$G$6,",","Buffer批号：",'IDseq-上机流程监控表'!$G$7)) -> 芯片批号：20546839,上机试剂批号：20557000,Buffer批号：20544484
A6: =IF(C6=0,"","YF23"&TEXT(MID(pooling详情!$A$1,14,(FIND("期",pooling详情!$A$1)-FIND("第",pooling详情!$A$1)-1)),"0000")) -> YF231635 | B6: =上机信息表!G6 -> 科研样本 | C6: =上机信息表!C6 -> KY14542 | D6: =上机信息表!D6 -> VM031共提 | E6: =上机信息表!E6 -> 研磨液白蛉 | F6: =上机信息表!F6 -> DNA | G6: =上机信息表!H6 -> 破壁+prime2.0DNA建库 | H6: =上机信息表!I6 -> 0.452 | I6: =IF(F6="DNA",上机信息表!I6*70,上机信息表!I6*100) -> 31.64 | K6: =上机信息表!A6 -> 2026.5.20 | L6: =上机信息表!J6 -> 0 | M6: =上机信息表!K6 -> KY14542-1-T230D | N6: =上机信息表!L6 -> T230 | O6: =上机信息表!M6 -> 0 | P6: =上机信息表!N6 -> 14.4 | Q6: =上机信息表!O6 -> 20 | R6: =IF(C6=0,"","VMGZ22"&TEXT(MID(pooling详情!$A$1,14,(FIND("期",pooling详情!$A$1)-FIND("第",pooling详情!$A$1)-1)),"0000")) -> VMGZ221635 | S6: =上机信息表!P6 -> 0 | T6: =IF(C6=0,"",pooling详情!$G$66) -> 8.68 | U6: =IF(C6=0,"",pooling详情!$A$80) -> 1.3 | V6: =IF(C6=0,"","illumina") -> illumina | W6: =上机信息表!X6 -> 0 | X6: =上机信息表!R6 -> 科研组+冯冬凤 | Y6: =IF(F6="RNA","RNA提取试剂盒",IF(LEFT(F6,3)="DNA","DNA提取试剂盒","")) -> DNA提取试剂盒 | Z6: =IFERROR(IF(Y6="RNA提取试剂盒",CONCATENATE(MID(上机信息表!Q6,SEARCH("提取",上机信息表!Q6),SEARCH("建",上机信息表!Q6)-2)),IF(Y6="DNA提取试剂盒",IF(ISNUMBER(FIND("呼吸道",上机信息表!Q6)),CONCATENATE(MID(上机信息表!Q6,SEARCH("提取",上机信息表!Q6),SEARCH(",",上机信息表!Q6,SEARCH("呼吸道",上机信息表!Q6))-1)),IF(ISNUMBER(FIND("组织",上机信息表!Q6)),CONCATENATE(MID(上机信息表!Q6,SEARCH("提取",上机信息表!Q6),SEARCH(",",上机信息表!Q6,SEARCH("组织",上机信息表!Q6))-1)),CONCATENATE(MID(上机信息表!Q6,SEARCH("提取",上机信息表!Q6),SEARCH(",",上机信息表!Q6)-1)))),"")),"") | AA6: =IF(F6="RNA","RNA建库试剂盒",IF(LEFT(F6,3)="DNA","DNA建库试剂盒","")) -> DNA建库试剂盒 | AB6: =IFERROR(IF(AA6="RNA建库试剂盒",MID(上机信息表!Q6,SEARCH("建库",上机信息表!Q6),20),IF(AA6="DNA建库试剂盒",MID(上机信息表!Q6,SEARCH("建库",上机信息表!Q6),20),"")),"") -> 建库RUO20260105/引物2025 | AC6: =IF(C6=0,"",CONCATENATE("芯片批号：",'IDseq-上机流程监控表'!$G$5,",","上机试剂批号：",'IDseq-上机流程监控表'!$G$6,",","Buffer批号：",'IDseq-上机流程监控表'!$G$7)) -> 芯片批号：20546839,上机试剂批号：20557000,Buffer批号：20544484
A7: =IF(C7=0,"","YF23"&TEXT(MID(pooling详情!$A$1,14,(FIND("期",pooling详情!$A$1)-FIND("第",pooling详情!$A$1)-1)),"0000")) -> YF231635 | B7: =上机信息表!G7 -> 科研样本 | C7: =上机信息表!C7 -> KY14543 | D7: =上机信息表!D7 -> VM031共提 | E7: =上机信息表!E7 -> 研磨液白蛉 | F7: =上机信息表!F7 -> DNA | G7: =上机信息表!H7 -> 破壁+prime2.0DNA建库 | H7: =上机信息表!I7 -> 0.868 | I7: =IF(F7="DNA",上机信息表!I7*70,上机信息表!I7*100) -> 60.76 | K7: =上机信息表!A7 -> 2026.5.20 | L7: =上机信息表!J7 -> 0 | M7: =上机信息表!K7 -> KY14543-1-T229D | N7: =上机信息表!L7 -> T229 | O7: =上机信息表!M7 -> 0 | P7: =上机信息表!N7 -> 15.1 | Q7: =上机信息表!O7 -> 20 | R7: =IF(C7=0,"","VMGZ22"&TEXT(MID(pooling详情!$A$1,14,(FIND("期",pooling详情!$A$1)-FIND("第",pooling详情!$A$1)-1)),"0000")) -> VMGZ221635 | S7: =上机信息表!P7 -> 0 | T7: =IF(C7=0,"",pooling详情!$G$66) -> 8.68 | U7: =IF(C7=0,"",pooling详情!$A$80) -> 1.3 | V7: =IF(C7=0,"","illumina") -> illumina | W7: =上机信息表!X7 -> 0 | X7: =上机信息表!R7 -> 科研组+冯冬凤 | Y7: =IF(F7="RNA","RNA提取试剂盒",IF(LEFT(F7,3)="DNA","DNA提取试剂盒","")) -> DNA提取试剂盒 | Z7: =IFERROR(IF(Y7="RNA提取试剂盒",CONCATENATE(MID(上机信息表!Q7,SEARCH("提取",上机信息表!Q7),SEARCH("建",上机信息表!Q7)-2)),IF(Y7="DNA提取试剂盒",IF(ISNUMBER(FIND("呼吸道",上机信息表!Q7)),CONCATENATE(MID(上机信息表!Q7,SEARCH("提取",上机信息表!Q7),SEARCH(",",上机信息表!Q7,SEARCH("呼吸道",上机信息表!Q7))-1)),IF(ISNUMBER(FIND("组织",上机信息表!Q7)),CONCATENATE(MID(上机信息表!Q7,SEARCH("提取",上机信息表!Q7),SEARCH(",",上机信息表!Q7,SEARCH("组织",上机信息表!Q7))-1)),CONCATENATE(MID(上机信息表!Q7,SEARCH("提取",上机信息表!Q7),SEARCH(",",上机信息表!Q7)-1)))),"")),"") | AA7: =IF(F7="RNA","RNA建库试剂盒",IF(LEFT(F7,3)="DNA","DNA建库试剂盒","")) -> DNA建库试剂盒 | AB7: =IFERROR(IF(AA7="RNA建库试剂盒",MID(上机信息表!Q7,SEARCH("建库",上机信息表!Q7),20),IF(AA7="DNA建库试剂盒",MID(上机信息表!Q7,SEARCH("建库",上机信息表!Q7),20),"")),"") -> 建库RUO20260105/引物2025 | AC7: =IF(C7=0,"",CONCATENATE("芯片批号：",'IDseq-上机流程监控表'!$G$5,",","上机试剂批号：",'IDseq-上机流程监控表'!$G$6,",","Buffer批号：",'IDseq-上机流程监控表'!$G$7)) -> 芯片批号：20546839,上机试剂批号：20557000,Buffer批号：20544484
A8: =IF(C8=0,"","YF23"&TEXT(MID(pooling详情!$A$1,14,(FIND("期",pooling详情!$A$1)-FIND("第",pooling详情!$A$1)-1)),"0000")) | B8: =上机信息表!G8 -> 0 | C8: =上机信息表!C8 -> 0 | D8: =上机信息表!D8 -> 0 | E8: =上机信息表!E8 -> 0 | F8: =上机信息表!F8 -> 0 | G8: =上机信息表!H8 -> 0 | H8: =上机信息表!I8 -> 0 | I8: =IF(F8="DNA",上机信息表!I8*70,上机信息表!I8*100) -> 0 | K8: =上机信息表!A8 -> 0 | L8: =上机信息表!J8 -> 0 | M8: =上机信息表!K8 -> 0 | N8: =上机信息表!L8 -> 0 | O8: =上机信息表!M8 -> 0 | P8: =上机信息表!N8 -> 0 | Q8: =上机信息表!O8 -> 0 | R8: =IF(C8=0,"","VMGZ22"&TEXT(MID(pooling详情!$A$1,14,(FIND("期",pooling详情!$A$1)-FIND("第",pooling详情!$A$1)-1)),"0000")) | S8: =上机信息表!P8 -> 0 | T8: =IF(C8=0,"",pooling详情!$G$66) | U8: =IF(C8=0,"",pooling详情!$A$80) | V8: =IF(C8=0,"","illumina") | W8: =上机信息表!X8 -> 0 | X8: =上机信息表!R8 -> 0 | Y8: =IF(F8="RNA","RNA提取试剂盒",IF(LEFT(F8,3)="DNA","DNA提取试剂盒","")) | Z8: =IFERROR(IF(Y8="RNA提取试剂盒",CONCATENATE(MID(上机信息表!Q8,SEARCH("提取",上机信息表!Q8),SEARCH("建",上机信息表!Q8)-2)),IF(Y8="DNA提取试剂盒",IF(ISNUMBER(FIND("呼吸道",上机信息表!Q8)),CONCATENATE(MID(上机信息表!Q8,SEARCH("提取",上机信息表!Q8),SEARCH(",",上机信息表!Q8,SEARCH("呼吸道",上机信息表!Q8))-1)),IF(ISNUMBER(FIND("组织",上机信息表!Q8)),CONCATENATE(MID(上机信息表!Q8,SEARCH("提取",上机信息表!Q8),SEARCH(",",上机信息表!Q8,SEARCH("组织",上机信息表!Q8))-1)),CONCATENATE(MID(上机信息表!Q8,SEARCH("提取",上机信息表!Q8),SEARCH(",",上机信息表!Q8)-1)))),"")),"") | AA8: =IF(F8="RNA","RNA建库试剂盒",IF(LEFT(F8,3)="DNA","DNA建库试剂盒","")) | AB8: =IFERROR(IF(AA8="RNA建库试剂盒",MID(上机信息表!Q8,SEARCH("建库",上机信息表!Q8),20),IF(AA8="DNA建库试剂盒",MID(上机信息表!Q8,SEARCH("建库",上机信息表!Q8),20),"")),"") | AC8: =IF(C8=0,"",CONCATENATE("芯片批号：",'IDseq-上机流程监控表'!$G$5,",","上机试剂批号：",'IDseq-上机流程监控表'!$G$6,",","Buffer批号：",'IDseq-上机流程监控表'!$G$7))
A9: =IF(C9=0,"","YF23"&TEXT(MID(pooling详情!$A$1,14,(FIND("期",pooling详情!$A$1)-FIND("第",pooling详情!$A$1)-1)),"0000")) | B9: =上机信息表!G9 -> 0 | C9: =上机信息表!C9 -> 0 | D9: =上机信息表!D9 -> 0 | E9: =上机信息表!E9 -> 0 | F9: =上机信息表!F9 -> 0 | G9: =上机信息表!H9 -> 0 | H9: =上机信息表!I9 -> 0 | I9: =IF(F9="DNA",上机信息表!I9*70,上机信息表!I9*100) -> 0 | K9: =上机信息表!A9 -> 0 | L9: =上机信息表!J9 -> 0 | M9: =上机信息表!K9 -> 0 | N9: =上机信息表!L9 -> 0 | O9: =上机信息表!M9 -> 0 | P9: =上机信息表!N9 -> 0 | Q9: =上机信息表!O9 -> 0 | R9: =IF(C9=0,"","VMGZ22"&TEXT(MID(pooling详情!$A$1,14,(FIND("期",pooling详情!$A$1)-FIND("第",pooling详情!$A$1)-1)),"0000")) | S9: =上机信息表!P9 -> 0 | T9: =IF(C9=0,"",pooling详情!$G$66) | U9: =IF(C9=0,"",pooling详情!$A$80) | V9: =IF(C9=0,"","illumina") | W9: =上机信息表!X9 -> 0 | X9: =上机信息表!R9 -> 0 | Y9: =IF(F9="RNA","RNA提取试剂盒",IF(LEFT(F9,3)="DNA","DNA提取试剂盒","")) | Z9: =IFERROR(IF(Y9="RNA提取试剂盒",CONCATENATE(MID(上机信息表!Q9,SEARCH("提取",上机信息表!Q9),SEARCH("建",上机信息表!Q9)-2)),IF(Y9="DNA提取试剂盒",IF(ISNUMBER(FIND("呼吸道",上机信息表!Q9)),CONCATENATE(MID(上机信息表!Q9,SEARCH("提取",上机信息表!Q9),SEARCH(",",上机信息表!Q9,SEARCH("呼吸道",上机信息表!Q9))-1)),IF(ISNUMBER(FIND("组织",上机信息表!Q9)),CONCATENATE(MID(上机信息表!Q9,SEARCH("提取",上机信息表!Q9),SEARCH(",",上机信息表!Q9,SEARCH("组织",上机信息表!Q9))-1)),CONCATENATE(MID(上机信息表!Q9,SEARCH("提取",上机信息表!Q9),SEARCH(",",上机信息表!Q9)-1)))),"")),"") | AA9: =IF(F9="RNA","RNA建库试剂盒",IF(LEFT(F9,3)="DNA","DNA建库试剂盒","")) | AB9: =IFERROR(IF(AA9="RNA建库试剂盒",MID(上机信息表!Q9,SEARCH("建库",上机信息表!Q9),20),IF(AA9="DNA建库试剂盒",MID(上机信息表!Q9,SEARCH("建库",上机信息表!Q9),20),"")),"") | AC9: =IF(C9=0,"",CONCATENATE("芯片批号：",'IDseq-上机流程监控表'!$G$5,",","上机试剂批号：",'IDseq-上机流程监控表'!$G$6,",","Buffer批号：",'IDseq-上机流程监控表'!$G$7))
