Workbook

Sheet 样本到样信息汇总统计
A1: 医院名称 | B1: 客户名称 | C1: 科研经理 | D1: OA立项编号 | E1: 订单编号 | F1: 样本类型 | G1: 样本性质 | H1: 实收样本量 | I1: 外送测序样本量 | J1: 到样时间 | K1: 优先级 | L1: 具体实验室流程 | M1: 具体操作补充 | N1: 测序安排 | O1: 上机平台 | P1: 上机批次号 | Q1: 外送大pool号 | R1: 外送小pool号 | S1: 测序模式 | T1: 测序数据量/例 | U1: 网盘数据位置编号 | V1: 目前进展 | W1: 当前进展的时间点 | X1: 紧急序号 | Y1: 未进行序号 | Z1: 进行中序号 | AA1: 已完成序号 | AB1: 物流匹配键 | AC1: 物流序号
A2: XX省人民医院 | B2: 张主任课题组 | C2: 陈经理 | D2: PJ2026-001 | E2: ORD-2026-0001 | F2: 肿瘤组织 | G2: 核酸 | H2: 50 | I2: 48 | J2: 2026-05-20 | K2: 紧急 | L2: DNA提取→文库构建→上机测序 | M2: 需关注降解情况 | N2: 外送华大 | O2: G99 | P2: RUN-2026-001 | Q2: BPOOL-001 | R2: SPOOL-001 | S2: PE150 | T2: 6G | U2: /data/project_001 | V2: 未提取 | W2: 2026-05-22 | X2: =IF(K2="紧急",COUNTIF($K$2:K2,"紧急"),"") -> 1 | Y2: =IF(V2="未提取",COUNTIF($V$2:V2,"未提取"),"") -> 1 | Z2: =IF(OR(V2="提取中",V2="文库构建中",V2="文库质检中",V2="pooling排机中",V2="上机测序中"),SUMPRODUCT((($V$2:V2="提取中")+($V$2:V2="文库构建中")+($V$2:V2="文库质检中")+($V$2:V2="pooling排机中")+($V$2:V2="上机测序中"))*1),"") | AA2: =IF(V2="测序完成",COUNTIF($V$2:V2,"测序完成"),"") | AB2: =E2&COUNTIFS($E$2:E2,E2) -> ORD-2026-00011 | AC2: =IF(A2<>"",ROW()-1,"") -> 1
A3: XX市第一医院 | B3: 李教授团队 | C3: 陈经理 | D3: PJ2026-002 | E3: ORD-2026-0002 | F3: 血液 | G3: 原始样本 | H3: 200 | I3: 200 | J3: 2026-05-21 | K3: 重要 | L3: RNA提取→逆转录→文库构建 | M3: RNA完整性较好 | N3: 外送华大 | O3: T7 | P3: RUN-2026-002 | Q3: BPOOL-002 | R3: SPOOL-002 | S3: PE150 | T3: 12G | U3: /data/project_002 | V3: 提取中 | W3: 2026-05-23 | X3: =IF(K3="紧急",COUNTIF($K$2:K3,"紧急"),"") | Y3: =IF(V3="未提取",COUNTIF($V$2:V3,"未提取"),"") | Z3: =IF(OR(V3="提取中",V3="文库构建中",V3="文库质检中",V3="pooling排机中",V3="上机测序中"),SUMPRODUCT((($V$2:V3="提取中")+($V$2:V3="文库构建中")+($V$2:V3="文库质检中")+($V$2:V3="pooling排机中")+($V$2:V3="上机测序中"))*1),"") -> 1 | AA3: =IF(V3="测序完成",COUNTIF($V$2:V3,"测序完成"),"") | AB3: =E3&COUNTIFS($E$2:E3,E3) -> ORD-2026-00021 | AC3: =IF(A3<>"",ROW()-1,"") -> 2
A4: XX大学附属医院 | B4: 王博士实验室 | C4: 林经理 | D4: PJ2026-003 | E4: ORD-2026-0003 | F4: FFPE | G4: 文库 | H4: 30 | I4: 30 | J4: 2026-05-22 | K4: 常规 | L4: 质检→文库构建→上机测序 | M4: 切片厚度5μm | N4: 外送解达 | O4: illumina | P4: RUN-2026-003 | Q4: BPOOL-003 | R4: SPOOL-003 | S4: SE50 | T4: 3G | U4: /data/project_003 | V4: 文库构建中 | W4: 2026-05-24 | X4: =IF(K4="紧急",COUNTIF($K$2:K4,"紧急"),"") | Y4: =IF(V4="未提取",COUNTIF($V$2:V4,"未提取"),"") | Z4: =IF(OR(V4="提取中",V4="文库构建中",V4="文库质检中",V4="pooling排机中",V4="上机测序中"),SUMPRODUCT((($V$2:V4="提取中")+($V$2:V4="文库构建中")+($V$2:V4="文库质检中")+($V$2:V4="pooling排机中")+($V$2:V4="上机测序中"))*1),"") -> 2 | AA4: =IF(V4="测序完成",COUNTIF($V$2:V4,"测序完成"),"") | AB4: =E4&COUNTIFS($E$2:E4,E4) -> ORD-2026-00031 | AC4: =IF(A4<>"",ROW()-1,"") -> 3
A5: XX肿瘤医院 | B5: 赵主任课题组 | C5: 林经理 | D5: PJ2026-004 | E5: ORD-2026-0004 | F5: 细胞 | G5: 核酸 | H5: 15 | I5: 15 | J5: 2026-05-23 | K5: 紧急 | L5: DNA提取→PCR扩增→文库构建 | M5: 细胞活性>90% | N5: 内部上机 | O5: Vision | P5: RUN-2026-004 | Q5: BPOOL-004 | R5: SPOOL-004 | S5: PE150 | T5: 6G | U5: /data/project_004 | V5: 文库质检中 | W5: 2026-05-24 | X5: =IF(K5="紧急",COUNTIF($K$2:K5,"紧急"),"") -> 2 | Y5: =IF(V5="未提取",COUNTIF($V$2:V5,"未提取"),"") | Z5: =IF(OR(V5="提取中",V5="文库构建中",V5="文库质检中",V5="pooling排机中",V5="上机测序中"),SUMPRODUCT((($V$2:V5="提取中")+($V$2:V5="文库构建中")+($V$2:V5="文库质检中")+($V$2:V5="pooling排机中")+($V$2:V5="上机测序中"))*1),"") -> 3 | AA5: =IF(V5="测序完成",COUNTIF($V$2:V5,"测序完成"),"") | AB5: =E5&COUNTIFS($E$2:E5,E5) -> ORD-2026-00041 | AC5: =IF(A5<>"",ROW()-1,"") -> 4
A6: XX儿童医院 | B6: 刘教授团队 | C6: 陈经理 | D6: PJ2026-005 | E6: ORD-2026-0005 | F6: 脑脊液 | G6: 原始样本 | H6: 100 | I6: 100 | J6: 2026-05-24 | K6: 重要 | L6: DNA提取→文库构建→上机测序 | M6: 需加急处理 | N6: 外送华大 | O6: T7+ | P6: RUN-2026-005 | Q6: BPOOL-005 | R6: SPOOL-005 | S6: PE150 | T6: 6G | U6: /data/project_005 | V6: pooling排机中 | W6: 2026-05-23 | X6: =IF(K6="紧急",COUNTIF($K$2:K6,"紧急"),"") | Y6: =IF(V6="未提取",COUNTIF($V$2:V6,"未提取"),"") | Z6: =IF(OR(V6="提取中",V6="文库构建中",V6="文库质检中",V6="pooling排机中",V6="上机测序中"),SUMPRODUCT((($V$2:V6="提取中")+($V$2:V6="文库构建中")+($V$2:V6="文库质检中")+($V$2:V6="pooling排机中")+($V$2:V6="上机测序中"))*1),"") -> 4 | AA6: =IF(V6="测序完成",COUNTIF($V$2:V6,"测序完成"),"") | AB6: =E6&COUNTIFS($E$2:E6,E6) -> ORD-2026-00051 | AC6: =IF(A6<>"",ROW()-1,"") -> 5
A7: XX儿童医院 | B7: 刘教授团队 | C7: 陈经理 | D7: PJ2026-006 | E7: ORD-2026-0006 | F7: 脑脊液 | G7: 原始样本 | H7: 100 | I7: 100 | J7: 2026-05-24 | K7: 紧急 | L7: DNA提取→文库构建→上机测序 | M7: 需加急处理 | N7: 外送华大 | O7: T7+ | P7: RUN-2026-005 | Q7: BPOOL-005 | R7: SPOOL-005 | S7: PE150 | T7: 6G | U7: /data/project_005 | V7: pooling排机中 | W7: 2026-05-23 | X7: =IF(K7="紧急",COUNTIF($K$2:K7,"紧急"),"") -> 3 | Y7: =IF(V7="未提取",COUNTIF($V$2:V7,"未提取"),"") | Z7: =IF(OR(V7="提取中",V7="文库构建中",V7="文库质检中",V7="pooling排机中",V7="上机测序中"),SUMPRODUCT((($V$2:V7="提取中")+($V$2:V7="文库构建中")+($V$2:V7="文库质检中")+($V$2:V7="pooling排机中")+($V$2:V7="上机测序中"))*1),"") -> 5 | AA7: =IF(V7="测序完成",COUNTIF($V$2:V7,"测序完成"),"") | AB7: =E7&COUNTIFS($E$2:E7,E7) -> ORD-2026-00061 | AC7: =IF(A7<>"",ROW()-1,"") -> 6
A8: XX儿童医院 | B8: 刘教授团队 | C8: 陈经理 | D8: PJ2026-007 | E8: ORD-2026-0007 | F8: 脑脊液 | G8: 原始样本 | H8: 100 | I8: 100 | J8: 2026-05-24 | K8: 紧急 | L8: DNA提取→文库构建→上机测序 | M8: 需加急处理 | N8: 外送华大 | O8: T7+ | P8: RUN-2026-005 | Q8: BPOOL-005 | R8: SPOOL-005 | S8: PE150 | T8: 6G | U8: /data/project_005 | V8: pooling排机中 | W8: 2026-05-23 | X8: =IF(K8="紧急",COUNTIF($K$2:K8,"紧急"),"") -> 4 | Y8: =IF(V8="未提取",COUNTIF($V$2:V8,"未提取"),"") | Z8: =IF(OR(V8="提取中",V8="文库构建中",V8="文库质检中",V8="pooling排机中",V8="上机测序中"),SUMPRODUCT((($V$2:V8="提取中")+($V$2:V8="文库构建中")+($V$2:V8="文库质检中")+($V$2:V8="pooling排机中")+($V$2:V8="上机测序中"))*1),"") -> 6 | AA8: =IF(V8="测序完成",COUNTIF($V$2:V8,"测序完成"),"") | AB8: =E8&COUNTIFS($E$2:E8,E8) -> ORD-2026-00071 | AC8: =IF(A8<>"",ROW()-1,"") -> 7
A9: XX儿童医院 | B9: 刘教授团队 | C9: 陈经理 | D9: PJ2026-008 | E9: ORD-2026-0008 | F9: 脑脊液 | G9: 原始样本 | H9: 100 | I9: 100 | J9: 2026-05-24 | K9: 重要 | L9: DNA提取→文库构建→上机测序 | M9: 需加急处理 | N9: 外送华大 | O9: T7+ | P9: RUN-2026-005 | Q9: BPOOL-005 | R9: SPOOL-005 | S9: PE150 | T9: 6G | U9: /data/project_005 | V9: pooling排机中 | W9: 2026-05-23 | X9: =IF(K9="紧急",COUNTIF($K$2:K9,"紧急"),"") | Y9: =IF(V9="未提取",COUNTIF($V$2:V9,"未提取"),"") | Z9: =IF(OR(V9="提取中",V9="文库构建中",V9="文库质检中",V9="pooling排机中",V9="上机测序中"),SUMPRODUCT((($V$2:V9="提取中")+($V$2:V9="文库构建中")+($V$2:V9="文库质检中")+($V$2:V9="pooling排机中")+($V$2:V9="上机测序中"))*1),"") -> 7 | AA9: =IF(V9="测序完成",COUNTIF($V$2:V9,"测序完成"),"") | AB9: =E9&COUNTIFS($E$2:E9,E9) -> ORD-2026-00081 | AC9: =IF(A9<>"",ROW()-1,"") -> 8
A10: XX儿童医院 | B10: 刘教授团队 | C10: 陈经理 | D10: PJ2026-009 | E10: ORD-2026-0009 | F10: 脑脊液 | G10: 原始样本 | H10: 100 | I10: 100 | J10: 2026-05-24 | K10: 紧急 | L10: DNA提取→文库构建→上机测序 | M10: 需加急处理 | N10: 外送华大 | O10: T7+ | P10: RUN-2026-005 | Q10: BPOOL-005 | R10: SPOOL-005 | S10: PE150 | T10: 6G | U10: /data/project_005 | V10: pooling排机中 | W10: 2026-05-23 | X10: =IF(K10="紧急",COUNTIF($K$2:K10,"紧急"),"") -> 5 | Y10: =IF(V10="未提取",COUNTIF($V$2:V10,"未提取"),"") | Z10: =IF(OR(V10="提取中",V10="文库构建中",V10="文库质检中",V10="pooling排机中",V10="上机测序中"),SUMPRODUCT((($V$2:V10="提取中")+($V$2:V10="文库构建中")+($V$2:V10="文库质检中")+($V$2:V10="pooling排机中")+($V$2:V10="上机测序中"))*1),"") -> 8 | AA10: =IF(V10="测序完成",COUNTIF($V$2:V10,"测序完成"),"") | AB10: =E10&COUNTIFS($E$2:E10,E10) -> ORD-2026-00091 | AC10: =IF(A10<>"",ROW()-1,"") -> 9
A11: XX儿童医院 | B11: 刘教授团队 | C11: 陈经理 | D11: PJ2026-010 | E11: ORD-2026-0010 | F11: 脑脊液 | G11: 原始样本 | H11: 100 | I11: 100 | J11: 2026-05-24 | K11: 紧急 | L11: DNA提取→文库构建→上机测序 | M11: 需加急处理 | N11: 外送华大 | O11: T7+ | P11: RUN-2026-005 | Q11: BPOOL-005 | R11: SPOOL-005 | S11: PE150 | T11: 6G | U11: /data/project_005 | V11: pooling排机中 | W11: 2026-05-23 | X11: =IF(K11="紧急",COUNTIF($K$2:K11,"紧急"),"") -> 6 | Y11: =IF(V11="未提取",COUNTIF($V$2:V11,"未提取"),"") | Z11: =IF(OR(V11="提取中",V11="文库构建中",V11="文库质检中",V11="pooling排机中",V11="上机测序中"),SUMPRODUCT((($V$2:V11="提取中")+($V$2:V11="文库构建中")+($V$2:V11="文库质检中")+($V$2:V11="pooling排机中")+($V$2:V11="上机测序中"))*1),"") -> 9 | AA11: =IF(V11="测序完成",COUNTIF($V$2:V11,"测序完成"),"") | AB11: =E11&COUNTIFS($E$2:E11,E11) -> ORD-2026-00101 | AC11: =IF(A11<>"",ROW()-1,"") -> 10
X12: =IF(K12="紧急",COUNTIF($K$2:K12,"紧急"),"") | Y12: =IF(V12="未提取",COUNTIF($V$2:V12,"未提取"),"") | Z12: =IF(OR(V12="提取中",V12="文库构建中",V12="文库质检中",V12="pooling排机中",V12="上机测序中"),SUMPRODUCT((($V$2:V12="提取中")+($V$2:V12="文库构建中")+($V$2:V12="文库质检中")+($V$2:V12="pooling排机中")+($V$2:V12="上机测序中"))*1),"") | AA12: =IF(V12="测序完成",COUNTIF($V$2:V12,"测序完成"),"") | AB12: =E12&COUNTIFS($E$2:E12,E12) -> 0 | AC12: =IF(A12<>"",ROW()-1,"")
X13: =IF(K13="紧急",COUNTIF($K$2:K13,"紧急"),"") | Y13: =IF(V13="未提取",COUNTIF($V$2:V13,"未提取"),"") | Z13: =IF(OR(V13="提取中",V13="文库构建中",V13="文库质检中",V13="pooling排机中",V13="上机测序中"),SUMPRODUCT((($V$2:V13="提取中")+($V$2:V13="文库构建中")+($V$2:V13="文库质检中")+($V$2:V13="pooling排机中")+($V$2:V13="上机测序中"))*1),"") | AA13: =IF(V13="测序完成",COUNTIF($V$2:V13,"测序完成"),"") | AB13: =E13&COUNTIFS($E$2:E13,E13) -> 0 | AC13: =IF(A13<>"",ROW()-1,"")
X14: =IF(K14="紧急",COUNTIF($K$2:K14,"紧急"),"") | Y14: =IF(V14="未提取",COUNTIF($V$2:V14,"未提取"),"") | Z14: =IF(OR(V14="提取中",V14="文库构建中",V14="文库质检中",V14="pooling排机中",V14="上机测序中"),SUMPRODUCT((($V$2:V14="提取中")+($V$2:V14="文库构建中")+($V$2:V14="文库质检中")+($V$2:V14="pooling排机中")+($V$2:V14="上机测序中"))*1),"") | AA14: =IF(V14="测序完成",COUNTIF($V$2:V14,"测序完成"),"") | AB14: =E14&COUNTIFS($E$2:E14,E14) -> 0 | AC14: =IF(A14<>"",ROW()-1,"")
X15: =IF(K15="紧急",COUNTIF($K$2:K15,"紧急"),"") | Y15: =IF(V15="未提取",COUNTIF($V$2:V15,"未提取"),"") | Z15: =IF(OR(V15="提取中",V15="文库构建中",V15="文库质检中",V15="pooling排机中",V15="上机测序中"),SUMPRODUCT((($V$2:V15="提取中")+($V$2:V15="文库构建中")+($V$2:V15="文库质检中")+($V$2:V15="pooling排机中")+($V$2:V15="上机测序中"))*1),"") | AA15: =IF(V15="测序完成",COUNTIF($V$2:V15,"测序完成"),"") | AB15: =E15&COUNTIFS($E$2:E15,E15) -> 0 | AC15: =IF(A15<>"",ROW()-1,"")
X16: =IF(K16="紧急",COUNTIF($K$2:K16,"紧急"),"") | Y16: =IF(V16="未提取",COUNTIF($V$2:V16,"未提取"),"") | Z16: =IF(OR(V16="提取中",V16="文库构建中",V16="文库质检中",V16="pooling排机中",V16="上机测序中"),SUMPRODUCT((($V$2:V16="提取中")+($V$2:V16="文库构建中")+($V$2:V16="文库质检中")+($V$2:V16="pooling排机中")+($V$2:V16="上机测序中"))*1),"") | AA16: =IF(V16="测序完成",COUNTIF($V$2:V16,"测序完成"),"") | AB16: =E16&COUNTIFS($E$2:E16,E16) -> 0 | AC16: =IF(A16<>"",ROW()-1,"")
X17: =IF(K17="紧急",COUNTIF($K$2:K17,"紧急"),"") | Y17: =IF(V17="未提取",COUNTIF($V$2:V17,"未提取"),"") | Z17: =IF(OR(V17="提取中",V17="文库构建中",V17="文库质检中",V17="pooling排机中",V17="上机测序中"),SUMPRODUCT((($V$2:V17="提取中")+($V$2:V17="文库构建中")+($V$2:V17="文库质检中")+($V$2:V17="pooling排机中")+($V$2:V17="上机测序中"))*1),"") | AA17: =IF(V17="测序完成",COUNTIF($V$2:V17,"测序完成"),"") | AB17: =E17&COUNTIFS($E$2:E17,E17) -> 0 | AC17: =IF(A17<>"",ROW()-1,"")
X18: =IF(K18="紧急",COUNTIF($K$2:K18,"紧急"),"") | Y18: =IF(V18="未提取",COUNTIF($V$2:V18,"未提取"),"") | Z18: =IF(OR(V18="提取中",V18="文库构建中",V18="文库质检中",V18="pooling排机中",V18="上机测序中"),SUMPRODUCT((($V$2:V18="提取中")+($V$2:V18="文库构建中")+($V$2:V18="文库质检中")+($V$2:V18="pooling排机中")+($V$2:V18="上机测序中"))*1),"") | AA18: =IF(V18="测序完成",COUNTIF($V$2:V18,"测序完成"),"") | AB18: =E18&COUNTIFS($E$2:E18,E18) -> 0 | AC18: =IF(A18<>"",ROW()-1,"")
X19: =IF(K19="紧急",COUNTIF($K$2:K19,"紧急"),"") | Y19: =IF(V19="未提取",COUNTIF($V$2:V19,"未提取"),"") | Z19: =IF(OR(V19="提取中",V19="文库构建中",V19="文库质检中",V19="pooling排机中",V19="上机测序中"),SUMPRODUCT((($V$2:V19="提取中")+($V$2:V19="文库构建中")+($V$2:V19="文库质检中")+($V$2:V19="pooling排机中")+($V$2:V19="上机测序中"))*1),"") | AA19: =IF(V19="测序完成",COUNTIF($V$2:V19,"测序完成"),"") | AB19: =E19&COUNTIFS($E$2:E19,E19) -> 0 | AC19: =IF(A19<>"",ROW()-1,"")
X20: =IF(K20="紧急",COUNTIF($K$2:K20,"紧急"),"") | Y20: =IF(V20="未提取",COUNTIF($V$2:V20,"未提取"),"") | Z20: =IF(OR(V20="提取中",V20="文库构建中",V20="文库质检中",V20="pooling排机中",V20="上机测序中"),SUMPRODUCT((($V$2:V20="提取中")+($V$2:V20="文库构建中")+($V$2:V20="文库质检中")+($V$2:V20="pooling排机中")+($V$2:V20="上机测序中"))*1),"") | AA20: =IF(V20="测序完成",COUNTIF($V$2:V20,"测序完成"),"") | AB20: =E20&COUNTIFS($E$2:E20,E20) -> 0 | AC20: =IF(A20<>"",ROW()-1,"")
X21: =IF(K21="紧急",COUNTIF($K$2:K21,"紧急"),"") | Y21: =IF(V21="未提取",COUNTIF($V$2:V21,"未提取"),"") | Z21: =IF(OR(V21="提取中",V21="文库构建中",V21="文库质检中",V21="pooling排机中",V21="上机测序中"),SUMPRODUCT((($V$2:V21="提取中")+($V$2:V21="文库构建中")+($V$2:V21="文库质检中")+($V$2:V21="pooling排机中")+($V$2:V21="上机测序中"))*1),"") | AA21: =IF(V21="测序完成",COUNTIF($V$2:V21,"测序完成"),"") | AB21: =E21&COUNTIFS($E$2:E21,E21) -> 0 | AC21: =IF(A21<>"",ROW()-1,"")
X22: =IF(K22="紧急",COUNTIF($K$2:K22,"紧急"),"") | Y22: =IF(V22="未提取",COUNTIF($V$2:V22,"未提取"),"") | Z22: =IF(OR(V22="提取中",V22="文库构建中",V22="文库质检中",V22="pooling排机中",V22="上机测序中"),SUMPRODUCT((($V$2:V22="提取中")+($V$2:V22="文库构建中")+($V$2:V22="文库质检中")+($V$2:V22="pooling排机中")+($V$2:V22="上机测序中"))*1),"") | AA22: =IF(V22="测序完成",COUNTIF($V$2:V22,"测序完成"),"") | AB22: =E22&COUNTIFS($E$2:E22,E22) -> 0 | AC22: =IF(A22<>"",ROW()-1,"")
X23: =IF(K23="紧急",COUNTIF($K$2:K23,"紧急"),"") | Y23: =IF(V23="未提取",COUNTIF($V$2:V23,"未提取"),"") | Z23: =IF(OR(V23="提取中",V23="文库构建中",V23="文库质检中",V23="pooling排机中",V23="上机测序中"),SUMPRODUCT((($V$2:V23="提取中")+($V$2:V23="文库构建中")+($V$2:V23="文库质检中")+($V$2:V23="pooling排机中")+($V$2:V23="上机测序中"))*1),"") | AA23: =IF(V23="测序完成",COUNTIF($V$2:V23,"测序完成"),"") | AB23: =E23&COUNTIFS($E$2:E23,E23) -> 0 | AC23: =IF(A23<>"",ROW()-1,"")
... X500: =IF(K500="紧急",COUNTIF($K$2:K500,"紧急"),"") | Y500: =IF(V500="未提取",COUNTIF($V$2:V500,"未提取"),"") | Z500: =IF(OR(V500="提取中",V500="文库构建中",V500="文库质检中",V500="pooling排机中",V500="上机测序中"),SUMPRODUCT((($V$2:V500="提取中")+($V$2:V500="文库构建中")+($V$2:V500="文库质检中")+($V$2:V500="pooling排机中")+($V$2:V500="上机测序中"))*1),"") | AA500: =IF(V500="测序完成",COUNTIF($V$2:V500,"测序完成"),"") | AB500: =E500&COUNTIFS($E$2:E500,E500) -> 0 | AC500: =IF(A500<>"",ROW()-1,"")

Sheet 紧急项目列表
A1: 医院名称 | B1: 客户名称 | C1: 科研经理 | D1: OA立项编号 | E1: 订单编号 | F1: 样本类型 | G1: 样本性质 | H1: 实收样本量 | I1: 外送测序样本量 | J1: 到样时间 | K1: 优先级 | L1: 具体实验室流程 | M1: 具体操作补充 | N1: 测序安排 | O1: 上机平台 | P1: 上机批次号 | Q1: 外送大pool号 | R1: 外送小pool号 | S1: 测序模式 | T1: 测序数据量/例 | U1: 网盘数据位置编号 | V1: 目前进展 | W1: 当前进展的时间点
A2: =IFERROR(INDEX(样本到样信息汇总统计!A$2:A$500,MATCH(1,样本到样信息汇总统计!$X$2:$X$500,0)),"") -> XX省人民医院 | B2: =IFERROR(INDEX(样本到样信息汇总统计!B$2:B$500,MATCH(1,样本到样信息汇总统计!$X$2:$X$500,0)),"") -> 张主任课题组 | C2: =IFERROR(INDEX(样本到样信息汇总统计!C$2:C$500,MATCH(1,样本到样信息汇总统计!$X$2:$X$500,0)),"") -> 陈经理 | D2: =IFERROR(INDEX(样本到样信息汇总统计!D$2:D$500,MATCH(1,样本到样信息汇总统计!$X$2:$X$500,0)),"") -> PJ2026-001 | E2: =IFERROR(INDEX(样本到样信息汇总统计!E$2:E$500,MATCH(1,样本到样信息汇总统计!$X$2:$X$500,0)),"") -> ORD-2026-0001 | F2: =IFERROR(INDEX(样本到样信息汇总统计!F$2:F$500,MATCH(1,样本到样信息汇总统计!$X$2:$X$500,0)),"") -> 肿瘤组织 | G2: =IFERROR(INDEX(样本到样信息汇总统计!G$2:G$500,MATCH(1,样本到样信息汇总统计!$X$2:$X$500,0)),"") -> 核酸 | H2: =IFERROR(INDEX(样本到样信息汇总统计!H$2:H$500,MATCH(1,样本到样信息汇总统计!$X$2:$X$500,0)),"") -> 50 | ... W2: =IFERROR(INDEX(样本到样信息汇总统计!W$2:W$500,MATCH(1,样本到样信息汇总统计!$X$2:$X$500,0)),"") -> 2026-05-22
A3: =IFERROR(INDEX(样本到样信息汇总统计!A$2:A$500,MATCH(2,样本到样信息汇总统计!$X$2:$X$500,0)),"") -> XX肿瘤医院 | B3: =IFERROR(INDEX(样本到样信息汇总统计!B$2:B$500,MATCH(2,样本到样信息汇总统计!$X$2:$X$500,0)),"") -> 赵主任课题组 | C3: =IFERROR(INDEX(样本到样信息汇总统计!C$2:C$500,MATCH(2,样本到样信息汇总统计!$X$2:$X$500,0)),"") -> 林经理 | D3: =IFERROR(INDEX(样本到样信息汇总统计!D$2:D$500,MATCH(2,样本到样信息汇总统计!$X$2:$X$500,0)),"") -> PJ2026-004 | E3: =IFERROR(INDEX(样本到样信息汇总统计!E$2:E$500,MATCH(2,样本到样信息汇总统计!$X$2:$X$500,0)),"") -> ORD-2026-0004 | F3: =IFERROR(INDEX(样本到样信息汇总统计!F$2:F$500,MATCH(2,样本到样信息汇总统计!$X$2:$X$500,0)),"") -> 细胞 | G3: =IFERROR(INDEX(样本到样信息汇总统计!G$2:G$500,MATCH(2,样本到样信息汇总统计!$X$2:$X$500,0)),"") -> 核酸 | H3: =IFERROR(INDEX(样本到样信息汇总统计!H$2:H$500,MATCH(2,样本到样信息汇总统计!$X$2:$X$500,0)),"") -> 15 | ... W3: =IFERROR(INDEX(样本到样信息汇总统计!W$2:W$500,MATCH(2,样本到样信息汇总统计!$X$2:$X$500,0)),"") -> 2026-05-24
A4: =IFERROR(INDEX(样本到样信息汇总统计!A$2:A$500,MATCH(3,样本到样信息汇总统计!$X$2:$X$500,0)),"") -> XX儿童医院 | B4: =IFERROR(INDEX(样本到样信息汇总统计!B$2:B$500,MATCH(3,样本到样信息汇总统计!$X$2:$X$500,0)),"") -> 刘教授团队 | C4: =IFERROR(INDEX(样本到样信息汇总统计!C$2:C$500,MATCH(3,样本到样信息汇总统计!$X$2:$X$500,0)),"") -> 陈经理 | D4: =IFERROR(INDEX(样本到样信息汇总统计!D$2:D$500,MATCH(3,样本到样信息汇总统计!$X$2:$X$500,0)),"") -> PJ2026-006 | E4: =IFERROR(INDEX(样本到样信息汇总统计!E$2:E$500,MATCH(3,样本到样信息汇总统计!$X$2:$X$500,0)),"") -> ORD-2026-0006 | F4: =IFERROR(INDEX(样本到样信息汇总统计!F$2:F$500,MATCH(3,样本到样信息汇总统计!$X$2:$X$500,0)),"") -> 脑脊液 | G4: =IFERROR(INDEX(样本到样信息汇总统计!G$2:G$500,MATCH(3,样本到样信息汇总统计!$X$2:$X$500,0)),"") -> 原始样本 | H4: =IFERROR(INDEX(样本到样信息汇总统计!H$2:H$500,MATCH(3,样本到样信息汇总统计!$X$2:$X$500,0)),"") -> 100 | ... W4: =IFERROR(INDEX(样本到样信息汇总统计!W$2:W$500,MATCH(3,样本到样信息汇总统计!$X$2:$X$500,0)),"") -> 2026-05-23
A5: =IFERROR(INDEX(样本到样信息汇总统计!A$2:A$500,MATCH(4,样本到样信息汇总统计!$X$2:$X$500,0)),"") -> XX儿童医院 | B5: =IFERROR(INDEX(样本到样信息汇总统计!B$2:B$500,MATCH(4,样本到样信息汇总统计!$X$2:$X$500,0)),"") -> 刘教授团队 | C5: =IFERROR(INDEX(样本到样信息汇总统计!C$2:C$500,MATCH(4,样本到样信息汇总统计!$X$2:$X$500,0)),"") -> 陈经理 | D5: =IFERROR(INDEX(样本到样信息汇总统计!D$2:D$500,MATCH(4,样本到样信息汇总统计!$X$2:$X$500,0)),"") -> PJ2026-007 | E5: =IFERROR(INDEX(样本到样信息汇总统计!E$2:E$500,MATCH(4,样本到样信息汇总统计!$X$2:$X$500,0)),"") -> ORD-2026-0007 | F5: =IFERROR(INDEX(样本到样信息汇总统计!F$2:F$500,MATCH(4,样本到样信息汇总统计!$X$2:$X$500,0)),"") -> 脑脊液 | G5: =IFERROR(INDEX(样本到样信息汇总统计!G$2:G$500,MATCH(4,样本到样信息汇总统计!$X$2:$X$500,0)),"") -> 原始样本 | H5: =IFERROR(INDEX(样本到样信息汇总统计!H$2:H$500,MATCH(4,样本到样信息汇总统计!$X$2:$X$500,0)),"") -> 100 | ... W5: =IFERROR(INDEX(样本到样信息汇总统计!W$2:W$500,MATCH(4,样本到样信息汇总统计!$X$2:$X$500,0)),"") -> 2026-05-23
A6: =IFERROR(INDEX(样本到样信息汇总统计!A$2:A$500,MATCH(5,样本到样信息汇总统计!$X$2:$X$500,0)),"") -> XX儿童医院 | B6: =IFERROR(INDEX(样本到样信息汇总统计!B$2:B$500,MATCH(5,样本到样信息汇总统计!$X$2:$X$500,0)),"") -> 刘教授团队 | C6: =IFERROR(INDEX(样本到样信息汇总统计!C$2:C$500,MATCH(5,样本到样信息汇总统计!$X$2:$X$500,0)),"") -> 陈经理 | D6: =IFERROR(INDEX(样本到样信息汇总统计!D$2:D$500,MATCH(5,样本到样信息汇总统计!$X$2:$X$500,0)),"") -> PJ2026-009 | E6: =IFERROR(INDEX(样本到样信息汇总统计!E$2:E$500,MATCH(5,样本到样信息汇总统计!$X$2:$X$500,0)),"") -> ORD-2026-0009 | F6: =IFERROR(INDEX(样本到样信息汇总统计!F$2:F$500,MATCH(5,样本到样信息汇总统计!$X$2:$X$500,0)),"") -> 脑脊液 | G6: =IFERROR(INDEX(样本到样信息汇总统计!G$2:G$500,MATCH(5,样本到样信息汇总统计!$X$2:$X$500,0)),"") -> 原始样本 | H6: =IFERROR(INDEX(样本到样信息汇总统计!H$2:H$500,MATCH(5,样本到样信息汇总统计!$X$2:$X$500,0)),"") -> 100 | ... W6: =IFERROR(INDEX(样本到样信息汇总统计!W$2:W$500,MATCH(5,样本到样信息汇总统计!$X$2:$X$500,0)),"") -> 2026-05-23
A7: =IFERROR(INDEX(样本到样信息汇总统计!A$2:A$500,MATCH(6,样本到样信息汇总统计!$X$2:$X$500,0)),"") -> XX儿童医院 | B7: =IFERROR(INDEX(样本到样信息汇总统计!B$2:B$500,MATCH(6,样本到样信息汇总统计!$X$2:$X$500,0)),"") -> 刘教授团队 | C7: =IFERROR(INDEX(样本到样信息汇总统计!C$2:C$500,MATCH(6,样本到样信息汇总统计!$X$2:$X$500,0)),"") -> 陈经理 | D7: =IFERROR(INDEX(样本到样信息汇总统计!D$2:D$500,MATCH(6,样本到样信息汇总统计!$X$2:$X$500,0)),"") -> PJ2026-010 | E7: =IFERROR(INDEX(样本到样信息汇总统计!E$2:E$500,MATCH(6,样本到样信息汇总统计!$X$2:$X$500,0)),"") -> ORD-2026-0010 | F7: =IFERROR(INDEX(样本到样信息汇总统计!F$2:F$500,MATCH(6,样本到样信息汇总统计!$X$2:$X$500,0)),"") -> 脑脊液 | G7: =IFERROR(INDEX(样本到样信息汇总统计!G$2:G$500,MATCH(6,样本到样信息汇总统计!$X$2:$X$500,0)),"") -> 原始样本 | H7: =IFERROR(INDEX(样本到样信息汇总统计!H$2:H$500,MATCH(6,样本到样信息汇总统计!$X$2:$X$500,0)),"") -> 100 | ... W7: =IFERROR(INDEX(样本到样信息汇总统计!W$2:W$500,MATCH(6,样本到样信息汇总统计!$X$2:$X$500,0)),"") -> 2026-05-23
A8: =IFERROR(INDEX(样本到样信息汇总统计!A$2:A$500,MATCH(7,样本到样信息汇总统计!$X$2:$X$500,0)),"") | B8: =IFERROR(INDEX(样本到样信息汇总统计!B$2:B$500,MATCH(7,样本到样信息汇总统计!$X$2:$X$500,0)),"") | C8: =IFERROR(INDEX(样本到样信息汇总统计!C$2:C$500,MATCH(7,样本到样信息汇总统计!$X$2:$X$500,0)),"") | D8: =IFERROR(INDEX(样本到样信息汇总统计!D$2:D$500,MATCH(7,样本到样信息汇总统计!$X$2:$X$500,0)),"") | E8: =IFERROR(INDEX(样本到样信息汇总统计!E$2:E$500,MATCH(7,样本到样信息汇总统计!$X$2:$X$500,0)),"") | F8: =IFERROR(INDEX(样本到样信息汇总统计!F$2:F$500,MATCH(7,样本到样信息汇总统计!$X$2:$X$500,0)),"") | G8: =IFERROR(INDEX(样本到样信息汇总统计!G$2:G$500,MATCH(7,样本到样信息汇总统计!$X$2:$X$500,0)),"") | H8: =IFERROR(INDEX(样本到样信息汇总统计!H$2:H$500,MATCH(7,样本到样信息汇总统计!$X$2:$X$500,0)),"") | ... W8: =IFERROR(INDEX(样本到样信息汇总统计!W$2:W$500,MATCH(7,样本到样信息汇总统计!$X$2:$X$500,0)),"")
A9: =IFERROR(INDEX(样本到样信息汇总统计!A$2:A$500,MATCH(8,样本到样信息汇总统计!$X$2:$X$500,0)),"") | B9: =IFERROR(INDEX(样本到样信息汇总统计!B$2:B$500,MATCH(8,样本到样信息汇总统计!$X$2:$X$500,0)),"") | C9: =IFERROR(INDEX(样本到样信息汇总统计!C$2:C$500,MATCH(8,样本到样信息汇总统计!$X$2:$X$500,0)),"") | D9: =IFERROR(INDEX(样本到样信息汇总统计!D$2:D$500,MATCH(8,样本到样信息汇总统计!$X$2:$X$500,0)),"") | E9: =IFERROR(INDEX(样本到样信息汇总统计!E$2:E$500,MATCH(8,样本到样信息汇总统计!$X$2:$X$500,0)),"") | F9: =IFERROR(INDEX(样本到样信息汇总统计!F$2:F$500,MATCH(8,样本到样信息汇总统计!$X$2:$X$500,0)),"") | G9: =IFERROR(INDEX(样本到样信息汇总统计!G$2:G$500,MATCH(8,样本到样信息汇总统计!$X$2:$X$500,0)),"") | H9: =IFERROR(INDEX(样本到样信息汇总统计!H$2:H$500,MATCH(8,样本到样信息汇总统计!$X$2:$X$500,0)),"") | ... W9: =IFERROR(INDEX(样本到样信息汇总统计!W$2:W$500,MATCH(8,样本到样信息汇总统计!$X$2:$X$500,0)),"")
A10: =IFERROR(INDEX(样本到样信息汇总统计!A$2:A$500,MATCH(9,样本到样信息汇总统计!$X$2:$X$500,0)),"") | B10: =IFERROR(INDEX(样本到样信息汇总统计!B$2:B$500,MATCH(9,样本到样信息汇总统计!$X$2:$X$500,0)),"") | C10: =IFERROR(INDEX(样本到样信息汇总统计!C$2:C$500,MATCH(9,样本到样信息汇总统计!$X$2:$X$500,0)),"") | D10: =IFERROR(INDEX(样本到样信息汇总统计!D$2:D$500,MATCH(9,样本到样信息汇总统计!$X$2:$X$500,0)),"") | E10: =IFERROR(INDEX(样本到样信息汇总统计!E$2:E$500,MATCH(9,样本到样信息汇总统计!$X$2:$X$500,0)),"") | F10: =IFERROR(INDEX(样本到样信息汇总统计!F$2:F$500,MATCH(9,样本到样信息汇总统计!$X$2:$X$500,0)),"") | G10: =IFERROR(INDEX(样本到样信息汇总统计!G$2:G$500,MATCH(9,样本到样信息汇总统计!$X$2:$X$500,0)),"") | H10: =IFERROR(INDEX(样本到样信息汇总统计!H$2:H$500,MATCH(9,样本到样信息汇总统计!$X$2:$X$500,0)),"") | ... W10: =IFERROR(INDEX(样本到样信息汇总统计!W$2:W$500,MATCH(9,样本到样信息汇总统计!$X$2:$X$500,0)),"")
A11: =IFERROR(INDEX(样本到样信息汇总统计!A$2:A$500,MATCH(10,样本到样信息汇总统计!$X$2:$X$500,0)),"") | B11: =IFERROR(INDEX(样本到样信息汇总统计!B$2:B$500,MATCH(10,样本到样信息汇总统计!$X$2:$X$500,0)),"") | C11: =IFERROR(INDEX(样本到样信息汇总统计!C$2:C$500,MATCH(10,样本到样信息汇总统计!$X$2:$X$500,0)),"") | D11: =IFERROR(INDEX(样本到样信息汇总统计!D$2:D$500,MATCH(10,样本到样信息汇总统计!$X$2:$X$500,0)),"") | E11: =IFERROR(INDEX(样本到样信息汇总统计!E$2:E$500,MATCH(10,样本到样信息汇总统计!$X$2:$X$500,0)),"") | F11: =IFERROR(INDEX(样本到样信息汇总统计!F$2:F$500,MATCH(10,样本到样信息汇总统计!$X$2:$X$500,0)),"") | G11: =IFERROR(INDEX(样本到样信息汇总统计!G$2:G$500,MATCH(10,样本到样信息汇总统计!$X$2:$X$500,0)),"") | H11: =IFERROR(INDEX(样本到样信息汇总统计!H$2:H$500,MATCH(10,样本到样信息汇总统计!$X$2:$X$500,0)),"") | ... W11: =IFERROR(INDEX(样本到样信息汇总统计!W$2:W$500,MATCH(10,样本到样信息汇总统计!$X$2:$X$500,0)),"")
A12: =IFERROR(INDEX(样本到样信息汇总统计!A$2:A$500,MATCH(11,样本到样信息汇总统计!$X$2:$X$500,0)),"") | B12: =IFERROR(INDEX(样本到样信息汇总统计!B$2:B$500,MATCH(11,样本到样信息汇总统计!$X$2:$X$500,0)),"") | C12: =IFERROR(INDEX(样本到样信息汇总统计!C$2:C$500,MATCH(11,样本到样信息汇总统计!$X$2:$X$500,0)),"") | D12: =IFERROR(INDEX(样本到样信息汇总统计!D$2:D$500,MATCH(11,样本到样信息汇总统计!$X$2:$X$500,0)),"") | E12: =IFERROR(INDEX(样本到样信息汇总统计!E$2:E$500,MATCH(11,样本到样信息汇总统计!$X$2:$X$500,0)),"") | F12: =IFERROR(INDEX(样本到样信息汇总统计!F$2:F$500,MATCH(11,样本到样信息汇总统计!$X$2:$X$500,0)),"") | G12: =IFERROR(INDEX(样本到样信息汇总统计!G$2:G$500,MATCH(11,样本到样信息汇总统计!$X$2:$X$500,0)),"") | H12: =IFERROR(INDEX(样本到样信息汇总统计!H$2:H$500,MATCH(11,样本到样信息汇总统计!$X$2:$X$500,0)),"") | ... W12: =IFERROR(INDEX(样本到样信息汇总统计!W$2:W$500,MATCH(11,样本到样信息汇总统计!$X$2:$X$500,0)),"")
A13: =IFERROR(INDEX(样本到样信息汇总统计!A$2:A$500,MATCH(12,样本到样信息汇总统计!$X$2:$X$500,0)),"") | B13: =IFERROR(INDEX(样本到样信息汇总统计!B$2:B$500,MATCH(12,样本到样信息汇总统计!$X$2:$X$500,0)),"") | C13: =IFERROR(INDEX(样本到样信息汇总统计!C$2:C$500,MATCH(12,样本到样信息汇总统计!$X$2:$X$500,0)),"") | D13: =IFERROR(INDEX(样本到样信息汇总统计!D$2:D$500,MATCH(12,样本到样信息汇总统计!$X$2:$X$500,0)),"") | E13: =IFERROR(INDEX(样本到样信息汇总统计!E$2:E$500,MATCH(12,样本到样信息汇总统计!$X$2:$X$500,0)),"") | F13: =IFERROR(INDEX(样本到样信息汇总统计!F$2:F$500,MATCH(12,样本到样信息汇总统计!$X$2:$X$500,0)),"") | G13: =IFERROR(INDEX(样本到样信息汇总统计!G$2:G$500,MATCH(12,样本到样信息汇总统计!$X$2:$X$500,0)),"") | H13: =IFERROR(INDEX(样本到样信息汇总统计!H$2:H$500,MATCH(12,样本到样信息汇总统计!$X$2:$X$500,0)),"") | ... W13: =IFERROR(INDEX(样本到样信息汇总统计!W$2:W$500,MATCH(12,样本到样信息汇总统计!$X$2:$X$500,0)),"")
A14: =IFERROR(INDEX(样本到样信息汇总统计!A$2:A$500,MATCH(13,样本到样信息汇总统计!$X$2:$X$500,0)),"") | B14: =IFERROR(INDEX(样本到样信息汇总统计!B$2:B$500,MATCH(13,样本到样信息汇总统计!$X$2:$X$500,0)),"") | C14: =IFERROR(INDEX(样本到样信息汇总统计!C$2:C$500,MATCH(13,样本到样信息汇总统计!$X$2:$X$500,0)),"") | D14: =IFERROR(INDEX(样本到样信息汇总统计!D$2:D$500,MATCH(13,样本到样信息汇总统计!$X$2:$X$500,0)),"") | E14: =IFERROR(INDEX(样本到样信息汇总统计!E$2:E$500,MATCH(13,样本到样信息汇总统计!$X$2:$X$500,0)),"") | F14: =IFERROR(INDEX(样本到样信息汇总统计!F$2:F$500,MATCH(13,样本到样信息汇总统计!$X$2:$X$500,0)),"") | G14: =IFERROR(INDEX(样本到样信息汇总统计!G$2:G$500,MATCH(13,样本到样信息汇总统计!$X$2:$X$500,0)),"") | H14: =IFERROR(INDEX(样本到样信息汇总统计!H$2:H$500,MATCH(13,样本到样信息汇总统计!$X$2:$X$500,0)),"") | ... W14: =IFERROR(INDEX(样本到样信息汇总统计!W$2:W$500,MATCH(13,样本到样信息汇总统计!$X$2:$X$500,0)),"")
A15: =IFERROR(INDEX(样本到样信息汇总统计!A$2:A$500,MATCH(14,样本到样信息汇总统计!$X$2:$X$500,0)),"") | B15: =IFERROR(INDEX(样本到样信息汇总统计!B$2:B$500,MATCH(14,样本到样信息汇总统计!$X$2:$X$500,0)),"") | C15: =IFERROR(INDEX(样本到样信息汇总统计!C$2:C$500,MATCH(14,样本到样信息汇总统计!$X$2:$X$500,0)),"") | D15: =IFERROR(INDEX(样本到样信息汇总统计!D$2:D$500,MATCH(14,样本到样信息汇总统计!$X$2:$X$500,0)),"") | E15: =IFERROR(INDEX(样本到样信息汇总统计!E$2:E$500,MATCH(14,样本到样信息汇总统计!$X$2:$X$500,0)),"") | F15: =IFERROR(INDEX(样本到样信息汇总统计!F$2:F$500,MATCH(14,样本到样信息汇总统计!$X$2:$X$500,0)),"") | G15: =IFERROR(INDEX(样本到样信息汇总统计!G$2:G$500,MATCH(14,样本到样信息汇总统计!$X$2:$X$500,0)),"") | H15: =IFERROR(INDEX(样本到样信息汇总统计!H$2:H$500,MATCH(14,样本到样信息汇总统计!$X$2:$X$500,0)),"") | ... W15: =IFERROR(INDEX(样本到样信息汇总统计!W$2:W$500,MATCH(14,样本到样信息汇总统计!$X$2:$X$500,0)),"")
A16: =IFERROR(INDEX(样本到样信息汇总统计!A$2:A$500,MATCH(15,样本到样信息汇总统计!$X$2:$X$500,0)),"") | B16: =IFERROR(INDEX(样本到样信息汇总统计!B$2:B$500,MATCH(15,样本到样信息汇总统计!$X$2:$X$500,0)),"") | C16: =IFERROR(INDEX(样本到样信息汇总统计!C$2:C$500,MATCH(15,样本到样信息汇总统计!$X$2:$X$500,0)),"") | D16: =IFERROR(INDEX(样本到样信息汇总统计!D$2:D$500,MATCH(15,样本到样信息汇总统计!$X$2:$X$500,0)),"") | E16: =IFERROR(INDEX(样本到样信息汇总统计!E$2:E$500,MATCH(15,样本到样信息汇总统计!$X$2:$X$500,0)),"") | F16: =IFERROR(INDEX(样本到样信息汇总统计!F$2:F$500,MATCH(15,样本到样信息汇总统计!$X$2:$X$500,0)),"") | G16: =IFERROR(INDEX(样本到样信息汇总统计!G$2:G$500,MATCH(15,样本到样信息汇总统计!$X$2:$X$500,0)),"") | H16: =IFERROR(INDEX(样本到样信息汇总统计!H$2:H$500,MATCH(15,样本到样信息汇总统计!$X$2:$X$500,0)),"") | ... W16: =IFERROR(INDEX(样本到样信息汇总统计!W$2:W$500,MATCH(15,样本到样信息汇总统计!$X$2:$X$500,0)),"")
A17: =IFERROR(INDEX(样本到样信息汇总统计!A$2:A$500,MATCH(16,样本到样信息汇总统计!$X$2:$X$500,0)),"") | B17: =IFERROR(INDEX(样本到样信息汇总统计!B$2:B$500,MATCH(16,样本到样信息汇总统计!$X$2:$X$500,0)),"") | C17: =IFERROR(INDEX(样本到样信息汇总统计!C$2:C$500,MATCH(16,样本到样信息汇总统计!$X$2:$X$500,0)),"") | D17: =IFERROR(INDEX(样本到样信息汇总统计!D$2:D$500,MATCH(16,样本到样信息汇总统计!$X$2:$X$500,0)),"") | E17: =IFERROR(INDEX(样本到样信息汇总统计!E$2:E$500,MATCH(16,样本到样信息汇总统计!$X$2:$X$500,0)),"") | F17: =IFERROR(INDEX(样本到样信息汇总统计!F$2:F$500,MATCH(16,样本到样信息汇总统计!$X$2:$X$500,0)),"") | G17: =IFERROR(INDEX(样本到样信息汇总统计!G$2:G$500,MATCH(16,样本到样信息汇总统计!$X$2:$X$500,0)),"") | H17: =IFERROR(INDEX(样本到样信息汇总统计!H$2:H$500,MATCH(16,样本到样信息汇总统计!$X$2:$X$500,0)),"") | ... W17: =IFERROR(INDEX(样本到样信息汇总统计!W$2:W$500,MATCH(16,样本到样信息汇总统计!$X$2:$X$500,0)),"")
A18: =IFERROR(INDEX(样本到样信息汇总统计!A$2:A$500,MATCH(17,样本到样信息汇总统计!$X$2:$X$500,0)),"") | B18: =IFERROR(INDEX(样本到样信息汇总统计!B$2:B$500,MATCH(17,样本到样信息汇总统计!$X$2:$X$500,0)),"") | C18: =IFERROR(INDEX(样本到样信息汇总统计!C$2:C$500,MATCH(17,样本到样信息汇总统计!$X$2:$X$500,0)),"") | D18: =IFERROR(INDEX(样本到样信息汇总统计!D$2:D$500,MATCH(17,样本到样信息汇总统计!$X$2:$X$500,0)),"") | E18: =IFERROR(INDEX(样本到样信息汇总统计!E$2:E$500,MATCH(17,样本到样信息汇总统计!$X$2:$X$500,0)),"") | F18: =IFERROR(INDEX(样本到样信息汇总统计!F$2:F$500,MATCH(17,样本到样信息汇总统计!$X$2:$X$500,0)),"") | G18: =IFERROR(INDEX(样本到样信息汇总统计!G$2:G$500,MATCH(17,样本到样信息汇总统计!$X$2:$X$500,0)),"") | H18: =IFERROR(INDEX(样本到样信息汇总统计!H$2:H$500,MATCH(17,样本到样信息汇总统计!$X$2:$X$500,0)),"") | ... W18: =IFERROR(INDEX(样本到样信息汇总统计!W$2:W$500,MATCH(17,样本到样信息汇总统计!$X$2:$X$500,0)),"")
A19: =IFERROR(INDEX(样本到样信息汇总统计!A$2:A$500,MATCH(18,样本到样信息汇总统计!$X$2:$X$500,0)),"") | B19: =IFERROR(INDEX(样本到样信息汇总统计!B$2:B$500,MATCH(18,样本到样信息汇总统计!$X$2:$X$500,0)),"") | C19: =IFERROR(INDEX(样本到样信息汇总统计!C$2:C$500,MATCH(18,样本到样信息汇总统计!$X$2:$X$500,0)),"") | D19: =IFERROR(INDEX(样本到样信息汇总统计!D$2:D$500,MATCH(18,样本到样信息汇总统计!$X$2:$X$500,0)),"") | E19: =IFERROR(INDEX(样本到样信息汇总统计!E$2:E$500,MATCH(18,样本到样信息汇总统计!$X$2:$X$500,0)),"") | F19: =IFERROR(INDEX(样本到样信息汇总统计!F$2:F$500,MATCH(18,样本到样信息汇总统计!$X$2:$X$500,0)),"") | G19: =IFERROR(INDEX(样本到样信息汇总统计!G$2:G$500,MATCH(18,样本到样信息汇总统计!$X$2:$X$500,0)),"") | H19: =IFERROR(INDEX(样本到样信息汇总统计!H$2:H$500,MATCH(18,样本到样信息汇总统计!$X$2:$X$500,0)),"") | ... W19: =IFERROR(INDEX(样本到样信息汇总统计!W$2:W$500,MATCH(18,样本到样信息汇总统计!$X$2:$X$500,0)),"")
A20: =IFERROR(INDEX(样本到样信息汇总统计!A$2:A$500,MATCH(19,样本到样信息汇总统计!$X$2:$X$500,0)),"") | B20: =IFERROR(INDEX(样本到样信息汇总统计!B$2:B$500,MATCH(19,样本到样信息汇总统计!$X$2:$X$500,0)),"") | C20: =IFERROR(INDEX(样本到样信息汇总统计!C$2:C$500,MATCH(19,样本到样信息汇总统计!$X$2:$X$500,0)),"") | D20: =IFERROR(INDEX(样本到样信息汇总统计!D$2:D$500,MATCH(19,样本到样信息汇总统计!$X$2:$X$500,0)),"") | E20: =IFERROR(INDEX(样本到样信息汇总统计!E$2:E$500,MATCH(19,样本到样信息汇总统计!$X$2:$X$500,0)),"") | F20: =IFERROR(INDEX(样本到样信息汇总统计!F$2:F$500,MATCH(19,样本到样信息汇总统计!$X$2:$X$500,0)),"") | G20: =IFERROR(INDEX(样本到样信息汇总统计!G$2:G$500,MATCH(19,样本到样信息汇总统计!$X$2:$X$500,0)),"") | H20: =IFERROR(INDEX(样本到样信息汇总统计!H$2:H$500,MATCH(19,样本到样信息汇总统计!$X$2:$X$500,0)),"") | ... W20: =IFERROR(INDEX(样本到样信息汇总统计!W$2:W$500,MATCH(19,样本到样信息汇总统计!$X$2:$X$500,0)),"")
A21: =IFERROR(INDEX(样本到样信息汇总统计!A$2:A$500,MATCH(20,样本到样信息汇总统计!$X$2:$X$500,0)),"") | B21: =IFERROR(INDEX(样本到样信息汇总统计!B$2:B$500,MATCH(20,样本到样信息汇总统计!$X$2:$X$500,0)),"") | C21: =IFERROR(INDEX(样本到样信息汇总统计!C$2:C$500,MATCH(20,样本到样信息汇总统计!$X$2:$X$500,0)),"") | D21: =IFERROR(INDEX(样本到样信息汇总统计!D$2:D$500,MATCH(20,样本到样信息汇总统计!$X$2:$X$500,0)),"") | E21: =IFERROR(INDEX(样本到样信息汇总统计!E$2:E$500,MATCH(20,样本到样信息汇总统计!$X$2:$X$500,0)),"") | F21: =IFERROR(INDEX(样本到样信息汇总统计!F$2:F$500,MATCH(20,样本到样信息汇总统计!$X$2:$X$500,0)),"") | G21: =IFERROR(INDEX(样本到样信息汇总统计!G$2:G$500,MATCH(20,样本到样信息汇总统计!$X$2:$X$500,0)),"") | H21: =IFERROR(INDEX(样本到样信息汇总统计!H$2:H$500,MATCH(20,样本到样信息汇总统计!$X$2:$X$500,0)),"") | ... W21: =IFERROR(INDEX(样本到样信息汇总统计!W$2:W$500,MATCH(20,样本到样信息汇总统计!$X$2:$X$500,0)),"")
A22: =IFERROR(INDEX(样本到样信息汇总统计!A$2:A$500,MATCH(21,样本到样信息汇总统计!$X$2:$X$500,0)),"") | B22: =IFERROR(INDEX(样本到样信息汇总统计!B$2:B$500,MATCH(21,样本到样信息汇总统计!$X$2:$X$500,0)),"") | C22: =IFERROR(INDEX(样本到样信息汇总统计!C$2:C$500,MATCH(21,样本到样信息汇总统计!$X$2:$X$500,0)),"") | D22: =IFERROR(INDEX(样本到样信息汇总统计!D$2:D$500,MATCH(21,样本到样信息汇总统计!$X$2:$X$500,0)),"") | E22: =IFERROR(INDEX(样本到样信息汇总统计!E$2:E$500,MATCH(21,样本到样信息汇总统计!$X$2:$X$500,0)),"") | F22: =IFERROR(INDEX(样本到样信息汇总统计!F$2:F$500,MATCH(21,样本到样信息汇总统计!$X$2:$X$500,0)),"") | G22: =IFERROR(INDEX(样本到样信息汇总统计!G$2:G$500,MATCH(21,样本到样信息汇总统计!$X$2:$X$500,0)),"") | H22: =IFERROR(INDEX(样本到样信息汇总统计!H$2:H$500,MATCH(21,样本到样信息汇总统计!$X$2:$X$500,0)),"") | ... W22: =IFERROR(INDEX(样本到样信息汇总统计!W$2:W$500,MATCH(21,样本到样信息汇总统计!$X$2:$X$500,0)),"")
A23: =IFERROR(INDEX(样本到样信息汇总统计!A$2:A$500,MATCH(22,样本到样信息汇总统计!$X$2:$X$500,0)),"") | B23: =IFERROR(INDEX(样本到样信息汇总统计!B$2:B$500,MATCH(22,样本到样信息汇总统计!$X$2:$X$500,0)),"") | C23: =IFERROR(INDEX(样本到样信息汇总统计!C$2:C$500,MATCH(22,样本到样信息汇总统计!$X$2:$X$500,0)),"") | D23: =IFERROR(INDEX(样本到样信息汇总统计!D$2:D$500,MATCH(22,样本到样信息汇总统计!$X$2:$X$500,0)),"") | E23: =IFERROR(INDEX(样本到样信息汇总统计!E$2:E$500,MATCH(22,样本到样信息汇总统计!$X$2:$X$500,0)),"") | F23: =IFERROR(INDEX(样本到样信息汇总统计!F$2:F$500,MATCH(22,样本到样信息汇总统计!$X$2:$X$500,0)),"") | G23: =IFERROR(INDEX(样本到样信息汇总统计!G$2:G$500,MATCH(22,样本到样信息汇总统计!$X$2:$X$500,0)),"") | H23: =IFERROR(INDEX(样本到样信息汇总统计!H$2:H$500,MATCH(22,样本到样信息汇总统计!$X$2:$X$500,0)),"") | ... W23: =IFERROR(INDEX(样本到样信息汇总统计!W$2:W$500,MATCH(22,样本到样信息汇总统计!$X$2:$X$500,0)),"")
A24: =IFERROR(INDEX(样本到样信息汇总统计!A$2:A$500,MATCH(23,样本到样信息汇总统计!$X$2:$X$500,0)),"") | B24: =IFERROR(INDEX(样本到样信息汇总统计!B$2:B$500,MATCH(23,样本到样信息汇总统计!$X$2:$X$500,0)),"") | C24: =IFERROR(INDEX(样本到样信息汇总统计!C$2:C$500,MATCH(23,样本到样信息汇总统计!$X$2:$X$500,0)),"") | D24: =IFERROR(INDEX(样本到样信息汇总统计!D$2:D$500,MATCH(23,样本到样信息汇总统计!$X$2:$X$500,0)),"") | E24: =IFERROR(INDEX(样本到样信息汇总统计!E$2:E$500,MATCH(23,样本到样信息汇总统计!$X$2:$X$500,0)),"") | F24: =IFERROR(INDEX(样本到样信息汇总统计!F$2:F$500,MATCH(23,样本到样信息汇总统计!$X$2:$X$500,0)),"") | G24: =IFERROR(INDEX(样本到样信息汇总统计!G$2:G$500,MATCH(23,样本到样信息汇总统计!$X$2:$X$500,0)),"") | H24: =IFERROR(INDEX(样本到样信息汇总统计!H$2:H$500,MATCH(23,样本到样信息汇总统计!$X$2:$X$500,0)),"") | ... W24: =IFERROR(INDEX(样本到样信息汇总统计!W$2:W$500,MATCH(23,样本到样信息汇总统计!$X$2:$X$500,0)),"")
A25: =IFERROR(INDEX(样本到样信息汇总统计!A$2:A$500,MATCH(24,样本到样信息汇总统计!$X$2:$X$500,0)),"") | B25: =IFERROR(INDEX(样本到样信息汇总统计!B$2:B$500,MATCH(24,样本到样信息汇总统计!$X$2:$X$500,0)),"") | C25: =IFERROR(INDEX(样本到样信息汇总统计!C$2:C$500,MATCH(24,样本到样信息汇总统计!$X$2:$X$500,0)),"") | D25: =IFERROR(INDEX(样本到样信息汇总统计!D$2:D$500,MATCH(24,样本到样信息汇总统计!$X$2:$X$500,0)),"") | E25: =IFERROR(INDEX(样本到样信息汇总统计!E$2:E$500,MATCH(24,样本到样信息汇总统计!$X$2:$X$500,0)),"") | F25: =IFERROR(INDEX(样本到样信息汇总统计!F$2:F$500,MATCH(24,样本到样信息汇总统计!$X$2:$X$500,0)),"") | G25: =IFERROR(INDEX(样本到样信息汇总统计!G$2:G$500,MATCH(24,样本到样信息汇总统计!$X$2:$X$500,0)),"") | H25: =IFERROR(INDEX(样本到样信息汇总统计!H$2:H$500,MATCH(24,样本到样信息汇总统计!$X$2:$X$500,0)),"") | ... W25: =IFERROR(INDEX(样本到样信息汇总统计!W$2:W$500,MATCH(24,样本到样信息汇总统计!$X$2:$X$500,0)),"")
A26: =IFERROR(INDEX(样本到样信息汇总统计!A$2:A$500,MATCH(25,样本到样信息汇总统计!$X$2:$X$500,0)),"") | B26: =IFERROR(INDEX(样本到样信息汇总统计!B$2:B$500,MATCH(25,样本到样信息汇总统计!$X$2:$X$500,0)),"") | C26: =IFERROR(INDEX(样本到样信息汇总统计!C$2:C$500,MATCH(25,样本到样信息汇总统计!$X$2:$X$500,0)),"") | D26: =IFERROR(INDEX(样本到样信息汇总统计!D$2:D$500,MATCH(25,样本到样信息汇总统计!$X$2:$X$500,0)),"") | E26: =IFERROR(INDEX(样本到样信息汇总统计!E$2:E$500,MATCH(25,样本到样信息汇总统计!$X$2:$X$500,0)),"") | F26: =IFERROR(INDEX(样本到样信息汇总统计!F$2:F$500,MATCH(25,样本到样信息汇总统计!$X$2:$X$500,0)),"") | G26: =IFERROR(INDEX(样本到样信息汇总统计!G$2:G$500,MATCH(25,样本到样信息汇总统计!$X$2:$X$500,0)),"") | H26: =IFERROR(INDEX(样本到样信息汇总统计!H$2:H$500,MATCH(25,样本到样信息汇总统计!$X$2:$X$500,0)),"") | ... W26: =IFERROR(INDEX(样本到样信息汇总统计!W$2:W$500,MATCH(25,样本到样信息汇总统计!$X$2:$X$500,0)),"")
A27: =IFERROR(INDEX(样本到样信息汇总统计!A$2:A$500,MATCH(26,样本到样信息汇总统计!$X$2:$X$500,0)),"") | B27: =IFERROR(INDEX(样本到样信息汇总统计!B$2:B$500,MATCH(26,样本到样信息汇总统计!$X$2:$X$500,0)),"") | C27: =IFERROR(INDEX(样本到样信息汇总统计!C$2:C$500,MATCH(26,样本到样信息汇总统计!$X$2:$X$500,0)),"") | D27: =IFERROR(INDEX(样本到样信息汇总统计!D$2:D$500,MATCH(26,样本到样信息汇总统计!$X$2:$X$500,0)),"") | E27: =IFERROR(INDEX(样本到样信息汇总统计!E$2:E$500,MATCH(26,样本到样信息汇总统计!$X$2:$X$500,0)),"") | F27: =IFERROR(INDEX(样本到样信息汇总统计!F$2:F$500,MATCH(26,样本到样信息汇总统计!$X$2:$X$500,0)),"") | G27: =IFERROR(INDEX(样本到样信息汇总统计!G$2:G$500,MATCH(26,样本到样信息汇总统计!$X$2:$X$500,0)),"") | H27: =IFERROR(INDEX(样本到样信息汇总统计!H$2:H$500,MATCH(26,样本到样信息汇总统计!$X$2:$X$500,0)),"") | ... W27: =IFERROR(INDEX(样本到样信息汇总统计!W$2:W$500,MATCH(26,样本到样信息汇总统计!$X$2:$X$500,0)),"")
A28: =IFERROR(INDEX(样本到样信息汇总统计!A$2:A$500,MATCH(27,样本到样信息汇总统计!$X$2:$X$500,0)),"") | B28: =IFERROR(INDEX(样本到样信息汇总统计!B$2:B$500,MATCH(27,样本到样信息汇总统计!$X$2:$X$500,0)),"") | C28: =IFERROR(INDEX(样本到样信息汇总统计!C$2:C$500,MATCH(27,样本到样信息汇总统计!$X$2:$X$500,0)),"") | D28: =IFERROR(INDEX(样本到样信息汇总统计!D$2:D$500,MATCH(27,样本到样信息汇总统计!$X$2:$X$500,0)),"") | E28: =IFERROR(INDEX(样本到样信息汇总统计!E$2:E$500,MATCH(27,样本到样信息汇总统计!$X$2:$X$500,0)),"") | F28: =IFERROR(INDEX(样本到样信息汇总统计!F$2:F$500,MATCH(27,样本到样信息汇总统计!$X$2:$X$500,0)),"") | G28: =IFERROR(INDEX(样本到样信息汇总统计!G$2:G$500,MATCH(27,样本到样信息汇总统计!$X$2:$X$500,0)),"") | H28: =IFERROR(INDEX(样本到样信息汇总统计!H$2:H$500,MATCH(27,样本到样信息汇总统计!$X$2:$X$500,0)),"") | ... W28: =IFERROR(INDEX(样本到样信息汇总统计!W$2:W$500,MATCH(27,样本到样信息汇总统计!$X$2:$X$500,0)),"")
A29: =IFERROR(INDEX(样本到样信息汇总统计!A$2:A$500,MATCH(28,样本到样信息汇总统计!$X$2:$X$500,0)),"") | B29: =IFERROR(INDEX(样本到样信息汇总统计!B$2:B$500,MATCH(28,样本到样信息汇总统计!$X$2:$X$500,0)),"") | C29: =IFERROR(INDEX(样本到样信息汇总统计!C$2:C$500,MATCH(28,样本到样信息汇总统计!$X$2:$X$500,0)),"") | D29: =IFERROR(INDEX(样本到样信息汇总统计!D$2:D$500,MATCH(28,样本到样信息汇总统计!$X$2:$X$500,0)),"") | E29: =IFERROR(INDEX(样本到样信息汇总统计!E$2:E$500,MATCH(28,样本到样信息汇总统计!$X$2:$X$500,0)),"") | F29: =IFERROR(INDEX(样本到样信息汇总统计!F$2:F$500,MATCH(28,样本到样信息汇总统计!$X$2:$X$500,0)),"") | G29: =IFERROR(INDEX(样本到样信息汇总统计!G$2:G$500,MATCH(28,样本到样信息汇总统计!$X$2:$X$500,0)),"") | H29: =IFERROR(INDEX(样本到样信息汇总统计!H$2:H$500,MATCH(28,样本到样信息汇总统计!$X$2:$X$500,0)),"") | ... W29: =IFERROR(INDEX(样本到样信息汇总统计!W$2:W$500,MATCH(28,样本到样信息汇总统计!$X$2:$X$500,0)),"")
A30: =IFERROR(INDEX(样本到样信息汇总统计!A$2:A$500,MATCH(29,样本到样信息汇总统计!$X$2:$X$500,0)),"") | B30: =IFERROR(INDEX(样本到样信息汇总统计!B$2:B$500,MATCH(29,样本到样信息汇总统计!$X$2:$X$500,0)),"") | C30: =IFERROR(INDEX(样本到样信息汇总统计!C$2:C$500,MATCH(29,样本到样信息汇总统计!$X$2:$X$500,0)),"") | D30: =IFERROR(INDEX(样本到样信息汇总统计!D$2:D$500,MATCH(29,样本到样信息汇总统计!$X$2:$X$500,0)),"") | E30: =IFERROR(INDEX(样本到样信息汇总统计!E$2:E$500,MATCH(29,样本到样信息汇总统计!$X$2:$X$500,0)),"") | F30: =IFERROR(INDEX(样本到样信息汇总统计!F$2:F$500,MATCH(29,样本到样信息汇总统计!$X$2:$X$500,0)),"") | G30: =IFERROR(INDEX(样本到样信息汇总统计!G$2:G$500,MATCH(29,样本到样信息汇总统计!$X$2:$X$500,0)),"") | H30: =IFERROR(INDEX(样本到样信息汇总统计!H$2:H$500,MATCH(29,样本到样信息汇总统计!$X$2:$X$500,0)),"") | ... W30: =IFERROR(INDEX(样本到样信息汇总统计!W$2:W$500,MATCH(29,样本到样信息汇总统计!$X$2:$X$500,0)),"")
A31: =IFERROR(INDEX(样本到样信息汇总统计!A$2:A$500,MATCH(30,样本到样信息汇总统计!$X$2:$X$500,0)),"") | B31: =IFERROR(INDEX(样本到样信息汇总统计!B$2:B$500,MATCH(30,样本到样信息汇总统计!$X$2:$X$500,0)),"") | C31: =IFERROR(INDEX(样本到样信息汇总统计!C$2:C$500,MATCH(30,样本到样信息汇总统计!$X$2:$X$500,0)),"") | D31: =IFERROR(INDEX(样本到样信息汇总统计!D$2:D$500,MATCH(30,样本到样信息汇总统计!$X$2:$X$500,0)),"") | E31: =IFERROR(INDEX(样本到样信息汇总统计!E$2:E$500,MATCH(30,样本到样信息汇总统计!$X$2:$X$500,0)),"") | F31: =IFERROR(INDEX(样本到样信息汇总统计!F$2:F$500,MATCH(30,样本到样信息汇总统计!$X$2:$X$500,0)),"") | G31: =IFERROR(INDEX(样本到样信息汇总统计!G$2:G$500,MATCH(30,样本到样信息汇总统计!$X$2:$X$500,0)),"") | H31: =IFERROR(INDEX(样本到样信息汇总统计!H$2:H$500,MATCH(30,样本到样信息汇总统计!$X$2:$X$500,0)),"") | ... W31: =IFERROR(INDEX(样本到样信息汇总统计!W$2:W$500,MATCH(30,样本到样信息汇总统计!$X$2:$X$500,0)),"")
A32: =IFERROR(INDEX(样本到样信息汇总统计!A$2:A$500,MATCH(31,样本到样信息汇总统计!$X$2:$X$500,0)),"") | B32: =IFERROR(INDEX(样本到样信息汇总统计!B$2:B$500,MATCH(31,样本到样信息汇总统计!$X$2:$X$500,0)),"") | C32: =IFERROR(INDEX(样本到样信息汇总统计!C$2:C$500,MATCH(31,样本到样信息汇总统计!$X$2:$X$500,0)),"") | D32: =IFERROR(INDEX(样本到样信息汇总统计!D$2:D$500,MATCH(31,样本到样信息汇总统计!$X$2:$X$500,0)),"") | E32: =IFERROR(INDEX(样本到样信息汇总统计!E$2:E$500,MATCH(31,样本到样信息汇总统计!$X$2:$X$500,0)),"") | F32: =IFERROR(INDEX(样本到样信息汇总统计!F$2:F$500,MATCH(31,样本到样信息汇总统计!$X$2:$X$500,0)),"") | G32: =IFERROR(INDEX(样本到样信息汇总统计!G$2:G$500,MATCH(31,样本到样信息汇总统计!$X$2:$X$500,0)),"") | H32: =IFERROR(INDEX(样本到样信息汇总统计!H$2:H$500,MATCH(31,样本到样信息汇总统计!$X$2:$X$500,0)),"") | ... W32: =IFERROR(INDEX(样本到样信息汇总统计!W$2:W$500,MATCH(31,样本到样信息汇总统计!$X$2:$X$500,0)),"")
A33: =IFERROR(INDEX(样本到样信息汇总统计!A$2:A$500,MATCH(32,样本到样信息汇总统计!$X$2:$X$500,0)),"") | B33: =IFERROR(INDEX(样本到样信息汇总统计!B$2:B$500,MATCH(32,样本到样信息汇总统计!$X$2:$X$500,0)),"") | C33: =IFERROR(INDEX(样本到样信息汇总统计!C$2:C$500,MATCH(32,样本到样信息汇总统计!$X$2:$X$500,0)),"") | D33: =IFERROR(INDEX(样本到样信息汇总统计!D$2:D$500,MATCH(32,样本到样信息汇总统计!$X$2:$X$500,0)),"") | E33: =IFERROR(INDEX(样本到样信息汇总统计!E$2:E$500,MATCH(32,样本到样信息汇总统计!$X$2:$X$500,0)),"") | F33: =IFERROR(INDEX(样本到样信息汇总统计!F$2:F$500,MATCH(32,样本到样信息汇总统计!$X$2:$X$500,0)),"") | G33: =IFERROR(INDEX(样本到样信息汇总统计!G$2:G$500,MATCH(32,样本到样信息汇总统计!$X$2:$X$500,0)),"") | H33: =IFERROR(INDEX(样本到样信息汇总统计!H$2:H$500,MATCH(32,样本到样信息汇总统计!$X$2:$X$500,0)),"") | ... W33: =IFERROR(INDEX(样本到样信息汇总统计!W$2:W$500,MATCH(32,样本到样信息汇总统计!$X$2:$X$500,0)),"")
A34: =IFERROR(INDEX(样本到样信息汇总统计!A$2:A$500,MATCH(33,样本到样信息汇总统计!$X$2:$X$500,0)),"") | B34: =IFERROR(INDEX(样本到样信息汇总统计!B$2:B$500,MATCH(33,样本到样信息汇总统计!$X$2:$X$500,0)),"") | C34: =IFERROR(INDEX(样本到样信息汇总统计!C$2:C$500,MATCH(33,样本到样信息汇总统计!$X$2:$X$500,0)),"") | D34: =IFERROR(INDEX(样本到样信息汇总统计!D$2:D$500,MATCH(33,样本到样信息汇总统计!$X$2:$X$500,0)),"") | E34: =IFERROR(INDEX(样本到样信息汇总统计!E$2:E$500,MATCH(33,样本到样信息汇总统计!$X$2:$X$500,0)),"") | F34: =IFERROR(INDEX(样本到样信息汇总统计!F$2:F$500,MATCH(33,样本到样信息汇总统计!$X$2:$X$500,0)),"") | G34: =IFERROR(INDEX(样本到样信息汇总统计!G$2:G$500,MATCH(33,样本到样信息汇总统计!$X$2:$X$500,0)),"") | H34: =IFERROR(INDEX(样本到样信息汇总统计!H$2:H$500,MATCH(33,样本到样信息汇总统计!$X$2:$X$500,0)),"") | ... W34: =IFERROR(INDEX(样本到样信息汇总统计!W$2:W$500,MATCH(33,样本到样信息汇总统计!$X$2:$X$500,0)),"")
A35: =IFERROR(INDEX(样本到样信息汇总统计!A$2:A$500,MATCH(34,样本到样信息汇总统计!$X$2:$X$500,0)),"") | B35: =IFERROR(INDEX(样本到样信息汇总统计!B$2:B$500,MATCH(34,样本到样信息汇总统计!$X$2:$X$500,0)),"") | C35: =IFERROR(INDEX(样本到样信息汇总统计!C$2:C$500,MATCH(34,样本到样信息汇总统计!$X$2:$X$500,0)),"") | D35: =IFERROR(INDEX(样本到样信息汇总统计!D$2:D$500,MATCH(34,样本到样信息汇总统计!$X$2:$X$500,0)),"") | E35: =IFERROR(INDEX(样本到样信息汇总统计!E$2:E$500,MATCH(34,样本到样信息汇总统计!$X$2:$X$500,0)),"") | F35: =IFERROR(INDEX(样本到样信息汇总统计!F$2:F$500,MATCH(34,样本到样信息汇总统计!$X$2:$X$500,0)),"") | G35: =IFERROR(INDEX(样本到样信息汇总统计!G$2:G$500,MATCH(34,样本到样信息汇总统计!$X$2:$X$500,0)),"") | H35: =IFERROR(INDEX(样本到样信息汇总统计!H$2:H$500,MATCH(34,样本到样信息汇总统计!$X$2:$X$500,0)),"") | ... W35: =IFERROR(INDEX(样本到样信息汇总统计!W$2:W$500,MATCH(34,样本到样信息汇总统计!$X$2:$X$500,0)),"")
A36: =IFERROR(INDEX(样本到样信息汇总统计!A$2:A$500,MATCH(35,样本到样信息汇总统计!$X$2:$X$500,0)),"") | B36: =IFERROR(INDEX(样本到样信息汇总统计!B$2:B$500,MATCH(35,样本到样信息汇总统计!$X$2:$X$500,0)),"") | C36: =IFERROR(INDEX(样本到样信息汇总统计!C$2:C$500,MATCH(35,样本到样信息汇总统计!$X$2:$X$500,0)),"") | D36: =IFERROR(INDEX(样本到样信息汇总统计!D$2:D$500,MATCH(35,样本到样信息汇总统计!$X$2:$X$500,0)),"") | E36: =IFERROR(INDEX(样本到样信息汇总统计!E$2:E$500,MATCH(35,样本到样信息汇总统计!$X$2:$X$500,0)),"") | F36: =IFERROR(INDEX(样本到样信息汇总统计!F$2:F$500,MATCH(35,样本到样信息汇总统计!$X$2:$X$500,0)),"") | G36: =IFERROR(INDEX(样本到样信息汇总统计!G$2:G$500,MATCH(35,样本到样信息汇总统计!$X$2:$X$500,0)),"") | H36: =IFERROR(INDEX(样本到样信息汇总统计!H$2:H$500,MATCH(35,样本到样信息汇总统计!$X$2:$X$500,0)),"") | ... W36: =IFERROR(INDEX(样本到样信息汇总统计!W$2:W$500,MATCH(35,样本到样信息汇总统计!$X$2:$X$500,0)),"")
A37: =IFERROR(INDEX(样本到样信息汇总统计!A$2:A$500,MATCH(36,样本到样信息汇总统计!$X$2:$X$500,0)),"") | B37: =IFERROR(INDEX(样本到样信息汇总统计!B$2:B$500,MATCH(36,样本到样信息汇总统计!$X$2:$X$500,0)),"") | C37: =IFERROR(INDEX(样本到样信息汇总统计!C$2:C$500,MATCH(36,样本到样信息汇总统计!$X$2:$X$500,0)),"") | D37: =IFERROR(INDEX(样本到样信息汇总统计!D$2:D$500,MATCH(36,样本到样信息汇总统计!$X$2:$X$500,0)),"") | E37: =IFERROR(INDEX(样本到样信息汇总统计!E$2:E$500,MATCH(36,样本到样信息汇总统计!$X$2:$X$500,0)),"") | F37: =IFERROR(INDEX(样本到样信息汇总统计!F$2:F$500,MATCH(36,样本到样信息汇总统计!$X$2:$X$500,0)),"") | G37: =IFERROR(INDEX(样本到样信息汇总统计!G$2:G$500,MATCH(36,样本到样信息汇总统计!$X$2:$X$500,0)),"") | H37: =IFERROR(INDEX(样本到样信息汇总统计!H$2:H$500,MATCH(36,样本到样信息汇总统计!$X$2:$X$500,0)),"") | ... W37: =IFERROR(INDEX(样本到样信息汇总统计!W$2:W$500,MATCH(36,样本到样信息汇总统计!$X$2:$X$500,0)),"")
A38: =IFERROR(INDEX(样本到样信息汇总统计!A$2:A$500,MATCH(37,样本到样信息汇总统计!$X$2:$X$500,0)),"") | B38: =IFERROR(INDEX(样本到样信息汇总统计!B$2:B$500,MATCH(37,样本到样信息汇总统计!$X$2:$X$500,0)),"") | C38: =IFERROR(INDEX(样本到样信息汇总统计!C$2:C$500,MATCH(37,样本到样信息汇总统计!$X$2:$X$500,0)),"") | D38: =IFERROR(INDEX(样本到样信息汇总统计!D$2:D$500,MATCH(37,样本到样信息汇总统计!$X$2:$X$500,0)),"") | E38: =IFERROR(INDEX(样本到样信息汇总统计!E$2:E$500,MATCH(37,样本到样信息汇总统计!$X$2:$X$500,0)),"") | F38: =IFERROR(INDEX(样本到样信息汇总统计!F$2:F$500,MATCH(37,样本到样信息汇总统计!$X$2:$X$500,0)),"") | G38: =IFERROR(INDEX(样本到样信息汇总统计!G$2:G$500,MATCH(37,样本到样信息汇总统计!$X$2:$X$500,0)),"") | H38: =IFERROR(INDEX(样本到样信息汇总统计!H$2:H$500,MATCH(37,样本到样信息汇总统计!$X$2:$X$500,0)),"") | ... W38: =IFERROR(INDEX(样本到样信息汇总统计!W$2:W$500,MATCH(37,样本到样信息汇总统计!$X$2:$X$500,0)),"")
A39: =IFERROR(INDEX(样本到样信息汇总统计!A$2:A$500,MATCH(38,样本到样信息汇总统计!$X$2:$X$500,0)),"") | B39: =IFERROR(INDEX(样本到样信息汇总统计!B$2:B$500,MATCH(38,样本到样信息汇总统计!$X$2:$X$500,0)),"") | C39: =IFERROR(INDEX(样本到样信息汇总统计!C$2:C$500,MATCH(38,样本到样信息汇总统计!$X$2:$X$500,0)),"") | D39: =IFERROR(INDEX(样本到样信息汇总统计!D$2:D$500,MATCH(38,样本到样信息汇总统计!$X$2:$X$500,0)),"") | E39: =IFERROR(INDEX(样本到样信息汇总统计!E$2:E$500,MATCH(38,样本到样信息汇总统计!$X$2:$X$500,0)),"") | F39: =IFERROR(INDEX(样本到样信息汇总统计!F$2:F$500,MATCH(38,样本到样信息汇总统计!$X$2:$X$500,0)),"") | G39: =IFERROR(INDEX(样本到样信息汇总统计!G$2:G$500,MATCH(38,样本到样信息汇总统计!$X$2:$X$500,0)),"") | H39: =IFERROR(INDEX(样本到样信息汇总统计!H$2:H$500,MATCH(38,样本到样信息汇总统计!$X$2:$X$500,0)),"") | ... W39: =IFERROR(INDEX(样本到样信息汇总统计!W$2:W$500,MATCH(38,样本到样信息汇总统计!$X$2:$X$500,0)),"")
A40: =IFERROR(INDEX(样本到样信息汇总统计!A$2:A$500,MATCH(39,样本到样信息汇总统计!$X$2:$X$500,0)),"") | B40: =IFERROR(INDEX(样本到样信息汇总统计!B$2:B$500,MATCH(39,样本到样信息汇总统计!$X$2:$X$500,0)),"") | C40: =IFERROR(INDEX(样本到样信息汇总统计!C$2:C$500,MATCH(39,样本到样信息汇总统计!$X$2:$X$500,0)),"") | D40: =IFERROR(INDEX(样本到样信息汇总统计!D$2:D$500,MATCH(39,样本到样信息汇总统计!$X$2:$X$500,0)),"") | E40: =IFERROR(INDEX(样本到样信息汇总统计!E$2:E$500,MATCH(39,样本到样信息汇总统计!$X$2:$X$500,0)),"") | F40: =IFERROR(INDEX(样本到样信息汇总统计!F$2:F$500,MATCH(39,样本到样信息汇总统计!$X$2:$X$500,0)),"") | G40: =IFERROR(INDEX(样本到样信息汇总统计!G$2:G$500,MATCH(39,样本到样信息汇总统计!$X$2:$X$500,0)),"") | H40: =IFERROR(INDEX(样本到样信息汇总统计!H$2:H$500,MATCH(39,样本到样信息汇总统计!$X$2:$X$500,0)),"") | ... W40: =IFERROR(INDEX(样本到样信息汇总统计!W$2:W$500,MATCH(39,样本到样信息汇总统计!$X$2:$X$500,0)),"")
...

Sheet 未进行项目
A1: 医院名称 | B1: 客户名称 | C1: 科研经理 | D1: OA立项编号 | E1: 订单编号 | F1: 样本类型 | G1: 样本性质 | H1: 实收样本量 | I1: 外送测序样本量 | J1: 到样时间 | K1: 优先级 | L1: 具体实验室流程 | M1: 具体操作补充 | N1: 测序安排 | O1: 上机平台 | P1: 上机批次号 | Q1: 外送大pool号 | R1: 外送小pool号 | S1: 测序模式 | T1: 测序数据量/例 | U1: 网盘数据位置编号 | V1: 目前进展 | W1: 当前进展的时间点
A2: =IFERROR(INDEX(样本到样信息汇总统计!A$2:A$500,MATCH(1,样本到样信息汇总统计!$Y$2:$Y$500,0)),"") -> XX省人民医院 | B2: =IFERROR(INDEX(样本到样信息汇总统计!B$2:B$500,MATCH(1,样本到样信息汇总统计!$Y$2:$Y$500,0)),"") -> 张主任课题组 | C2: =IFERROR(INDEX(样本到样信息汇总统计!C$2:C$500,MATCH(1,样本到样信息汇总统计!$Y$2:$Y$500,0)),"") -> 陈经理 | D2: =IFERROR(INDEX(样本到样信息汇总统计!D$2:D$500,MATCH(1,样本到样信息汇总统计!$Y$2:$Y$500,0)),"") -> PJ2026-001 | E2: =IFERROR(INDEX(样本到样信息汇总统计!E$2:E$500,MATCH(1,样本到样信息汇总统计!$Y$2:$Y$500,0)),"") -> ORD-2026-0001 | F2: =IFERROR(INDEX(样本到样信息汇总统计!F$2:F$500,MATCH(1,样本到样信息汇总统计!$Y$2:$Y$500,0)),"") -> 肿瘤组织 | G2: =IFERROR(INDEX(样本到样信息汇总统计!G$2:G$500,MATCH(1,样本到样信息汇总统计!$Y$2:$Y$500,0)),"") -> 核酸 | H2: =IFERROR(INDEX(样本到样信息汇总统计!H$2:H$500,MATCH(1,样本到样信息汇总统计!$Y$2:$Y$500,0)),"") -> 50 | ... W2: =IFERROR(INDEX(样本到样信息汇总统计!W$2:W$500,MATCH(1,样本到样信息汇总统计!$Y$2:$Y$500,0)),"") -> 2026-05-22
A3: =IFERROR(INDEX(样本到样信息汇总统计!A$2:A$500,MATCH(2,样本到样信息汇总统计!$Y$2:$Y$500,0)),"") | B3: =IFERROR(INDEX(样本到样信息汇总统计!B$2:B$500,MATCH(2,样本到样信息汇总统计!$Y$2:$Y$500,0)),"") | C3: =IFERROR(INDEX(样本到样信息汇总统计!C$2:C$500,MATCH(2,样本到样信息汇总统计!$Y$2:$Y$500,0)),"") | D3: =IFERROR(INDEX(样本到样信息汇总统计!D$2:D$500,MATCH(2,样本到样信息汇总统计!$Y$2:$Y$500,0)),"") | E3: =IFERROR(INDEX(样本到样信息汇总统计!E$2:E$500,MATCH(2,样本到样信息汇总统计!$Y$2:$Y$500,0)),"") | F3: =IFERROR(INDEX(样本到样信息汇总统计!F$2:F$500,MATCH(2,样本到样信息汇总统计!$Y$2:$Y$500,0)),"") | G3: =IFERROR(INDEX(样本到样信息汇总统计!G$2:G$500,MATCH(2,样本到样信息汇总统计!$Y$2:$Y$500,0)),"") | H3: =IFERROR(INDEX(样本到样信息汇总统计!H$2:H$500,MATCH(2,样本到样信息汇总统计!$Y$2:$Y$500,0)),"") | ... W3: =IFERROR(INDEX(样本到样信息汇总统计!W$2:W$500,MATCH(2,样本到样信息汇总统计!$Y$2:$Y$500,0)),"")
A4: =IFERROR(INDEX(样本到样信息汇总统计!A$2:A$500,MATCH(3,样本到样信息汇总统计!$Y$2:$Y$500,0)),"") | B4: =IFERROR(INDEX(样本到样信息汇总统计!B$2:B$500,MATCH(3,样本到样信息汇总统计!$Y$2:$Y$500,0)),"") | C4: =IFERROR(INDEX(样本到样信息汇总统计!C$2:C$500,MATCH(3,样本到样信息汇总统计!$Y$2:$Y$500,0)),"") | D4: =IFERROR(INDEX(样本到样信息汇总统计!D$2:D$500,MATCH(3,样本到样信息汇总统计!$Y$2:$Y$500,0)),"") | E4: =IFERROR(INDEX(样本到样信息汇总统计!E$2:E$500,MATCH(3,样本到样信息汇总统计!$Y$2:$Y$500,0)),"") | F4: =IFERROR(INDEX(样本到样信息汇总统计!F$2:F$500,MATCH(3,样本到样信息汇总统计!$Y$2:$Y$500,0)),"") | G4: =IFERROR(INDEX(样本到样信息汇总统计!G$2:G$500,MATCH(3,样本到样信息汇总统计!$Y$2:$Y$500,0)),"") | H4: =IFERROR(INDEX(样本到样信息汇总统计!H$2:H$500,MATCH(3,样本到样信息汇总统计!$Y$2:$Y$500,0)),"") | ... W4: =IFERROR(INDEX(样本到样信息汇总统计!W$2:W$500,MATCH(3,样本到样信息汇总统计!$Y$2:$Y$500,0)),"")
A5: =IFERROR(INDEX(样本到样信息汇总统计!A$2:A$500,MATCH(4,样本到样信息汇总统计!$Y$2:$Y$500,0)),"") | B5: =IFERROR(INDEX(样本到样信息汇总统计!B$2:B$500,MATCH(4,样本到样信息汇总统计!$Y$2:$Y$500,0)),"") | C5: =IFERROR(INDEX(样本到样信息汇总统计!C$2:C$500,MATCH(4,样本到样信息汇总统计!$Y$2:$Y$500,0)),"") | D5: =IFERROR(INDEX(样本到样信息汇总统计!D$2:D$500,MATCH(4,样本到样信息汇总统计!$Y$2:$Y$500,0)),"") | E5: =IFERROR(INDEX(样本到样信息汇总统计!E$2:E$500,MATCH(4,样本到样信息汇总统计!$Y$2:$Y$500,0)),"") | F5: =IFERROR(INDEX(样本到样信息汇总统计!F$2:F$500,MATCH(4,样本到样信息汇总统计!$Y$2:$Y$500,0)),"") | G5: =IFERROR(INDEX(样本到样信息汇总统计!G$2:G$500,MATCH(4,样本到样信息汇总统计!$Y$2:$Y$500,0)),"") | H5: =IFERROR(INDEX(样本到样信息汇总统计!H$2:H$500,MATCH(4,样本到样信息汇总统计!$Y$2:$Y$500,0)),"") | ... W5: =IFERROR(INDEX(样本到样信息汇总统计!W$2:W$500,MATCH(4,样本到样信息汇总统计!$Y$2:$Y$500,0)),"")
A6: =IFERROR(INDEX(样本到样信息汇总统计!A$2:A$500,MATCH(5,样本到样信息汇总统计!$Y$2:$Y$500,0)),"") | B6: =IFERROR(INDEX(样本到样信息汇总统计!B$2:B$500,MATCH(5,样本到样信息汇总统计!$Y$2:$Y$500,0)),"") | C6: =IFERROR(INDEX(样本到样信息汇总统计!C$2:C$500,MATCH(5,样本到样信息汇总统计!$Y$2:$Y$500,0)),"") | D6: =IFERROR(INDEX(样本到样信息汇总统计!D$2:D$500,MATCH(5,样本到样信息汇总统计!$Y$2:$Y$500,0)),"") | E6: =IFERROR(INDEX(样本到样信息汇总统计!E$2:E$500,MATCH(5,样本到样信息汇总统计!$Y$2:$Y$500,0)),"") | F6: =IFERROR(INDEX(样本到样信息汇总统计!F$2:F$500,MATCH(5,样本到样信息汇总统计!$Y$2:$Y$500,0)),"") | G6: =IFERROR(INDEX(样本到样信息汇总统计!G$2:G$500,MATCH(5,样本到样信息汇总统计!$Y$2:$Y$500,0)),"") | H6: =IFERROR(INDEX(样本到样信息汇总统计!H$2:H$500,MATCH(5,样本到样信息汇总统计!$Y$2:$Y$500,0)),"") | ... W6: =IFERROR(INDEX(样本到样信息汇总统计!W$2:W$500,MATCH(5,样本到样信息汇总统计!$Y$2:$Y$500,0)),"")
A7: =IFERROR(INDEX(样本到样信息汇总统计!A$2:A$500,MATCH(6,样本到样信息汇总统计!$Y$2:$Y$500,0)),"") | B7: =IFERROR(INDEX(样本到样信息汇总统计!B$2:B$500,MATCH(6,样本到样信息汇总统计!$Y$2:$Y$500,0)),"") | C7: =IFERROR(INDEX(样本到样信息汇总统计!C$2:C$500,MATCH(6,样本到样信息汇总统计!$Y$2:$Y$500,0)),"") | D7: =IFERROR(INDEX(样本到样信息汇总统计!D$2:D$500,MATCH(6,样本到样信息汇总统计!$Y$2:$Y$500,0)),"") | E7: =IFERROR(INDEX(样本到样信息汇总统计!E$2:E$500,MATCH(6,样本到样信息汇总统计!$Y$2:$Y$500,0)),"") | F7: =IFERROR(INDEX(样本到样信息汇总统计!F$2:F$500,MATCH(6,样本到样信息汇总统计!$Y$2:$Y$500,0)),"") | G7: =IFERROR(INDEX(样本到样信息汇总统计!G$2:G$500,MATCH(6,样本到样信息汇总统计!$Y$2:$Y$500,0)),"") | H7: =IFERROR(INDEX(样本到样信息汇总统计!H$2:H$500,MATCH(6,样本到样信息汇总统计!$Y$2:$Y$500,0)),"") | ... W7: =IFERROR(INDEX(样本到样信息汇总统计!W$2:W$500,MATCH(6,样本到样信息汇总统计!$Y$2:$Y$500,0)),"")
A8: =IFERROR(INDEX(样本到样信息汇总统计!A$2:A$500,MATCH(7,样本到样信息汇总统计!$Y$2:$Y$500,0)),"") | B8: =IFERROR(INDEX(样本到样信息汇总统计!B$2:B$500,MATCH(7,样本到样信息汇总统计!$Y$2:$Y$500,0)),"") | C8: =IFERROR(INDEX(样本到样信息汇总统计!C$2:C$500,MATCH(7,样本到样信息汇总统计!$Y$2:$Y$500,0)),"") | D8: =IFERROR(INDEX(样本到样信息汇总统计!D$2:D$500,MATCH(7,样本到样信息汇总统计!$Y$2:$Y$500,0)),"") | E8: =IFERROR(INDEX(样本到样信息汇总统计!E$2:E$500,MATCH(7,样本到样信息汇总统计!$Y$2:$Y$500,0)),"") | F8: =IFERROR(INDEX(样本到样信息汇总统计!F$2:F$500,MATCH(7,样本到样信息汇总统计!$Y$2:$Y$500,0)),"") | G8: =IFERROR(INDEX(样本到样信息汇总统计!G$2:G$500,MATCH(7,样本到样信息汇总统计!$Y$2:$Y$500,0)),"") | H8: =IFERROR(INDEX(样本到样信息汇总统计!H$2:H$500,MATCH(7,样本到样信息汇总统计!$Y$2:$Y$500,0)),"") | ... W8: =IFERROR(INDEX(样本到样信息汇总统计!W$2:W$500,MATCH(7,样本到样信息汇总统计!$Y$2:$Y$500,0)),"")
A9: =IFERROR(INDEX(样本到样信息汇总统计!A$2:A$500,MATCH(8,样本到样信息汇总统计!$Y$2:$Y$500,0)),"") | B9: =IFERROR(INDEX(样本到样信息汇总统计!B$2:B$500,MATCH(8,样本到样信息汇总统计!$Y$2:$Y$500,0)),"") | C9: =IFERROR(INDEX(样本到样信息汇总统计!C$2:C$500,MATCH(8,样本到样信息汇总统计!$Y$2:$Y$500,0)),"") | D9: =IFERROR(INDEX(样本到样信息汇总统计!D$2:D$500,MATCH(8,样本到样信息汇总统计!$Y$2:$Y$500,0)),"") | E9: =IFERROR(INDEX(样本到样信息汇总统计!E$2:E$500,MATCH(8,样本到样信息汇总统计!$Y$2:$Y$500,0)),"") | F9: =IFERROR(INDEX(样本到样信息汇总统计!F$2:F$500,MATCH(8,样本到样信息汇总统计!$Y$2:$Y$500,0)),"") | G9: =IFERROR(INDEX(样本到样信息汇总统计!G$2:G$500,MATCH(8,样本到样信息汇总统计!$Y$2:$Y$500,0)),"") | H9: =IFERROR(INDEX(样本到样信息汇总统计!H$2:H$500,MATCH(8,样本到样信息汇总统计!$Y$2:$Y$500,0)),"") | ... W9: =IFERROR(INDEX(样本到样信息汇总统计!W$2:W$500,MATCH(8,样本到样信息汇总统计!$Y$2:$Y$500,0)),"")
A10: =IFERROR(INDEX(样本到样信息汇总统计!A$2:A$500,MATCH(9,样本到样信息汇总统计!$Y$2:$Y$500,0)),"") | B10: =IFERROR(INDEX(样本到样信息汇总统计!B$2:B$500,MATCH(9,样本到样信息汇总统计!$Y$2:$Y$500,0)),"") | C10: =IFERROR(INDEX(样本到样信息汇总统计!C$2:C$500,MATCH(9,样本到样信息汇总统计!$Y$2:$Y$500,0)),"") | D10: =IFERROR(INDEX(样本到样信息汇总统计!D$2:D$500,MATCH(9,样本到样信息汇总统计!$Y$2:$Y$500,0)),"") | E10: =IFERROR(INDEX(样本到样信息汇总统计!E$2:E$500,MATCH(9,样本到样信息汇总统计!$Y$2:$Y$500,0)),"") | F10: =IFERROR(INDEX(样本到样信息汇总统计!F$2:F$500,MATCH(9,样本到样信息汇总统计!$Y$2:$Y$500,0)),"") | G10: =IFERROR(INDEX(样本到样信息汇总统计!G$2:G$500,MATCH(9,样本到样信息汇总统计!$Y$2:$Y$500,0)),"") | H10: =IFERROR(INDEX(样本到样信息汇总统计!H$2:H$500,MATCH(9,样本到样信息汇总统计!$Y$2:$Y$500,0)),"") | ... W10: =IFERROR(INDEX(样本到样信息汇总统计!W$2:W$500,MATCH(9,样本到样信息汇总统计!$Y$2:$Y$500,0)),"")
A11: =IFERROR(INDEX(样本到样信息汇总统计!A$2:A$500,MATCH(10,样本到样信息汇总统计!$Y$2:$Y$500,0)),"") | B11: =IFERROR(INDEX(样本到样信息汇总统计!B$2:B$500,MATCH(10,样本到样信息汇总统计!$Y$2:$Y$500,0)),"") | C11: =IFERROR(INDEX(样本到样信息汇总统计!C$2:C$500,MATCH(10,样本到样信息汇总统计!$Y$2:$Y$500,0)),"") | D11: =IFERROR(INDEX(样本到样信息汇总统计!D$2:D$500,MATCH(10,样本到样信息汇总统计!$Y$2:$Y$500,0)),"") | E11: =IFERROR(INDEX(样本到样信息汇总统计!E$2:E$500,MATCH(10,样本到样信息汇总统计!$Y$2:$Y$500,0)),"") | F11: =IFERROR(INDEX(样本到样信息汇总统计!F$2:F$500,MATCH(10,样本到样信息汇总统计!$Y$2:$Y$500,0)),"") | G11: =IFERROR(INDEX(样本到样信息汇总统计!G$2:G$500,MATCH(10,样本到样信息汇总统计!$Y$2:$Y$500,0)),"") | H11: =IFERROR(INDEX(样本到样信息汇总统计!H$2:H$500,MATCH(10,样本到样信息汇总统计!$Y$2:$Y$500,0)),"") | ... W11: =IFERROR(INDEX(样本到样信息汇总统计!W$2:W$500,MATCH(10,样本到样信息汇总统计!$Y$2:$Y$500,0)),"")
A12: =IFERROR(INDEX(样本到样信息汇总统计!A$2:A$500,MATCH(11,样本到样信息汇总统计!$Y$2:$Y$500,0)),"") | B12: =IFERROR(INDEX(样本到样信息汇总统计!B$2:B$500,MATCH(11,样本到样信息汇总统计!$Y$2:$Y$500,0)),"") | C12: =IFERROR(INDEX(样本到样信息汇总统计!C$2:C$500,MATCH(11,样本到样信息汇总统计!$Y$2:$Y$500,0)),"") | D12: =IFERROR(INDEX(样本到样信息汇总统计!D$2:D$500,MATCH(11,样本到样信息汇总统计!$Y$2:$Y$500,0)),"") | E12: =IFERROR(INDEX(样本到样信息汇总统计!E$2:E$500,MATCH(11,样本到样信息汇总统计!$Y$2:$Y$500,0)),"") | F12: =IFERROR(INDEX(样本到样信息汇总统计!F$2:F$500,MATCH(11,样本到样信息汇总统计!$Y$2:$Y$500,0)),"") | G12: =IFERROR(INDEX(样本到样信息汇总统计!G$2:G$500,MATCH(11,样本到样信息汇总统计!$Y$2:$Y$500,0)),"") | H12: =IFERROR(INDEX(样本到样信息汇总统计!H$2:H$500,MATCH(11,样本到样信息汇总统计!$Y$2:$Y$500,0)),"") | ... W12: =IFERROR(INDEX(样本到样信息汇总统计!W$2:W$500,MATCH(11,样本到样信息汇总统计!$Y$2:$Y$500,0)),"")
A13: =IFERROR(INDEX(样本到样信息汇总统计!A$2:A$500,MATCH(12,样本到样信息汇总统计!$Y$2:$Y$500,0)),"") | B13: =IFERROR(INDEX(样本到样信息汇总统计!B$2:B$500,MATCH(12,样本到样信息汇总统计!$Y$2:$Y$500,0)),"") | C13: =IFERROR(INDEX(样本到样信息汇总统计!C$2:C$500,MATCH(12,样本到样信息汇总统计!$Y$2:$Y$500,0)),"") | D13: =IFERROR(INDEX(样本到样信息汇总统计!D$2:D$500,MATCH(12,样本到样信息汇总统计!$Y$2:$Y$500,0)),"") | E13: =IFERROR(INDEX(样本到样信息汇总统计!E$2:E$500,MATCH(12,样本到样信息汇总统计!$Y$2:$Y$500,0)),"") | F13: =IFERROR(INDEX(样本到样信息汇总统计!F$2:F$500,MATCH(12,样本到样信息汇总统计!$Y$2:$Y$500,0)),"") | G13: =IFERROR(INDEX(样本到样信息汇总统计!G$2:G$500,MATCH(12,样本到样信息汇总统计!$Y$2:$Y$500,0)),"") | H13: =IFERROR(INDEX(样本到样信息汇总统计!H$2:H$500,MATCH(12,样本到样信息汇总统计!$Y$2:$Y$500,0)),"") | ... W13: =IFERROR(INDEX(样本到样信息汇总统计!W$2:W$500,MATCH(12,样本到样信息汇总统计!$Y$2:$Y$500,0)),"")
A14: =IFERROR(INDEX(样本到样信息汇总统计!A$2:A$500,MATCH(13,样本到样信息汇总统计!$Y$2:$Y$500,0)),"") | B14: =IFERROR(INDEX(样本到样信息汇总统计!B$2:B$500,MATCH(13,样本到样信息汇总统计!$Y$2:$Y$500,0)),"") | C14: =IFERROR(INDEX(样本到样信息汇总统计!C$2:C$500,MATCH(13,样本到样信息汇总统计!$Y$2:$Y$500,0)),"") | D14: =IFERROR(INDEX(样本到样信息汇总统计!D$2:D$500,MATCH(13,样本到样信息汇总统计!$Y$2:$Y$500,0)),"") | E14: =IFERROR(INDEX(样本到样信息汇总统计!E$2:E$500,MATCH(13,样本到样信息汇总统计!$Y$2:$Y$500,0)),"") | F14: =IFERROR(INDEX(样本到样信息汇总统计!F$2:F$500,MATCH(13,样本到样信息汇总统计!$Y$2:$Y$500,0)),"") | G14: =IFERROR(INDEX(样本到样信息汇总统计!G$2:G$500,MATCH(13,样本到样信息汇总统计!$Y$2:$Y$500,0)),"") | H14: =IFERROR(INDEX(样本到样信息汇总统计!H$2:H$500,MATCH(13,样本到样信息汇总统计!$Y$2:$Y$500,0)),"") | ... W14: =IFERROR(INDEX(样本到样信息汇总统计!W$2:W$500,MATCH(13,样本到样信息汇总统计!$Y$2:$Y$500,0)),"")
A15: =IFERROR(INDEX(样本到样信息汇总统计!A$2:A$500,MATCH(14,样本到样信息汇总统计!$Y$2:$Y$500,0)),"") | B15: =IFERROR(INDEX(样本到样信息汇总统计!B$2:B$500,MATCH(14,样本到样信息汇总统计!$Y$2:$Y$500,0)),"") | C15: =IFERROR(INDEX(样本到样信息汇总统计!C$2:C$500,MATCH(14,样本到样信息汇总统计!$Y$2:$Y$500,0)),"") | D15: =IFERROR(INDEX(样本到样信息汇总统计!D$2:D$500,MATCH(14,样本到样信息汇总统计!$Y$2:$Y$500,0)),"") | E15: =IFERROR(INDEX(样本到样信息汇总统计!E$2:E$500,MATCH(14,样本到样信息汇总统计!$Y$2:$Y$500,0)),"") | F15: =IFERROR(INDEX(样本到样信息汇总统计!F$2:F$500,MATCH(14,样本到样信息汇总统计!$Y$2:$Y$500,0)),"") | G15: =IFERROR(INDEX(样本到样信息汇总统计!G$2:G$500,MATCH(14,样本到样信息汇总统计!$Y$2:$Y$500,0)),"") | H15: =IFERROR(INDEX(样本到样信息汇总统计!H$2:H$500,MATCH(14,样本到样信息汇总统计!$Y$2:$Y$500,0)),"") | ... W15: =IFERROR(INDEX(样本到样信息汇总统计!W$2:W$500,MATCH(14,样本到样信息汇总统计!$Y$2:$Y$500,0)),"")
A16: =IFERROR(INDEX(样本到样信息汇总统计!A$2:A$500,MATCH(15,样本到样信息汇总统计!$Y$2:$Y$500,0)),"") | B16: =IFERROR(INDEX(样本到样信息汇总统计!B$2:B$500,MATCH(15,样本到样信息汇总统计!$Y$2:$Y$500,0)),"") | C16: =IFERROR(INDEX(样本到样信息汇总统计!C$2:C$500,MATCH(15,样本到样信息汇总统计!$Y$2:$Y$500,0)),"") | D16: =IFERROR(INDEX(样本到样信息汇总统计!D$2:D$500,MATCH(15,样本到样信息汇总统计!$Y$2:$Y$500,0)),"") | E16: =IFERROR(INDEX(样本到样信息汇总统计!E$2:E$500,MATCH(15,样本到样信息汇总统计!$Y$2:$Y$500,0)),"") | F16: =IFERROR(INDEX(样本到样信息汇总统计!F$2:F$500,MATCH(15,样本到样信息汇总统计!$Y$2:$Y$500,0)),"") | G16: =IFERROR(INDEX(样本到样信息汇总统计!G$2:G$500,MATCH(15,样本到样信息汇总统计!$Y$2:$Y$500,0)),"") | H16: =IFERROR(INDEX(样本到样信息汇总统计!H$2:H$500,MATCH(15,样本到样信息汇总统计!$Y$2:$Y$500,0)),"") | ... W16: =IFERROR(INDEX(样本到样信息汇总统计!W$2:W$500,MATCH(15,样本到样信息汇总统计!$Y$2:$Y$500,0)),"")
A17: =IFERROR(INDEX(样本到样信息汇总统计!A$2:A$500,MATCH(16,样本到样信息汇总统计!$Y$2:$Y$500,0)),"") | B17: =IFERROR(INDEX(样本到样信息汇总统计!B$2:B$500,MATCH(16,样本到样信息汇总统计!$Y$2:$Y$500,0)),"") | C17: =IFERROR(INDEX(样本到样信息汇总统计!C$2:C$500,MATCH(16,样本到样信息汇总统计!$Y$2:$Y$500,0)),"") | D17: =IFERROR(INDEX(样本到样信息汇总统计!D$2:D$500,MATCH(16,样本到样信息汇总统计!$Y$2:$Y$500,0)),"") | E17: =IFERROR(INDEX(样本到样信息汇总统计!E$2:E$500,MATCH(16,样本到样信息汇总统计!$Y$2:$Y$500,0)),"") | F17: =IFERROR(INDEX(样本到样信息汇总统计!F$2:F$500,MATCH(16,样本到样信息汇总统计!$Y$2:$Y$500,0)),"") | G17: =IFERROR(INDEX(样本到样信息汇总统计!G$2:G$500,MATCH(16,样本到样信息汇总统计!$Y$2:$Y$500,0)),"") | H17: =IFERROR(INDEX(样本到样信息汇总统计!H$2:H$500,MATCH(16,样本到样信息汇总统计!$Y$2:$Y$500,0)),"") | ... W17: =IFERROR(INDEX(样本到样信息汇总统计!W$2:W$500,MATCH(16,样本到样信息汇总统计!$Y$2:$Y$500,0)),"")
A18: =IFERROR(INDEX(样本到样信息汇总统计!A$2:A$500,MATCH(17,样本到样信息汇总统计!$Y$2:$Y$500,0)),"") | B18: =IFERROR(INDEX(样本到样信息汇总统计!B$2:B$500,MATCH(17,样本到样信息汇总统计!$Y$2:$Y$500,0)),"") | C18: =IFERROR(INDEX(样本到样信息汇总统计!C$2:C$500,MATCH(17,样本到样信息汇总统计!$Y$2:$Y$500,0)),"") | D18: =IFERROR(INDEX(样本到样信息汇总统计!D$2:D$500,MATCH(17,样本到样信息汇总统计!$Y$2:$Y$500,0)),"") | E18: =IFERROR(INDEX(样本到样信息汇总统计!E$2:E$500,MATCH(17,样本到样信息汇总统计!$Y$2:$Y$500,0)),"") | F18: =IFERROR(INDEX(样本到样信息汇总统计!F$2:F$500,MATCH(17,样本到样信息汇总统计!$Y$2:$Y$500,0)),"") | G18: =IFERROR(INDEX(样本到样信息汇总统计!G$2:G$500,MATCH(17,样本到样信息汇总统计!$Y$2:$Y$500,0)),"") | H18: =IFERROR(INDEX(样本到样信息汇总统计!H$2:H$500,MATCH(17,样本到样信息汇总统计!$Y$2:$Y$500,0)),"") | ... W18: =IFERROR(INDEX(样本到样信息汇总统计!W$2:W$500,MATCH(17,样本到样信息汇总统计!$Y$2:$Y$500,0)),"")
A19: =IFERROR(INDEX(样本到样信息汇总统计!A$2:A$500,MATCH(18,样本到样信息汇总统计!$Y$2:$Y$500,0)),"") | B19: =IFERROR(INDEX(样本到样信息汇总统计!B$2:B$500,MATCH(18,样本到样信息汇总统计!$Y$2:$Y$500,0)),"") | C19: =IFERROR(INDEX(样本到样信息汇总统计!C$2:C$500,MATCH(18,样本到样信息汇总统计!$Y$2:$Y$500,0)),"") | D19: =IFERROR(INDEX(样本到样信息汇总统计!D$2:D$500,MATCH(18,样本到样信息汇总统计!$Y$2:$Y$500,0)),"") | E19: =IFERROR(INDEX(样本到样信息汇总统计!E$2:E$500,MATCH(18,样本到样信息汇总统计!$Y$2:$Y$500,0)),"") | F19: =IFERROR(INDEX(样本到样信息汇总统计!F$2:F$500,MATCH(18,样本到样信息汇总统计!$Y$2:$Y$500,0)),"") | G19: =IFERROR(INDEX(样本到样信息汇总统计!G$2:G$500,MATCH(18,样本到样信息汇总统计!$Y$2:$Y$500,0)),"") | H19: =IFERROR(INDEX(样本到样信息汇总统计!H$2:H$500,MATCH(18,样本到样信息汇总统计!$Y$2:$Y$500,0)),"") | ... W19: =IFERROR(INDEX(样本到样信息汇总统计!W$2:W$500,MATCH(18,样本到样信息汇总统计!$Y$2:$Y$500,0)),"")
A20: =IFERROR(INDEX(样本到样信息汇总统计!A$2:A$500,MATCH(19,样本到样信息汇总统计!$Y$2:$Y$500,0)),"") | B20: =IFERROR(INDEX(样本到样信息汇总统计!B$2:B$500,MATCH(19,样本到样信息汇总统计!$Y$2:$Y$500,0)),"") | C20: =IFERROR(INDEX(样本到样信息汇总统计!C$2:C$500,MATCH(19,样本到样信息汇总统计!$Y$2:$Y$500,0)),"") | D20: =IFERROR(INDEX(样本到样信息汇总统计!D$2:D$500,MATCH(19,样本到样信息汇总统计!$Y$2:$Y$500,0)),"") | E20: =IFERROR(INDEX(样本到样信息汇总统计!E$2:E$500,MATCH(19,样本到样信息汇总统计!$Y$2:$Y$500,0)),"") | F20: =IFERROR(INDEX(样本到样信息汇总统计!F$2:F$500,MATCH(19,样本到样信息汇总统计!$Y$2:$Y$500,0)),"") | G20: =IFERROR(INDEX(样本到样信息汇总统计!G$2:G$500,MATCH(19,样本到样信息汇总统计!$Y$2:$Y$500,0)),"") | H20: =IFERROR(INDEX(样本到样信息汇总统计!H$2:H$500,MATCH(19,样本到样信息汇总统计!$Y$2:$Y$500,0)),"") | ... W20: =IFERROR(INDEX(样本到样信息汇总统计!W$2:W$500,MATCH(19,样本到样信息汇总统计!$Y$2:$Y$500,0)),"")
A21: =IFERROR(INDEX(样本到样信息汇总统计!A$2:A$500,MATCH(20,样本到样信息汇总统计!$Y$2:$Y$500,0)),"") | B21: =IFERROR(INDEX(样本到样信息汇总统计!B$2:B$500,MATCH(20,样本到样信息汇总统计!$Y$2:$Y$500,0)),"") | C21: =IFERROR(INDEX(样本到样信息汇总统计!C$2:C$500,MATCH(20,样本到样信息汇总统计!$Y$2:$Y$500,0)),"") | D21: =IFERROR(INDEX(样本到样信息汇总统计!D$2:D$500,MATCH(20,样本到样信息汇总统计!$Y$2:$Y$500,0)),"") | E21: =IFERROR(INDEX(样本到样信息汇总统计!E$2:E$500,MATCH(20,样本到样信息汇总统计!$Y$2:$Y$500,0)),"") | F21: =IFERROR(INDEX(样本到样信息汇总统计!F$2:F$500,MATCH(20,样本到样信息汇总统计!$Y$2:$Y$500,0)),"") | G21: =IFERROR(INDEX(样本到样信息汇总统计!G$2:G$500,MATCH(20,样本到样信息汇总统计!$Y$2:$Y$500,0)),"") | H21: =IFERROR(INDEX(样本到样信息汇总统计!H$2:H$500,MATCH(20,样本到样信息汇总统计!$Y$2:$Y$500,0)),"") | ... W21: =IFERROR(INDEX(样本到样信息汇总统计!W$2:W$500,MATCH(20,样本到样信息汇总统计!$Y$2:$Y$500,0)),"")
A22: =IFERROR(INDEX(样本到样信息汇总统计!A$2:A$500,MATCH(21,样本到样信息汇总统计!$Y$2:$Y$500,0)),"") | B22: =IFERROR(INDEX(样本到样信息汇总统计!B$2:B$500,MATCH(21,样本到样信息汇总统计!$Y$2:$Y$500,0)),"") | C22: =IFERROR(INDEX(样本到样信息汇总统计!C$2:C$500,MATCH(21,样本到样信息汇总统计!$Y$2:$Y$500,0)),"") | D22: =IFERROR(INDEX(样本到样信息汇总统计!D$2:D$500,MATCH(21,样本到样信息汇总统计!$Y$2:$Y$500,0)),"") | E22: =IFERROR(INDEX(样本到样信息汇总统计!E$2:E$500,MATCH(21,样本到样信息汇总统计!$Y$2:$Y$500,0)),"") | F22: =IFERROR(INDEX(样本到样信息汇总统计!F$2:F$500,MATCH(21,样本到样信息汇总统计!$Y$2:$Y$500,0)),"") | G22: =IFERROR(INDEX(样本到样信息汇总统计!G$2:G$500,MATCH(21,样本到样信息汇总统计!$Y$2:$Y$500,0)),"") | H22: =IFERROR(INDEX(样本到样信息汇总统计!H$2:H$500,MATCH(21,样本到样信息汇总统计!$Y$2:$Y$500,0)),"") | ... W22: =IFERROR(INDEX(样本到样信息汇总统计!W$2:W$500,MATCH(21,样本到样信息汇总统计!$Y$2:$Y$500,0)),"")
A23: =IFERROR(INDEX(样本到样信息汇总统计!A$2:A$500,MATCH(22,样本到样信息汇总统计!$Y$2:$Y$500,0)),"") | B23: =IFERROR(INDEX(样本到样信息汇总统计!B$2:B$500,MATCH(22,样本到样信息汇总统计!$Y$2:$Y$500,0)),"") | C23: =IFERROR(INDEX(样本到样信息汇总统计!C$2:C$500,MATCH(22,样本到样信息汇总统计!$Y$2:$Y$500,0)),"") | D23: =IFERROR(INDEX(样本到样信息汇总统计!D$2:D$500,MATCH(22,样本到样信息汇总统计!$Y$2:$Y$500,0)),"") | E23: =IFERROR(INDEX(样本到样信息汇总统计!E$2:E$500,MATCH(22,样本到样信息汇总统计!$Y$2:$Y$500,0)),"") | F23: =IFERROR(INDEX(样本到样信息汇总统计!F$2:F$500,MATCH(22,样本到样信息汇总统计!$Y$2:$Y$500,0)),"") | G23: =IFERROR(INDEX(样本到样信息汇总统计!G$2:G$500,MATCH(22,样本到样信息汇总统计!$Y$2:$Y$500,0)),"") | H23: =IFERROR(INDEX(样本到样信息汇总统计!H$2:H$500,MATCH(22,样本到样信息汇总统计!$Y$2:$Y$500,0)),"") | ... W23: =IFERROR(INDEX(样本到样信息汇总统计!W$2:W$500,MATCH(22,样本到样信息汇总统计!$Y$2:$Y$500,0)),"")
